Workbook

Sheet The List
A1: RK | B1: NAME | C1: POS | D1: PRK | E1: TEAM | F1: ADJ | G1: VALUE | H1: VORP | I1: ADP | J1: DIFF | L1: GP | M1: MPG | N1: PTS | O1: REB | P1: AST | Q1: STL | R1: BLK | S1: 3PM | T1: TO | U1: FG% | V1: FT% | W1: FGM | X1: FGA | Y1: FTM | Z1: FTA | AB1: zPTS | AC1: zREB | AD1: zAST | AE1: zSTL | AF1: zBLK | AG1: z3PM | AH1: zFG% | AI1: zFT% | AJ1: zTO | AL1: ROW | AM1: MULT | AN1: 1POS | AO1: FGimp1 | AP1: FTimp1 | AQ1: BASE | AR1: POOL | AS1: FGimp2 | AT1: FTimp2
A2: =RANK(H2,$H$2:$H$266) -> 1 | B2: Nikola Jokic | C2: =INDEX('Player Data'!$C:$C,AL2) -> C | D2: =SUMPRODUCT(($AN$2:$AN$266=AN2)*($H$2:$H$266>H2))+1 -> 1 | E2: =INDEX('Player Data'!$B:$B,AL2) -> DEN | G2: =Settings!$B$2*AB2+Settings!$B$3*AC2+Settings!$B$4*AD2+Settings!$B$5*AE2+Settings!$B$6*AF2+Settings!$B$7*AG2+Settings!$B$8*AH2+Settings!$B$9*AI2+Settings!$B$10*AJ2 -> 10.767653 | H2: =G2-LARGE($G$2:$G$266,Settings!$F$4) -> 13.983918 | I2: =IF(INDEX('Player Data'!$R:$R,AL2)="","",INDEX('Player Data'!$R:$R,AL2)) -> 2 | J2: =IF(I2="","",I2-A2) -> 1 | L2: =IF(Settings!$F$7="Yes",INDEX('Minutes & Health'!$O:$O,AL2),Settings!$F$8) -> 75 | M2: =INDEX('Minutes & Health'!$P:$P,AL2) -> 36.2 | N2: =INDEX('Player Data'!$F:$F,AL2)/INDEX('Player Data'!$E:$E,AL2)*M2*L2*AM2 -> 2045.7395 | O2: =INDEX('Player Data'!$G:$G,AL2)/INDEX('Player Data'!$E:$E,AL2)*M2*L2*AM2 -> 931.9702 | P2: =INDEX('Player Data'!$H:$H,AL2)/INDEX('Player Data'!$E:$E,AL2)*M2*L2*AM2 -> 721.20309 | Q2: =INDEX('Player Data'!$I:$I,AL2)/INDEX('Player Data'!$E:$E,AL2)*M2*L2*AM2 -> 110.87748 | R2: =INDEX('Player Data'!$J:$J,AL2)/INDEX('Player Data'!$E:$E,AL2)*M2*L2*AM2 -> 60.932671 | S2: =INDEX('Player Data'!$K:$K,AL2)/INDEX('Player Data'!$E:$E,AL2)*M2*L2*AM2 -> 124.86203 | T2: =INDEX('Player Data'!$L:$L,AL2)/INDEX('Player Data'!$E:$E,AL2)*M2*L2*AM2 -> 247.72627 | U2: =INDEX('Player Data'!$M:$M,AL2) -> 0.563 | V2: =INDEX('Player Data'!$N:$N,AL2) -> 0.819 | W2: =X2*U2 -> 740.03398 | X2: =INDEX('Player Data'!$O:$O,AL2)/INDEX('Player Data'!$E:$E,AL2)*M2*L2*AM2 -> 1314.4476 | Y2: =Z2*V2 -> 440.87195 | Z2: =INDEX('Player Data'!$P:$P,AL2)/INDEX('Player Data'!$E:$E,AL2)*M2*L2*AM2 -> 538.30519 | AB2: =(N2-Pool!$D$2)/Pool!$E$2 -> 1.9876451 | AC2: =(O2-Pool!$D$3)/Pool!$E$3 -> 2.9250704 | AD2: =(P2-Pool!$D$4)/Pool!$E$4 -> 2.9835777 | AE2: =(Q2-Pool!$D$5)/Pool!$E$5 -> 1.6182584 | AF2: =(R2-Pool!$D$6)/Pool!$E$6 -> 0.30673019 | AG2: =(S2-Pool!$D$7)/Pool!$E$7 -> 0.020415241 | AH2: =(AS2-Pool!$D$8)/Pool!$E$8 -> 2.2688517 | AI2: =(AT2-Pool!$D$9)/Pool!$E$9 -> 0.45508799 | AJ2: =-(T2-Pool!$D$10)/Pool!$E$10 -> -1.7979837 | AL2: =MATCH(B2,'Player Data'!$A:$A,0) -> 7 | AM2: =1+IF(Settings!$F$10="ON",IFERROR(VLOOKUP(TRIM(F2),Settings!$D$12:$F$17,3,FALSE),0),0) -> 1 | AN2: =IFERROR(LEFT(C2,FIND(",",C2)-1),C2) -> C | AO2: =X2*(U2-Pool!$B$12) -> 108.30158 | AP2: =Z2*(V2-Pool!$B$13) -> 15.557204 | AQ2: =Settings!$B$2*(N2-Pool!$B$2)/Pool!$C$2+Settings!$B$3*(O2-Pool!$B$3)/Pool!$C$3+Settings!$B$4*(P2-Pool!$B$4)/Pool!$C$4+Settings!$B$5*(Q2-Pool!$B$5)/Pool!$C$5+Settings!$B$6*(R2-Pool!$B$6)/Pool!$C$6+Settings!$B$7*(S2-Pool!$B$7)/Pool!$C$7+Settings!$B$8*(AO2-Pool!$B$8)/Pool!$C$8+Settings!$B$9*(AP2-Pool!$B$9)/Pool!$C$9+Settings!$B$10*-(T2-Pool!$B$10)/Pool!$C$10 -> 13.321661 | AR2: =IF(RANK(AQ2,$AQ$2:$AQ$266)<=Settings!$F$5,1,0) -> 1 | AS2: =X2*(U2-Pool!$D$12) -> 103.74462 | AT2: =Z2*(V2-Pool!$D$13) -> 10.153281
A3: =RANK(H3,$H$2:$H$266) -> 2 | B3: Shai Gilgeous-Alexander | C3: =INDEX('Player Data'!$C:$C,AL3) -> PG | D3: =SUMPRODUCT(($AN$2:$AN$266=AN3)*($H$2:$H$266>H3))+1 -> 1 | E3: =INDEX('Player Data'!$B:$B,AL3) -> OKC | G3: =Settings!$B$2*AB3+Settings!$B$3*AC3+Settings!$B$4*AD3+Settings!$B$5*AE3+Settings!$B$6*AF3+Settings!$B$7*AG3+Settings!$B$8*AH3+Settings!$B$9*AI3+Settings!$B$10*AJ3 -> 10.116328 | H3: =G3-LARGE($G$2:$G$266,Settings!$F$4) -> 13.332593 | I3: =IF(INDEX('Player Data'!$R:$R,AL3)="","",INDEX('Player Data'!$R:$R,AL3)) -> 4 | J3: =IF(I3="","",I3-A3) -> 2 | L3: =IF(Settings!$F$7="Yes",INDEX('Minutes & Health'!$O:$O,AL3),Settings!$F$8) -> 77 | M3: =INDEX('Minutes & Health'!$P:$P,AL3) -> 34.3 | N3: =INDEX('Player Data'!$F:$F,AL3)/INDEX('Player Data'!$E:$E,AL3)*M3*L3*AM3 -> 2421.0917 | O3: =INDEX('Player Data'!$G:$G,AL3)/INDEX('Player Data'!$E:$E,AL3)*M3*L3*AM3 -> 350.01325 | P3: =INDEX('Player Data'!$H:$H,AL3)/INDEX('Player Data'!$E:$E,AL3)*M3*L3*AM3 -> 484.01833 | Q3: =INDEX('Player Data'!$I:$I,AL3)/INDEX('Player Data'!$E:$E,AL3)*M3*L3*AM3 -> 124.0047 | R3: =INDEX('Player Data'!$J:$J,AL3)/INDEX('Player Data'!$E:$E,AL3)*M3*L3*AM3 -> 63.002385 | S3: =INDEX('Player Data'!$K:$K,AL3)/INDEX('Player Data'!$E:$E,AL3)*M3*L3*AM3 -> 133.00504 | T3: =INDEX('Player Data'!$L:$L,AL3)/INDEX('Player Data'!$E:$E,AL3)*M3*L3*AM3 -> 180.00682 | U3: =INDEX('Player Data'!$M:$M,AL3) -> 0.528 | V3: =INDEX('Player Data'!$N:$N,AL3) -> 0.887 | W3: =X3*U3 -> 836.64768 | X3: =INDEX('Player Data'!$O:$O,AL3)/INDEX('Player Data'!$E:$E,AL3)*M3*L3*AM3 -> 1584.56 | Y3: =Z3*V3 -> 614.80298 | Z3: =INDEX('Player Data'!$P:$P,AL3)/INDEX('Player Data'!$E:$E,AL3)*M3*L3*AM3 -> 693.12624 | AB3: =(N3-Pool!$D$2)/Pool!$E$2 -> 2.9128736 | AC3: =(O3-Pool!$D$3)/Pool!$E$3 -> -0.4622156 | AD3: =(P3-Pool!$D$4)/Pool!$E$4 -> 1.3794194 | AE3: =(Q3-Pool!$D$5)/Pool!$E$5 -> 2.1978007 | AF3: =(R3-Pool!$D$6)/Pool!$E$6 -> 0.36662923 | AG3: =(S3-Pool!$D$7)/Pool!$E$7 -> 0.13510386 | AH3: =(AS3-Pool!$D$8)/Pool!$E$8 -> 1.5222111 | AI3: =(AT3-Pool!$D$9)/Pool!$E$9 -> 2.6985409 | AJ3: =-(T3-Pool!$D$10)/Pool!$E$10 -> -0.63403512 | AL3: =MATCH(B3,'Player Data'!$A:$A,0) -> 2 | AM3: =1+IF(Settings!$F$10="ON",IFERROR(VLOOKUP(TRIM(F3),Settings!$D$12:$F$17,3,FALSE),0),0) -> 1 | AN3: =IFERROR(LEFT(C3,FIND(",",C3)-1),C3) -> PG | AO3: =X3*(U3-Pool!$B$12) -> 75.097417 | AP3: =Z3*(V3-Pool!$B$13) -> 67.164171 | AQ3: =Settings!$B$2*(N3-Pool!$B$2)/Pool!$C$2+Settings!$B$3*(O3-Pool!$B$3)/Pool!$C$3+Settings!$B$4*(P3-Pool!$B$4)/Pool!$C$4+Settings!$B$5*(Q3-Pool!$B$5)/Pool!$C$5+Settings!$B$6*(R3-Pool!$B$6)/Pool!$C$6+Settings!$B$7*(S3-Pool!$B$7)/Pool!$C$7+Settings!$B$8*(AO3-Pool!$B$8)/Pool!$C$8+Settings!$B$9*(AP3-Pool!$B$9)/Pool!$C$9+Settings!$B$10*-(T3-Pool!$B$10)/Pool!$C$10 -> 12.769624 | AR3: =IF(RANK(AQ3,$AQ$2:$AQ$266)<=Settings!$F$5,1,0) -> 1 | AS3: =X3*(U3-Pool!$D$12) -> 69.604027 | AT3: =Z3*(V3-Pool!$D$13) -> 60.206033
A4: =RANK(H4,$H$2:$H$266) -> 3 | B4: Victor Wembanyama | C4: =INDEX('Player Data'!$C:$C,AL4) -> C | D4: =SUMPRODUCT(($AN$2:$AN$266=AN4)*($H$2:$H$266>H4))+1 -> 2 | E4: =INDEX('Player Data'!$B:$B,AL4) -> SAS | G4: =Settings!$B$2*AB4+Settings!$B$3*AC4+Settings!$B$4*AD4+Settings!$B$5*AE4+Settings!$B$6*AF4+Settings!$B$7*AG4+Settings!$B$8*AH4+Settings!$B$9*AI4+Settings!$B$10*AJ4 -> 9.2094556 | H4: =G4-LARGE($G$2:$G$266,Settings!$F$4) -> 12.42572 | I4: =IF(INDEX('Player Data'!$R:$R,AL4)="","",INDEX('Player Data'!$R:$R,AL4)) -> 1 | J4: =IF(I4="","",I4-A4) -> -2 | L4: =IF(Settings!$F$7="Yes",INDEX('Minutes & Health'!$O:$O,AL4),Settings!$F$8) -> 73 | M4: =INDEX('Minutes & Health'!$P:$P,AL4) -> 31.9 | N4: =INDEX('Player Data'!$F:$F,AL4)/INDEX('Player Data'!$E:$E,AL4)*M4*L4*AM4 -> 1826.1173 | O4: =INDEX('Player Data'!$G:$G,AL4)/INDEX('Player Data'!$E:$E,AL4)*M4*L4*AM4 -> 834.9681 | P4: =INDEX('Player Data'!$H:$H,AL4)/INDEX('Player Data'!$E:$E,AL4)*M4*L4*AM4 -> 242.28091 | Q4: =INDEX('Player Data'!$I:$I,AL4)/INDEX('Player Data'!$E:$E,AL4)*M4*L4*AM4 -> 80.092863 | R4: =INDEX('Player Data'!$J:$J,AL4)/INDEX('Player Data'!$E:$E,AL4)*M4*L4*AM4 -> 227.2635 | S4: =INDEX('Player Data'!$K:$K,AL4)/INDEX('Player Data'!$E:$E,AL4)*M4*L4*AM4 -> 149.17296 | T4: =INDEX('Player Data'!$L:$L,AL4)/INDEX('Player Data'!$E:$E,AL4)*M4*L4*AM4 -> 195.22635 | U4: =INDEX('Player Data'!$M:$M,AL4) -> 0.491 | V4: =INDEX('Player Data'!$N:$N,AL4) -> 0.827 | W4: =X4*U4 -> 626.11264 | X4: =INDEX('Player Data'!$O:$O,AL4)/INDEX('Player Data'!$E:$E,AL4)*M4*L4*AM4 -> 1275.1785 | Y4: =Z4*V4 -> 424.66067 | Z4: =INDEX('Player Data'!$P:$P,AL4)/INDEX('Player Data'!$E:$E,AL4)*M4*L4*AM4 -> 513.49537 | AB4: =(N4-Pool!$D$2)/Pool!$E$2 -> 1.4462848 | AC4: =(O4-Pool!$D$3)/Pool!$E$3 -> 2.3604688 | AD4: =(P4-Pool!$D$4)/Pool!$E$4 -> -0.25552994 | AE4: =(Q4-Pool!$D$5)/Pool!$E$5 -> 0.25917373 | AF4: =(R4-Pool!$D$6)/Pool!$E$6 -> 5.1204651 | AG4: =(S4-Pool!$D$7)/Pool!$E$7 -> 0.36281792 | AH4: =(AS4-Pool!$D$8)/Pool!$E$8 -> 0.19316102 | AI4: =(AT4-Pool!$D$9)/Pool!$E$9 -> 0.61823971 | AJ4: =-(T4-Pool!$D$10)/Pool!$E$10 -> -0.89562554 | AL4: =MATCH(B4,'Player Data'!$A:$A,0) -> 15 | AM4: =1+IF(Settings!$F$10="ON",IFERROR(VLOOKUP(TRIM(F4),Settings!$D$12:$F$17,3,FALSE),0),0) -> 1 | AN4: =IFERROR(LEFT(C4,FIND(",",C4)-1),C4) -> C | AO4: =X4*(U4-Pool!$B$12) -> 13.253224 | AP4: =Z4*(V4-Pool!$B$13) -> 18.948155 | AQ4: =Settings!$B$2*(N4-Pool!$B$2)/Pool!$C$2+Settings!$B$3*(O4-Pool!$B$3)/Pool!$C$3+Settings!$B$4*(P4-Pool!$B$4)/Pool!$C$4+Settings!$B$5*(Q4-Pool!$B$5)/Pool!$C$5+Settings!$B$6*(R4-Pool!$B$6)/Pool!$C$6+Settings!$B$7*(S4-Pool!$B$7)/Pool!$C$7+Settings!$B$8*(AO4-Pool!$B$8)/Pool!$C$8+Settings!$B$9*(AP4-Pool!$B$9)/Pool!$C$9+Settings!$B$10*-(T4-Pool!$B$10)/Pool!$C$10 -> 12.037916 | AR4: =IF(RANK(AQ4,$AQ$2:$AQ$266)<=Settings!$F$5,1,0) -> 1 | AS4: =X4*(U4-Pool!$D$12) -> 8.8324051 | AT4: =Z4*(V4-Pool!$D$13) -> 13.793291
A5: =RANK(H5,$H$2:$H$266) -> 4 | B5: Tyrese Maxey | C5: =INDEX('Player Data'!$C:$C,AL5) -> PG,SG | D5: =SUMPRODUCT(($AN$2:$AN$266=AN5)*($H$2:$H$266>H5))+1 -> 2 | E5: =INDEX('Player Data'!$B:$B,AL5) -> PHI | G5: =Settings!$B$2*AB5+Settings!$B$3*AC5+Settings!$B$4*AD5+Settings!$B$5*AE5+Settings!$B$6*AF5+Settings!$B$7*AG5+Settings!$B$8*AH5+Settings!$B$9*AI5+Settings!$B$10*AJ5 -> 5.728766 | H5: =G5-LARGE($G$2:$G$266,Settings!$F$4) -> 8.9450308 | I5: =IF(INDEX('Player Data'!$R:$R,AL5)="","",INDEX('Player Data'!$R:$R,AL5)) -> 7 | J5: =IF(I5="","",I5-A5) -> 3 | L5: =IF(Settings!$F$7="Yes",INDEX('Minutes & Health'!$O:$O,AL5),Settings!$F$8) -> 75 | M5: =INDEX('Minutes & Health'!$P:$P,AL5) -> 35.9 | N5: =INDEX('Player Data'!$F:$F,AL5)/INDEX('Player Data'!$E:$E,AL5)*M5*L5*AM5 -> 1901.6469 | O5: =INDEX('Player Data'!$G:$G,AL5)/INDEX('Player Data'!$E:$E,AL5)*M5*L5*AM5 -> 283.94727 | P5: =INDEX('Player Data'!$H:$H,AL5)/INDEX('Player Data'!$E:$E,AL5)*M5*L5*AM5 -> 447.91682 | Q5: =INDEX('Player Data'!$I:$I,AL5)/INDEX('Player Data'!$E:$E,AL5)*M5*L5*AM5 -> 118.97791 | R5: =INDEX('Player Data'!$J:$J,AL5)/INDEX('Player Data'!$E:$E,AL5)*M5*L5*AM5 -> 48.990902 | S5: =INDEX('Player Data'!$K:$K,AL5)/INDEX('Player Data'!$E:$E,AL5)*M5*L5*AM5 -> 206.96157 | T5: =INDEX('Player Data'!$L:$L,AL5)/INDEX('Player Data'!$E:$E,AL5)*M5*L5*AM5 -> 164.96937 | U5: =INDEX('Player Data'!$M:$M,AL5) -> 0.468 | V5: =INDEX('Player Data'!$N:$N,AL5) -> 0.889 | W5: =X5*U5 -> 671.68927 | X5: =INDEX('Player Data'!$O:$O,AL5)/INDEX('Player Data'!$E:$E,AL5)*M5*L5*AM5 -> 1435.2335 | Y5: =Z5*V5 -> 351.35645 | Z5: =INDEX('Player Data'!$P:$P,AL5)/INDEX('Player Data'!$E:$E,AL5)*M5*L5*AM5 -> 395.22661 | AB5: =(N5-Pool!$D$2)/Pool!$E$2 -> 1.6324623 | AC5: =(O5-Pool!$D$3)/Pool!$E$3 -> -0.84675329 | AD5: =(P5-Pool!$D$4)/Pool!$E$4 -> 1.1352531 | AE5: =(Q5-Pool!$D$5)/Pool!$E$5 -> 1.9758772 | AF5: =(R5-Pool!$D$6)/Pool!$E$6 -> -0.038873265 | AG5: =(S5-Pool!$D$7)/Pool!$E$7 -> 1.1767307 | AH5: =(AS5-Pool!$D$8)/Pool!$E$8 -> -0.50451726 | AI5: =(AT5-Pool!$D$9)/Pool!$E$9 -> 1.574161 | AJ5: =-(T5-Pool!$D$10)/Pool!$E$10 -> -0.37557439 | AL5: =MATCH(B5,'Player Data'!$A:$A,0) -> 13 | AM5: =1+IF(Settings!$F$10="ON",IFERROR(VLOOKUP(TRIM(F5),Settings!$D$12:$F$17,3,FALSE),0),0) -> 1 | AN5: =IFERROR(LEFT(C5,FIND(",",C5)-1),C5) -> PG | AO5: =X5*(U5-Pool!$B$12) -> -18.093658 | AP5: =Z5*(V5-Pool!$B$13) -> 39.088047 | AQ5: =Settings!$B$2*(N5-Pool!$B$2)/Pool!$C$2+Settings!$B$3*(O5-Pool!$B$3)/Pool!$C$3+Settings!$B$4*(P5-Pool!$B$4)/Pool!$C$4+Settings!$B$5*(Q5-Pool!$B$5)/Pool!$C$5+Settings!$B$6*(R5-Pool!$B$6)/Pool!$C$6+Settings!$B$7*(S5-Pool!$B$7)/Pool!$C$7+Settings!$B$8*(AO5-Pool!$B$8)/Pool!$C$8+Settings!$B$9*(AP5-Pool!$B$9)/Pool!$C$9+Settings!$B$10*-(T5-Pool!$B$10)/Pool!$C$10 -> 7.8129103 | AR5: =IF(RANK(AQ5,$AQ$2:$AQ$266)<=Settings!$F$5,1,0) -> 1 | AS5: =X5*(U5-Pool!$D$12) -> -23.069359 | AT5: =Z5*(V5-Pool!$D$13) -> 35.120456
A6: =RANK(H6,$H$2:$H$266) -> 5 | B6: Luka Doncic | C6: =INDEX('Player Data'!$C:$C,AL6) -> PG,SG | D6: =SUMPRODUCT(($AN$2:$AN$266=AN6)*($H$2:$H$266>H6))+1 -> 3 | E6: =INDEX('Player Data'!$B:$B,AL6) -> LAL | G6: =Settings!$B$2*AB6+Settings!$B$3*AC6+Settings!$B$4*AD6+Settings!$B$5*AE6+Settings!$B$6*AF6+Settings!$B$7*AG6+Settings!$B$8*AH6+Settings!$B$9*AI6+Settings!$B$10*AJ6 -> 5.5059442 | H6: =G6-LARGE($G$2:$G$266,Settings!$F$4) -> 8.722209 | I6: =IF(INDEX('Player Data'!$R:$R,AL6)="","",INDEX('Player Data'!$R:$R,AL6)) -> 3 | J6: =IF(I6="","",I6-A6) -> -2 | L6: =IF(Settings!$F$7="Yes",INDEX('Minutes & Health'!$O:$O,AL6),Settings!$F$8) -> 74 | M6: =INDEX('Minutes & Health'!$P:$P,AL6) -> 36.1 | N6: =INDEX('Player Data'!$F:$F,AL6)/INDEX('Player Data'!$E:$E,AL6)*M6*L6*AM6 -> 2291.6275 | O6: =INDEX('Player Data'!$G:$G,AL6)/INDEX('Player Data'!$E:$E,AL6)*M6*L6*AM6 -> 587.64804 | P6: =INDEX('Player Data'!$H:$H,AL6)/INDEX('Player Data'!$E:$E,AL6)*M6*L6*AM6 -> 598.64145 | Q6: =INDEX('Player Data'!$I:$I,AL6)/INDEX('Player Data'!$E:$E,AL6)*M6*L6*AM6 -> 114.93116 | R6: =INDEX('Player Data'!$J:$J,AL6)/INDEX('Player Data'!$E:$E,AL6)*M6*L6*AM6 -> 33.979648 | S6: =INDEX('Player Data'!$K:$K,AL6)/INDEX('Player Data'!$E:$E,AL6)*M6*L6*AM6 -> 271.83719 | T6: =INDEX('Player Data'!$L:$L,AL6)/INDEX('Player Data'!$E:$E,AL6)*M6*L6*AM6 -> 297.82162 | U6: =INDEX('Player Data'!$M:$M,AL6) -> 0.469 | V6: =INDEX('Player Data'!$N:$N,AL6) -> 0.787 | W6: =X6*U6 -> 746.62292 | X6: =INDEX('Player Data'!$O:$O,AL6)/INDEX('Player Data'!$E:$E,AL6)*M6*L6*AM6 -> 1591.9465 | Y6: =Z6*V6 -> 526.50246 | Z6: =INDEX('Player Data'!$P:$P,AL6)/INDEX('Player Data'!$E:$E,AL6)*M6*L6*AM6 -> 668.99931 | AB6: =(N6-Pool!$D$2)/Pool!$E$2 -> 2.5937493 | AC6: =(O6-Pool!$D$3)/Pool!$E$3 -> 0.92093995 | AD6: =(P6-Pool!$D$4)/Pool!$E$4 -> 2.1546531 | AE6: =(Q6-Pool!$D$5)/Pool!$E$5 -> 1.7972209 | AF6: =(R6-Pool!$D$6)/Pool!$E$6 -> -0.47330985 | AG6: =(S6-Pool!$D$7)/Pool!$E$7 -> 2.0904592 | AH6: =(AS6-Pool!$D$8)/Pool!$E$8 -> -0.52479026 | AI6: =(AT6-Pool!$D$9)/Pool!$E$9 -> -0.39396546 | AJ6: =-(T6-Pool!$D$10)/Pool!$E$10 -> -2.6590127 | AL6: =MATCH(B6,'Player Data'!$A:$A,0) -> 4 | AM6: =1+IF(Settings!$F$10="ON",IFERROR(VLOOKUP(TRIM(F6),Settings!$D$12:$F$17,3,FALSE),0),0) -> 1 | AN6: =IFERROR(LEFT(C6,FIND(",",C6)-1),C6) -> PG | AO6: =X6*(U6-Pool!$B$12) -> -18.477357 | AP6: =Z6*(V6-Pool!$B$13) -> -2.0736686 | AQ6: =Settings!$B$2*(N6-Pool!$B$2)/Pool!$C$2+Settings!$B$3*(O6-Pool!$B$3)/Pool!$C$3+Settings!$B$4*(P6-Pool!$B$4)/Pool!$C$4+Settings!$B$5*(Q6-Pool!$B$5)/Pool!$C$5+Settings!$B$6*(R6-Pool!$B$6)/Pool!$C$6+Settings!$B$7*(S6-Pool!$B$7)/Pool!$C$7+Settings!$B$8*(AO6-Pool!$B$8)/Pool!$C$8+Settings!$B$9*(AP6-Pool!$B$9)/Pool!$C$9+Settings!$B$10*-(T6-Pool!$B$10)/Pool!$C$10 -> 7.3753022 | AR6: =IF(RANK(AQ6,$AQ$2:$AQ$266)<=Settings!$F$5,1,0) -> 1 | AS6: =X6*(U6-Pool!$D$12) -> -23.996354 | AT6: =Z6*(V6-Pool!$D$13) -> -8.7896011
A7: =RANK(H7,$H$2:$H$266) -> 6 | B7: Donovan Mitchell | C7: =INDEX('Player Data'!$C:$C,AL7) -> PG,SG | D7: =SUMPRODUCT(($AN$2:$AN$266=AN7)*($H$2:$H$266>H7))+1 -> 4 | E7: =INDEX('Player Data'!$B:$B,AL7) -> CLE | G7: =Settings!$B$2*AB7+Settings!$B$3*AC7+Settings!$B$4*AD7+Settings!$B$5*AE7+Settings!$B$6*AF7+Settings!$B$7*AG7+Settings!$B$8*AH7+Settings!$B$9*AI7+Settings!$B$10*AJ7 -> 4.4031472 | H7: =G7-LARGE($G$2:$G$266,Settings!$F$4) -> 7.6194119 | I7: =IF(INDEX('Player Data'!$R:$R,AL7)="","",INDEX('Player Data'!$R:$R,AL7)) -> 19 | J7: =IF(I7="","",I7-A7) -> 13 | L7: =IF(Settings!$F$7="Yes",INDEX('Minutes & Health'!$O:$O,AL7),Settings!$F$8) -> 75 | M7: =INDEX('Minutes & Health'!$P:$P,AL7) -> 33.2 | N7: =INDEX('Player Data'!$F:$F,AL7)/INDEX('Player Data'!$E:$E,AL7)*M7*L7*AM7 -> 1997.6045 | O7: =INDEX('Player Data'!$G:$G,AL7)/INDEX('Player Data'!$E:$E,AL7)*M7*L7*AM7 -> 360.28939 | P7: =INDEX('Player Data'!$H:$H,AL7)/INDEX('Player Data'!$E:$E,AL7)*M7*L7*AM7 -> 415.3336 | Q7: =INDEX('Player Data'!$I:$I,AL7)/INDEX('Player Data'!$E:$E,AL7)*M7*L7*AM7 -> 117.09405 | R7: =INDEX('Player Data'!$J:$J,AL7)/INDEX('Player Data'!$E:$E,AL7)*M7*L7*AM7 -> 22.017685 | S7: =INDEX('Player Data'!$K:$K,AL7)/INDEX('Player Data'!$E:$E,AL7)*M7*L7*AM7 -> 242.19453 | T7: =INDEX('Player Data'!$L:$L,AL7)/INDEX('Player Data'!$E:$E,AL7)*M7*L7*AM7 -> 194.15595 | U7: =INDEX('Player Data'!$M:$M,AL7) -> 0.463 | V7: =INDEX('Player Data'!$N:$N,AL7) -> 0.842 | W7: =X7*U7 -> 689.45148 | X7: =INDEX('Player Data'!$O:$O,AL7)/INDEX('Player Data'!$E:$E,AL7)*M7*L7*AM7 -> 1489.0961 | Y7: =Z7*V7 -> 376.50802 | Z7: =INDEX('Player Data'!$P:$P,AL7)/INDEX('Player Data'!$E:$E,AL7)*M7*L7*AM7 -> 447.15916 | AB7: =(N7-Pool!$D$2)/Pool!$E$2 -> 1.8689942 | AC7: =(O7-Pool!$D$3)/Pool!$E$3 -> -0.40240325 | AD7: =(P7-Pool!$D$4)/Pool!$E$4 -> 0.9148821 | AE7: =(Q7-Pool!$D$5)/Pool!$E$5 -> 1.8927084 | AF7: =(R7-Pool!$D$6)/Pool!$E$6 -> -0.81949775 | AG7: =(S7-Pool!$D$7)/Pool!$E$7 -> 1.6729628 | AH7: =(AS7-Pool!$D$8)/Pool!$E$8 -> -0.68628074 | AI7: =(AT7-Pool!$D$9)/Pool!$E$9 -> 0.83900901 | AJ7: =-(T7-Pool!$D$10)/Pool!$E$10 -> -0.87722762 | AL7: =MATCH(B7,'Player Data'!$A:$A,0) -> 8 | AM7: =1+IF(Settings!$F$10="ON",IFERROR(VLOOKUP(TRIM(F7),Settings!$D$12:$F$17,3,FALSE),0),0) -> 1 | AN7: =IFERROR(LEFT(C7,FIND(",",C7)-1),C7) -> PG | AO7: =X7*(U7-Pool!$B$12) -> -26.218171 | AP7: =Z7*(V7-Pool!$B$13) -> 23.207714 | AQ7: =Settings!$B$2*(N7-Pool!$B$2)/Pool!$C$2+Settings!$B$3*(O7-Pool!$B$3)/Pool!$C$3+Settings!$B$4*(P7-Pool!$B$4)/Pool!$C$4+Settings!$B$5*(Q7-Pool!$B$5)/Pool!$C$5+Settings!$B$6*(R7-Pool!$B$6)/Pool!$C$6+Settings!$B$7*(S7-Pool!$B$7)/Pool!$C$7+Settings!$B$8*(AO7-Pool!$B$8)/Pool!$C$8+Settings!$B$9*(AP7-Pool!$B$9)/Pool!$C$9+Settings!$B$10*-(T7-Pool!$B$10)/Pool!$C$10 -> 6.2774218 | AR7: =IF(RANK(AQ7,$AQ$2:$AQ$266)<=Settings!$F$5,1,0) -> 1 | AS7: =X7*(U7-Pool!$D$12) -> -31.380605 | AT7: =Z7*(V7-Pool!$D$13) -> 18.718784
A8: =RANK(H8,$H$2:$H$266) -> 7 | B8: Kawhi Leonard | C8: =INDEX('Player Data'!$C:$C,AL8) -> PF,SF,SG | D8: =SUMPRODUCT(($AN$2:$AN$266=AN8)*($H$2:$H$266>H8))+1 -> 1 | E8: =INDEX('Player Data'!$B:$B,AL8) -> TOR | G8: =Settings!$B$2*AB8+Settings!$B$3*AC8+Settings!$B$4*AD8+Settings!$B$5*AE8+Settings!$B$6*AF8+Settings!$B$7*AG8+Settings!$B$8*AH8+Settings!$B$9*AI8+Settings!$B$10*AJ8 -> 4.3671985 | H8: =G8-LARGE($G$2:$G$266,Settings!$F$4) -> 7.5834632 | I8: =IF(INDEX('Player Data'!$R:$R,AL8)="","",INDEX('Player Data'!$R:$R,AL8)) -> 17 | J8: =IF(I8="","",I8-A8) -> 10 | L8: =IF(Settings!$F$7="Yes",INDEX('Minutes & Health'!$O:$O,AL8),Settings!$F$8) -> 69 | M8: =INDEX('Minutes & Health'!$P:$P,AL8) -> 32.3 | N8: =INDEX('Player Data'!$F:$F,AL8)/INDEX('Player Data'!$E:$E,AL8)*M8*L8*AM8 -> 1707.2381 | O8: =INDEX('Player Data'!$G:$G,AL8)/INDEX('Player Data'!$E:$E,AL8)*M8*L8*AM8 -> 425.56082 | P8: =INDEX('Player Data'!$H:$H,AL8)/INDEX('Player Data'!$E:$E,AL8)*M8*L8*AM8 -> 252.73918 | Q8: =INDEX('Player Data'!$I:$I,AL8)/INDEX('Player Data'!$E:$E,AL8)*M8*L8*AM8 -> 109.8866 | R8: =INDEX('Player Data'!$J:$J,AL8)/INDEX('Player Data'!$E:$E,AL8)*M8*L8*AM8 -> 34.963918 | S8: =INDEX('Player Data'!$K:$K,AL8)/INDEX('Player Data'!$E:$E,AL8)*M8*L8*AM8 -> 153.84124 | T8: =INDEX('Player Data'!$L:$L,AL8)/INDEX('Player Data'!$E:$E,AL8)*M8*L8*AM8 -> 134.86082 | U8: =INDEX('Player Data'!$M:$M,AL8) -> 0.5 | V8: =INDEX('Player Data'!$N:$N,AL8) -> 0.875 | W8: =X8*U8 -> 607.47309 | X8: =INDEX('Player Data'!$O:$O,AL8)/INDEX('Player Data'!$E:$E,AL8)*M8*L8*AM8 -> 1214.9462 | Y8: =Z8*V8 -> 338.45072 | Z8: =INDEX('Player Data'!$P:$P,AL8)/INDEX('Player Data'!$E:$E,AL8)*M8*L8*AM8 -> 386.80082 | AB8: =(N8-Pool!$D$2)/Pool!$E$2 -> 1.1532524 | AC8: =(O8-Pool!$D$3)/Pool!$E$3 -> -0.022490226 | AD8: =(P8-Pool!$D$4)/Pool!$E$4 -> -0.18479727 | AE8: =(Q8-Pool!$D$5)/Pool!$E$5 -> 1.5745126 | AF8: =(R8-Pool!$D$6)/Pool!$E$6 -> -0.44482439 | AG8: =(S8-Pool!$D$7)/Pool!$E$7 -> 0.42856742 | AH8: =(AS8-Pool!$D$8)/Pool!$E$8 -> 0.42317047 | AI8: =(AT8-Pool!$D$9)/Pool!$E$9 -> 1.2978823 | AJ8: =-(T8-Pool!$D$10)/Pool!$E$10 -> 0.14192525 | AL8: =MATCH(B8,'Player Data'!$A:$A,0) -> 17 | AM8: =1+IF(Settings!$F$10="ON",IFERROR(VLOOKUP(TRIM(F8),Settings!$D$12:$F$17,3,FALSE),0),0) -> 1 | AN8: =IFERROR(LEFT(C8,FIND(",",C8)-1),C8) -> PF | AO8: =X8*(U8-Pool!$B$12) -> 23.561731 | AP8: =Z8*(V8-Pool!$B$13) -> 32.839523 | AQ8: =Settings!$B$2*(N8-Pool!$B$2)/Pool!$C$2+Settings!$B$3*(O8-Pool!$B$3)/Pool!$C$3+Settings!$B$4*(P8-Pool!$B$4)/Pool!$C$4+Settings!$B$5*(Q8-Pool!$B$5)/Pool!$C$5+Settings!$B$6*(R8-Pool!$B$6)/Pool!$C$6+Settings!$B$7*(S8-Pool!$B$7)/Pool!$C$7+Settings!$B$8*(AO8-Pool!$B$8)/Pool!$C$8+Settings!$B$9*(AP8-Pool!$B$9)/Pool!$C$9+Settings!$B$10*-(T8-Pool!$B$10)/Pool!$C$10 -> 6.5353224 | AR8: =IF(RANK(AQ8,$AQ$2:$AQ$266)<=Settings!$F$5,1,0) -> 1 | AS8: =X8*(U8-Pool!$D$12) -> 19.349727 | AT8: =Z8*(V8-Pool!$D$13) -> 28.956517
A9: =RANK(H9,$H$2:$H$266) -> 8 | B9: Stephen Curry | C9: =INDEX('Player Data'!$C:$C,AL9) -> PG | D9: =SUMPRODUCT(($AN$2:$AN$266=AN9)*($H$2:$H$266>H9))+1 -> 5 | E9: =INDEX('Player Data'!$B:$B,AL9) -> GSW | G9: =Settings!$B$2*AB9+Settings!$B$3*AC9+Settings!$B$4*AD9+Settings!$B$5*AE9+Settings!$B$6*AF9+Settings!$B$7*AG9+Settings!$B$8*AH9+Settings!$B$9*AI9+Settings!$B$10*AJ9 -> 4.1927638 | H9: =G9-LARGE($G$2:$G$266,Settings!$F$4) -> 7.4090286 | I9: =IF(INDEX('Player Data'!$R:$R,AL9)="","",INDEX('Player Data'!$R:$R,AL9)) -> 23 | J9: =IF(I9="","",I9-A9) -> 15 | L9: =IF(Settings!$F$7="Yes",INDEX('Minutes & Health'!$O:$O,AL9),Settings!$F$8) -> 73 | M9: =INDEX('Minutes & Health'!$P:$P,AL9) -> 31.7 | N9: =INDEX('Player Data'!$F:$F,AL9)/INDEX('Player Data'!$E:$E,AL9)*M9*L9*AM9 -> 1884.7103 | O9: =INDEX('Player Data'!$G:$G,AL9)/INDEX('Player Data'!$E:$E,AL9)*M9*L9*AM9 -> 304.27612 | P9: =INDEX('Player Data'!$H:$H,AL9)/INDEX('Player Data'!$E:$E,AL9)*M9*L9*AM9 -> 388.35242 | Q9: =INDEX('Player Data'!$I:$I,AL9)/INDEX('Player Data'!$E:$E,AL9)*M9*L9*AM9 -> 81.073573 | R9: =INDEX('Player Data'!$J:$J,AL9)/INDEX('Player Data'!$E:$E,AL9)*M9*L9*AM9 -> 29.026341 | S9: =INDEX('Player Data'!$K:$K,AL9)/INDEX('Player Data'!$E:$E,AL9)*M9*L9*AM9 -> 336.30519 | T9: =INDEX('Player Data'!$L:$L,AL9)/INDEX('Player Data'!$E:$E,AL9)*M9*L9*AM9 -> 215.19529 | U9: =INDEX('Player Data'!$M:$M,AL9) -> 0.452 | V9: =INDEX('Player Data'!$N:$N,AL9) -> 0.928 | W9: =X9*U9 -> 604.91815 | X9: =INDEX('Player Data'!$O:$O,AL9)/INDEX('Player Data'!$E:$E,AL9)*M9*L9*AM9 -> 1338.3145 | Y9: =Z9*V9 -> 338.65612 | Z9: =INDEX('Player Data'!$P:$P,AL9)/INDEX('Player Data'!$E:$E,AL9)*M9*L9*AM9 -> 364.93117 | AB9: =(N9-Pool!$D$2)/Pool!$E$2 -> 1.5907144 | AC9: =(O9-Pool!$D$3)/Pool!$E$3 -> -0.728429 | AD9: =(P9-Pool!$D$4)/Pool!$E$4 -> 0.73239955 | AE9: =(Q9-Pool!$D$5)/Pool!$E$5 -> 0.30247026 | AF9: =(R9-Pool!$D$6)/Pool!$E$6 -> -0.61666217 | AG9: =(S9-Pool!$D$7)/Pool!$E$7 -> 2.9984466 | AH9: =(AS9-Pool!$D$8)/Pool!$E$8 -> -0.93874211 | AI9: =(AT9-Pool!$D$9)/Pool!$E$9 -> 2.0914138 | AJ9: =-(T9-Pool!$D$10)/Pool!$E$10 -> -1.2388476 | AL9: =MATCH(B9,'Player Data'!$A:$A,0) -> 11 | AM9: =1+IF(Settings!$F$10="ON",IFERROR(VLOOKUP(TRIM(F9),Settings!$D$12:$F$17,3,FALSE),0),0) -> 1 | AN9: =IFERROR(LEFT(C9,FIND(",",C9)-1),C9) -> PG | AO9: =X9*(U9-Pool!$B$12) -> -38.284854 | AP9: =Z9*(V9-Pool!$B$13) -> 50.324133 | AQ9: =Settings!$B$2*(N9-Pool!$B$2)/Pool!$C$2+Settings!$B$3*(O9-Pool!$B$3)/Pool!$C$3+Settings!$B$4*(P9-Pool!$B$4)/Pool!$C$4+Settings!$B$5*(Q9-Pool!$B$5)/Pool!$C$5+Settings!$B$6*(R9-Pool!$B$6)/Pool!$C$6+Settings!$B$7*(S9-Pool!$B$7)/Pool!$C$7+Settings!$B$8*(AO9-Pool!$B$8)/Pool!$C$8+Settings!$B$9*(AP9-Pool!$B$9)/Pool!$C$9+Settings!$B$10*-(T9-Pool!$B$10)/Pool!$C$10 -> 6.4940866 | AR9: =IF(RANK(AQ9,$AQ$2:$AQ$266)<=Settings!$F$5,1,0) -> 1 | AS9: =X9*(U9-Pool!$D$12) -> -42.924555 | AT9: =Z9*(V9-Pool!$D$13) -> 46.660672
A10: =RANK(H10,$H$2:$H$266) -> 9 | B10: Anthony Edwards | C10: =INDEX('Player Data'!$C:$C,AL10) -> PG,SF,SG | D10: =SUMPRODUCT(($AN$2:$AN$266=AN10)*($H$2:$H$266>H10))+1 -> 6 | E10: =INDEX('Player Data'!$B:$B,AL10) -> MIN | G10: =Settings!$B$2*AB10+Settings!$B$3*AC10+Settings!$B$4*AD10+Settings!$B$5*AE10+Settings!$B$6*AF10+Settings!$B$7*AG10+Settings!$B$8*AH10+Settings!$B$9*AI10+Settings!$B$10*AJ10 -> 4.1660538 | H10: =G10-LARGE($G$2:$G$266,Settings!$F$4) -> 7.3823186 | I10: =IF(INDEX('Player Data'!$R:$R,AL10)="","",INDEX('Player Data'!$R:$R,AL10)) -> 13 | J10: =IF(I10="","",I10-A10) -> 4 | L10: =IF(Settings!$F$7="Yes",INDEX('Minutes & Health'!$O:$O,AL10),Settings!$F$8) -> 75 | M10: =INDEX('Minutes & Health'!$P:$P,AL10) -> 35.9 | N10: =INDEX('Player Data'!$F:$F,AL10)/INDEX('Player Data'!$E:$E,AL10)*M10*L10*AM10 -> 2150.6006 | O10: =INDEX('Player Data'!$G:$G,AL10)/INDEX('Player Data'!$E:$E,AL10)*M10*L10*AM10 -> 411.92351 | P10: =INDEX('Player Data'!$H:$H,AL10)/INDEX('Player Data'!$E:$E,AL10)*M10*L10*AM10 -> 317.94096 | Q10: =INDEX('Player Data'!$I:$I,AL10)/INDEX('Player Data'!$E:$E,AL10)*M10*L10*AM10 -> 101.98106 | R10: =INDEX('Player Data'!$J:$J,AL10)/INDEX('Player Data'!$E:$E,AL10)*M10*L10*AM10 -> 56.989417 | S10: =INDEX('Player Data'!$K:$K,AL10)/INDEX('Player Data'!$E:$E,AL10)*M10*L10*AM10 -> 264.9508 | T10: =INDEX('Player Data'!$L:$L,AL10)/INDEX('Player Data'!$E:$E,AL10)*M10*L10*AM10 -> 221.95878 | U10: =INDEX('Player Data'!$M:$M,AL10) -> 0.47 | V10: =INDEX('Player Data'!$N:$N,AL10) -> 0.808 | W10: =X10*U10 -> 728.97563 | X10: =INDEX('Player Data'!$O:$O,AL10)/INDEX('Player Data'!$E:$E,AL10)*M10*L10*AM10 -> 1551.012 | Y10: =Z10*V10 -> 427.67578 | Z10: =INDEX('Player Data'!$P:$P,AL10)/INDEX('Player Data'!$E:$E,AL10)*M10*L10*AM10 -> 529.30171 | AB10: =(N10-Pool!$D$2)/Pool!$E$2 -> 2.2461237 | AC10: =(O10-Pool!$D$3)/Pool!$E$3 -> -0.10186638 | AD10: =(P10-Pool!$D$4)/Pool!$E$4 -> 0.25618375 | AE10: =(Q10-Pool!$D$5)/Pool!$E$5 -> 1.2254976 | AF10: =(R10-Pool!$D$6)/Pool!$E$6 -> 0.19260955 | AG10: =(S10-Pool!$D$7)/Pool!$E$7 -> 1.9934691 | AH10: =(AS10-Pool!$D$8)/Pool!$E$8 -> -0.47737607 | AI10: =(AT10-Pool!$D$9)/Pool!$E$9 -> 0.18650974 | AJ10: =-(T10-Pool!$D$10)/Pool!$E$10 -> -1.3550972 | AL10: =MATCH(B10,'Player Data'!$A:$A,0) -> 5 | AM10: =1+IF(Settings!$F$10="ON",IFERROR(VLOOKUP(TRIM(F10),Settings!$D$12:$F$17,3,FALSE),0),0) -> 1 | AN10: =IFERROR(LEFT(C10,FIND(",",C10)-1),C10) -> PG | AO10: =X10*(U10-Pool!$B$12) -> -16.451227 | AP10: =Z10*(V10-Pool!$B$13) -> 9.474682 | AQ10: =Settings!$B$2*(N10-Pool!$B$2)/Pool!$C$2+Settings!$B$3*(O10-Pool!$B$3)/Pool!$C$3+Settings!$B$4*(P10-Pool!$B$4)/Pool!$C$4+Settings!$B$5*(Q10-Pool!$B$5)/Pool!$C$5+Settings!$B$6*(R10-Pool!$B$6)/Pool!$C$6+Settings!$B$7*(S10-Pool!$B$7)/Pool!$C$7+Settings!$B$8*(AO10-Pool!$B$8)/Pool!$C$8+Settings!$B$9*(AP10-Pool!$B$9)/Pool!$C$9+Settings!$B$10*-(T10-Pool!$B$10)/Pool!$C$10 -> 6.1455082 | AR10: =IF(RANK(AQ10,$AQ$2:$AQ$266)<=Settings!$F$5,1,0) -> 1 | AS10: =X10*(U10-Pool!$D$12) -> -21.828311 | AT10: =Z10*(V10-Pool!$D$13) -> 4.161142
A11: =RANK(H11,$H$2:$H$266) -> 10 | B11: Tyrese Haliburton | C11: =INDEX('Player Data'!$C:$C,AL11) -> PG,SG | D11: =SUMPRODUCT(($AN$2:$AN$266=AN11)*($H$2:$H$266>H11))+1 -> 7 | E11: =INDEX('Player Data'!$B:$B,AL11) -> IND | G11: =Settings!$B$2*AB11+Settings!$B$3*AC11+Settings!$B$4*AD11+Settings!$B$5*AE11+Settings!$B$6*AF11+Settings!$B$7*AG11+Settings!$B$8*AH11+Settings!$B$9*AI11+Settings!$B$10*AJ11 -> 4.16525 | H11: =G11-LARGE($G$2:$G$266,Settings!$F$4) -> 7.3815148 | I11: =IF(INDEX('Player Data'!$R:$R,AL11)="","",INDEX('Player Data'!$R:$R,AL11)) -> 24 | J11: =IF(I11="","",I11-A11) -> 14 | L11: =IF(Settings!$F$7="Yes",INDEX('Minutes & Health'!$O:$O,AL11),Settings!$F$8) -> 71 | M11: =INDEX('Minutes & Health'!$P:$P,AL11) -> 33.5 | N11: =INDEX('Player Data'!$F:$F,AL11)/INDEX('Player Data'!$E:$E,AL11)*M11*L11*AM11 -> 1334.7194 | O11: =INDEX('Player Data'!$G:$G,AL11)/INDEX('Player Data'!$E:$E,AL11)*M11*L11*AM11 -> 263.94451 | P11: =INDEX('Player Data'!$H:$H,AL11)/INDEX('Player Data'!$E:$E,AL11)*M11*L11*AM11 -> 690.85477 | Q11: =INDEX('Player Data'!$I:$I,AL11)/INDEX('Player Data'!$E:$E,AL11)*M11*L11*AM11 -> 86.981715 | R11: =INDEX('Player Data'!$J:$J,AL11)/INDEX('Player Data'!$E:$E,AL11)*M11*L11*AM11 -> 43.990752 | S11: =INDEX('Player Data'!$K:$K,AL11)/INDEX('Player Data'!$E:$E,AL11)*M11*L11*AM11 -> 199.95797 | T11: =INDEX('Player Data'!$L:$L,AL11)/INDEX('Player Data'!$E:$E,AL11)*M11*L11*AM11 -> 130.97247 | U11: =INDEX('Player Data'!$M:$M,AL11) -> 0.478 | V11: =INDEX('Player Data'!$N:$N,AL11) -> 0.852 | W11: =X11*U11 -> 461.69874 | X11: =INDEX('Player Data'!$O:$O,AL11)/INDEX('Player Data'!$E:$E,AL11)*M11*L11*AM11 -> 965.89695 | Y11: =Z11*V11 -> 211.42196 | Z11: =INDEX('Player Data'!$P:$P,AL11)/INDEX('Player Data'!$E:$E,AL11)*M11*L11*AM11 -> 248.14784 | AB11: =(N11-Pool!$D$2)/Pool!$E$2 -> 0.23500819 | AC11: =(O11-Pool!$D$3)/Pool!$E$3 -> -0.96317952 | AD11: =(P11-Pool!$D$4)/Pool!$E$4 -> 2.778322 | AE11: =(Q11-Pool!$D$5)/Pool!$E$5 -> 0.56330392 | AF11: =(R11-Pool!$D$6)/Pool!$E$6 -> -0.18358123 | AG11: =(S11-Pool!$D$7)/Pool!$E$7 -> 1.0780898 | AH11: =(AS11-Pool!$D$8)/Pool!$E$8 -> -0.12829715 | AI11: =(AT11-Pool!$D$9)/Pool!$E$9 -> 0.5768264 | AJ11: =-(T11-Pool!$D$10)/Pool!$E$10 -> 0.20875757 | AL11: =MATCH(B11,'Player Data'!$A:$A,0) -> 62 | AM11: =1+IF(Settings!$F$10="ON",IFERROR(VLOOKUP(TRIM(F11),Settings!$D$12:$F$17,3,FALSE),0),0) -> 1 | AN11: =IFERROR(LEFT(C11,FIND(",",C11)-1),C11) -> PG | AO11: =X11*(U11-Pool!$B$12) -> -2.5178709 | AP11: =Z11*(V11-Pool!$B$13) -> 15.360436 | AQ11: =Settings!$B$2*(N11-Pool!$B$2)/Pool!$C$2+Settings!$B$3*(O11-Pool!$B$3)/Pool!$C$3+Settings!$B$4*(P11-Pool!$B$4)/Pool!$C$4+Settings!$B$5*(Q11-Pool!$B$5)/Pool!$C$5+Settings!$B$6*(R11-Pool!$B$6)/Pool!$C$6+Settings!$B$7*(S11-Pool!$B$7)/Pool!$C$7+Settings!$B$8*(AO11-Pool!$B$8)/Pool!$C$8+Settings!$B$9*(AP11-Pool!$B$9)/Pool!$C$9+Settings!$B$10*-(T11-Pool!$B$10)/Pool!$C$10 -> 6.35796 | AR11: =IF(RANK(AQ11,$AQ$2:$AQ$266)<=Settings!$F$5,1,0) -> 1 | AS11: =X11*(U11-Pool!$D$12) -> -5.8664651 | AT11: =Z11*(V11-Pool!$D$13) -> 12.869336
A12: =RANK(H12,$H$2:$H$266) -> 11 | B12: Anthony Davis | C12: =INDEX('Player Data'!$C:$C,AL12) -> PF,C | D12: =SUMPRODUCT(($AN$2:$AN$266=AN12)*($H$2:$H$266>H12))+1 -> 2 | E12: =INDEX('Player Data'!$B:$B,AL12) -> WAS | G12: =Settings!$B$2*AB12+Settings!$B$3*AC12+Settings!$B$4*AD12+Settings!$B$5*AE12+Settings!$B$6*AF12+Settings!$B$7*AG12+Settings!$B$8*AH12+Settings!$B$9*AI12+Settings!$B$10*AJ12 -> 4.0868766 | H12: =G12-LARGE($G$2:$G$266,Settings!$F$4) -> 7.3031414 | I12: =IF(INDEX('Player Data'!$R:$R,AL12)="","",INDEX('Player Data'!$R:$R,AL12)) -> 25 | J12: =IF(I12="","",I12-A12) -> 14 | L12: =IF(Settings!$F$7="Yes",INDEX('Minutes & Health'!$O:$O,AL12),Settings!$F$8) -> 70 | M12: =INDEX('Minutes & Health'!$P:$P,AL12) -> 32.3 | N12: =INDEX('Player Data'!$F:$F,AL12)/INDEX('Player Data'!$E:$E,AL12)*M12*L12*AM12 -> 1535.0368 | O12: =INDEX('Player Data'!$G:$G,AL12)/INDEX('Player Data'!$E:$E,AL12)*M12*L12*AM12 -> 766.01639 | P12: =INDEX('Player Data'!$H:$H,AL12)/INDEX('Player Data'!$E:$E,AL12)*M12*L12*AM12 -> 209.27768 | Q12: =INDEX('Player Data'!$I:$I,AL12)/INDEX('Player Data'!$E:$E,AL12)*M12*L12*AM12 -> 76.100974 | R12: =INDEX('Player Data'!$J:$J,AL12)/INDEX('Player Data'!$E:$E,AL12)*M12*L12*AM12 -> 138.18335 | S12: =INDEX('Player Data'!$K:$K,AL12)/INDEX('Player Data'!$E:$E,AL12)*M12*L12*AM12 -> 38.050487 | T12: =INDEX('Player Data'!$L:$L,AL12)/INDEX('Player Data'!$E:$E,AL12)*M12*L12*AM12 -> 150.19929 | U12: =INDEX('Player Data'!$M:$M,AL12) -> 0.514 | V12: =INDEX('Player Data'!$N:$N,AL12) -> 0.783 | W12: =X12*U12 -> 632.03061 | X12: =INDEX('Player Data'!$O:$O,AL12)/INDEX('Player Data'!$E:$E,AL12)*M12*L12*AM12 -> 1229.6315 | Y12: =Z12*V12 -> 232.85997 | Z12: =INDEX('Player Data'!$P:$P,AL12)/INDEX('Player Data'!$E:$E,AL12)*M12*L12*AM12 -> 297.3946 | AB12: =(N12-Pool!$D$2)/Pool!$E$2 -> 0.72878264 | AC12: =(O12-Pool!$D$3)/Pool!$E$3 -> 1.9591347 | AD12: =(P12-Pool!$D$4)/Pool!$E$4 -> -0.47874161 | AE12: =(Q12-Pool!$D$5)/Pool!$E$5 -> 0.082939145 | AF12: =(R12-Pool!$D$6)/Pool!$E$6 -> 2.5424208 | AG12: =(S12-Pool!$D$7)/Pool!$E$7 -> -1.2022656 | AH12: =(AS12-Pool!$D$8)/Pool!$E$8 -> 0.80476684 | AI12: =(AT12-Pool!$D$9)/Pool!$E$9 -> -0.22845103 | AJ12: =-(T12-Pool!$D$10)/Pool!$E$10 -> -0.12170928 | AL12: =MATCH(B12,'Player Data'!$A:$A,0) -> 31 | AM12: =1+IF(Settings!$F$10="ON",IFERROR(VLOOKUP(TRIM(F12),Settings!$D$12:$F$17,3,FALSE),0),0) -> 1 | AN12: =IFERROR(LEFT(C12,FIND(",",C12)-1),C12) -> PF | AO12: =X12*(U12-Pool!$B$12) -> 41.061369 | AP12: =Z12*(V12-Pool!$B$13) -> -2.1113997 | AQ12: =Settings!$B$2*(N12-Pool!$B$2)/Pool!$C$2+Settings!$B$3*(O12-Pool!$B$3)/Pool!$C$3+Settings!$B$4*(P12-Pool!$B$4)/Pool!$C$4+Settings!$B$5*(Q12-Pool!$B$5)/Pool!$C$5+Settings!$B$6*(R12-Pool!$B$6)/Pool!$C$6+Settings!$B$7*(S12-Pool!$B$7)/Pool!$C$7+Settings!$B$8*(AO12-Pool!$B$8)/Pool!$C$8+Settings!$B$9*(AP12-Pool!$B$9)/Pool!$C$9+Settings!$B$10*-(T12-Pool!$B$10)/Pool!$C$10 -> 6.4983473 | AR12: =IF(RANK(AQ12,$AQ$2:$AQ$266)<=Settings!$F$5,1,0) -> 1 | AS12: =X12*(U12-Pool!$D$12) -> 36.798454 | AT12: =Z12*(V12-Pool!$D$13) -> -5.0968767
A13: =RANK(H13,$H$2:$H$266) -> 12 | B13: Karl-Anthony Towns | C13: =INDEX('Player Data'!$C:$C,AL13) -> PF,C | D13: =SUMPRODUCT(($AN$2:$AN$266=AN13)*($H$2:$H$266>H13))+1 -> 3 | E13: =INDEX('Player Data'!$B:$B,AL13) -> NYK | G13: =Settings!$B$2*AB13+Settings!$B$3*AC13+Settings!$B$4*AD13+Settings!$B$5*AE13+Settings!$B$6*AF13+Settings!$B$7*AG13+Settings!$B$8*AH13+Settings!$B$9*AI13+Settings!$B$10*AJ13 -> 3.8784685 | H13: =G13-LARGE($G$2:$G$266,Settings!$F$4) -> 7.0947333 | I13: =IF(INDEX('Player Data'!$R:$R,AL13)="","",INDEX('Player Data'!$R:$R,AL13)) -> 11 | J13: =IF(I13="","",I13-A13) -> -1 | L13: =IF(Settings!$F$7="Yes",INDEX('Minutes & Health'!$O:$O,AL13),Settings!$F$8) -> 74 | M13: =INDEX('Minutes & Health'!$P:$P,AL13) -> 32.8 | N13: =INDEX('Player Data'!$F:$F,AL13)/INDEX('Player Data'!$E:$E,AL13)*M13*L13*AM13 -> 1573.0739 | O13: =INDEX('Player Data'!$G:$G,AL13)/INDEX('Player Data'!$E:$E,AL13)*M13*L13*AM13 -> 870.14719 | P13: =INDEX('Player Data'!$H:$H,AL13)/INDEX('Player Data'!$E:$E,AL13)*M13*L13*AM13 -> 271.35776 | Q13: =INDEX('Player Data'!$I:$I,AL13)/INDEX('Player Data'!$E:$E,AL13)*M13*L13*AM13 -> 68.089769 | R13: =INDEX('Player Data'!$J:$J,AL13)/INDEX('Player Data'!$E:$E,AL13)*M13*L13*AM13 -> 50.066007 | S13: =INDEX('Player Data'!$K:$K,AL13)/INDEX('Player Data'!$E:$E,AL13)*M13*L13*AM13 -> 128.16898 | T13: =INDEX('Player Data'!$L:$L,AL13)/INDEX('Player Data'!$E:$E,AL13)*M13*L13*AM13 -> 188.24818 | U13: =INDEX('Player Data'!$M:$M,AL13) -> 0.51 | V13: =INDEX('Player Data'!$N:$N,AL13) -> 0.851 | W13: =X13*U13 -> 549.6887 | X13: =INDEX('Player Data'!$O:$O,AL13)/INDEX('Player Data'!$E:$E,AL13)*M13*L13*AM13 -> 1077.821 | Y13: =Z13*V13 -> 345.53605 | Z13: =INDEX('Player Data'!$P:$P,AL13)/INDEX('Player Data'!$E:$E,AL13)*M13*L13*AM13 -> 406.03531 | AB13: =(N13-Pool!$D$2)/Pool!$E$2 -> 0.82254279 | AC13: =(O13-Pool!$D$3)/Pool!$E$3 -> 2.565229 | AD13: =(P13-Pool!$D$4)/Pool!$E$4 -> -0.058873714 | AE13: =(Q13-Pool!$D$5)/Pool!$E$5 -> -0.2707409 | AF13: =(R13-Pool!$D$6)/Pool!$E$6 -> -0.0077589677 | AG13: =(S13-Pool!$D$7)/Pool!$E$7 -> 0.066991299 | AH13: =(AS13-Pool!$D$8)/Pool!$E$8 -> 0.61112419 | AI13: =(AT13-Pool!$D$9)/Pool!$E$9 -> 0.92564092 | AJ13: =-(T13-Pool!$D$10)/Pool!$E$10 -> -0.77568614 | AL13: =MATCH(B13,'Player Data'!$A:$A,0) -> 38 | AM13: =1+IF(Settings!$F$10="ON",IFERROR(VLOOKUP(TRIM(F13),Settings!$D$12:$F$17,3,FALSE),0),0) -> 1 | AN13: =IFERROR(LEFT(C13,FIND(",",C13)-1),C13) -> PF | AO13: =X13*(U13-Pool!$B$12) -> 31.680641 | AP13: =Z13*(V13-Pool!$B$13) -> 24.72769 | AQ13: =Settings!$B$2*(N13-Pool!$B$2)/Pool!$C$2+Settings!$B$3*(O13-Pool!$B$3)/Pool!$C$3+Settings!$B$4*(P13-Pool!$B$4)/Pool!$C$4+Settings!$B$5*(Q13-Pool!$B$5)/Pool!$C$5+Settings!$B$6*(R13-Pool!$B$6)/Pool!$C$6+Settings!$B$7*(S13-Pool!$B$7)/Pool!$C$7+Settings!$B$8*(AO13-Pool!$B$8)/Pool!$C$8+Settings!$B$9*(AP13-Pool!$B$9)/Pool!$C$9+Settings!$B$10*-(T13-Pool!$B$10)/Pool!$C$10 -> 6.3680096 | AR13: =IF(RANK(AQ13,$AQ$2:$AQ$266)<=Settings!$F$5,1,0) -> 1 | AS13: =X13*(U13-Pool!$D$12) -> 27.944026 | AT13: =Z13*(V13-Pool!$D$13) -> 20.651593
... A266: =RANK(H266,$H$2:$H$266) -> 265 | B266: Shaedon Sharpe | C266: =INDEX('Player Data'!$C:$C,AL266) -> PG,SF,SG | D266: =SUMPRODUCT(($AN$2:$AN$266=AN266)*($H$2:$H$266>H266))+1 -> 78 | E266: =INDEX('Player Data'!$B:$B,AL266) -> POR | G266: =Settings!$B$2*AB266+Settings!$B$3*AC266+Settings!$B$4*AD266+Settings!$B$5*AE266+Settings!$B$6*AF266+Settings!$B$7*AG266+Settings!$B$8*AH266+Settings!$B$9*AI266+Settings!$B$10*AJ266 -> -9.9573912 | H266: =G266-LARGE($G$2:$G$266,Settings!$F$4) -> -6.7411264 | I266: =IF(INDEX('Player Data'!$R:$R,AL266)="","",INDEX('Player Data'!$R:$R,AL266)) -> 149 | J266: =IF(I266="","",I266-A266) -> -116 | L266: =IF(Settings!$F$7="Yes",INDEX('Minutes & Health'!$O:$O,AL266),Settings!$F$8) -> 18 | M266: =INDEX('Minutes & Health'!$P:$P,AL266) -> 21.9 | N266: =INDEX('Player Data'!$F:$F,AL266)/INDEX('Player Data'!$E:$E,AL266)*M266*L266*AM266 -> 242.50785 | O266: =INDEX('Player Data'!$G:$G,AL266)/INDEX('Player Data'!$E:$E,AL266)*M266*L266*AM266 -> 55.886582 | P266: =INDEX('Player Data'!$H:$H,AL266)/INDEX('Player Data'!$E:$E,AL266)*M266*L266*AM266 -> 32.933165 | Q266: =INDEX('Player Data'!$I:$I,AL266)/INDEX('Player Data'!$E:$E,AL266)*M266*L266*AM266 -> 14.96962 | R266: =INDEX('Player Data'!$J:$J,AL266)/INDEX('Player Data'!$E:$E,AL266)*M266*L266*AM266 -> 0.99797468 | S266: =INDEX('Player Data'!$K:$K,AL266)/INDEX('Player Data'!$E:$E,AL266)*M266*L266*AM266 -> 24.949367 | T266: =INDEX('Player Data'!$L:$L,AL266)/INDEX('Player Data'!$E:$E,AL266)*M266*L266*AM266 -> 31.93519 | U266: =INDEX('Player Data'!$M:$M,AL266) -> 0.46 | V266: =INDEX('Player Data'!$N:$N,AL266) -> 0.785 | W266: =X266*U266 -> 90.757814 | X266: =INDEX('Player Data'!$O:$O,AL266)/INDEX('Player Data'!$E:$E,AL266)*M266*L266*AM266 -> 197.29959 | Y266: =Z266*V266 -> 36.036866 | Z266: =INDEX('Player Data'!$P:$P,AL266)/INDEX('Player Data'!$E:$E,AL266)*M266*L266*AM266 -> 45.906835 | AB266: =(N266-Pool!$D$2)/Pool!$E$2 -> -2.4572509 | AC266: =(O266-Pool!$D$3)/Pool!$E$3 -> -2.1741827 | AD266: =(P266-Pool!$D$4)/Pool!$E$4 -> -1.6714173 | AE266: =(Q266-Pool!$D$5)/Pool!$E$5 -> -2.6158982 | AF266: =(R266-Pool!$D$6)/Pool!$E$6 -> -1.4278234 | AG266: =(S266-Pool!$D$7)/Pool!$E$7 -> -1.3867859 | AH266: =(AS266-Pool!$D$8)/Pool!$E$8 -> -0.10387418 | AI266: =(AT266-Pool!$D$9)/Pool!$E$9 -> -0.031149222 | AJ266: =-(T266-Pool!$D$10)/Pool!$E$10 -> 1.9109907 | AL266: =MATCH(B266,'Player Data'!$A:$A,0) -> 115 | AM266: =1+IF(Settings!$F$10="ON",IFERROR(VLOOKUP(TRIM(F266),Settings!$D$12:$F$17,3,FALSE),0),0) -> 1 | AN266: =IFERROR(LEFT(C266,FIND(",",C266)-1),C266) -> PG | AO266: =X266*(U266-Pool!$B$12) -> -4.0657073 | AP266: =Z266*(V266-Pool!$B$13) -> -0.23410913 | AQ266: =Settings!$B$2*(N266-Pool!$B$2)/Pool!$C$2+Settings!$B$3*(O266-Pool!$B$3)/Pool!$C$3+Settings!$B$4*(P266-Pool!$B$4)/Pool!$C$4+Settings!$B$5*(Q266-Pool!$B$5)/Pool!$C$5+Settings!$B$6*(R266-Pool!$B$6)/Pool!$C$6+Settings!$B$7*(S266-Pool!$B$7)/Pool!$C$7+Settings!$B$8*(AO266-Pool!$B$8)/Pool!$C$8+Settings!$B$9*(AP266-Pool!$B$9)/Pool!$C$9+Settings!$B$10*-(T266-Pool!$B$10)/Pool!$C$10 -> -7.729113 | AR266: =IF(RANK(AQ266,$AQ$2:$AQ$266)<=Settings!$F$5,1,0) -> 0 | AS266: =X266*(U266-Pool!$D$12) -> -4.7497102 | AT266: =Z266*(V266-Pool!$D$13) -> -0.69495745

Sheet Minutes & Health
A1: Player | B1: Team | C1: Pos | D1: Proj GP | E1: Proj MPG | F1: 25-26 GP | G1: 25-26 MPG | H1: MPG Δ | I1: Status | J1: Return | K1: Games Out | L1: Max GP | M1: Your GP | N1: Your MPG | O1: GP Used | P1: MPG Used | Q1: Note
A2: Shai Gilgeous-Alexander | B2: OKC | C2: PG | D2: 77 | E2: 34.3 | F2: 68 | G2: 33.2 | H2: =IF(G2="","",E2-G2) -> 1.1 | I2: Day-To-Day | J2: 46308 | K2: =IF(J2="",0,COUNTIFS(Schedule!$B:$B,B2,Schedule!$A:$A,"<"&J2)) -> 0 | L2: =82-K2 -> 82 | O2: =IF(M2<>"",M2,MIN(D2,L2)) -> 77 | P2: =IF(N2<>"",N2,E2) -> 34.3 | Q2: 2026-10-10: Gilgeous-Alexander (rest) won't play in Monday's preseason game against Atlanta, Clemente Almanza of USA Today reports.
A3: Giannis Antetokounmpo | B3: MIA | C3: PF,C | D3: 73 | E3: 33 | F3: 36 | G3: 28.9 | H3: =IF(G3="","",E3-G3) -> 4.1 | I3: Day-To-Day | J3: 46309 | K3: =IF(J3="",0,COUNTIFS(Schedule!$B:$B,B3,Schedule!$A:$A,"<"&J3)) -> 0 | L3: =82-K3 -> 82 | O3: =IF(M3<>"",M3,MIN(D3,L3)) -> 73 | P3: =IF(N3<>"",N3,E3) -> 33 | Q3: 2026-10-10: Antetokounmpo (rest) won't be available for Saturday's preseason game against the Timberwolves, Eric Nehm of The Athletic reports.
A4: Luka Doncic | B4: LAL | C4: PG,SG | D4: 74 | E4: 36.1 | F4: 64 | G4: 35.8 | H4: =IF(G4="","",E4-G4) -> 0.3 | K4: =IF(J4="",0,COUNTIFS(Schedule!$B:$B,B4,Schedule!$A:$A,"<"&J4)) -> 0 | L4: =82-K4 -> 82 | O4: =IF(M4<>"",M4,MIN(D4,L4)) -> 74 | P4: =IF(N4<>"",N4,E4) -> 36.1
A5: Anthony Edwards | B5: MIN | C5: PG,SF,SG | D5: 75 | E5: 35.9 | F5: 61 | G5: 35 | H5: =IF(G5="","",E5-G5) -> 0.9 | I5: Day-To-Day | J5: 46307 | K5: =IF(J5="",0,COUNTIFS(Schedule!$B:$B,B5,Schedule!$A:$A,"<"&J5)) -> 0 | L5: =82-K5 -> 82 | O5: =IF(M5<>"",M5,MIN(D5,L5)) -> 75 | P5: =IF(N5<>"",N5,E5) -> 35.9 | Q5: 2026-10-10: Edwards (rest) is not available for Saturday's preseason game against Miami.
A6: Jayson Tatum | B6: BOS | C6: SF,PF | D6: 74 | E6: 36.1 | F6: 16 | G6: 32.6 | H6: =IF(G6="","",E6-G6) -> 3.5 | K6: =IF(J6="",0,COUNTIFS(Schedule!$B:$B,B6,Schedule!$A:$A,"<"&J6)) -> 0 | L6: =82-K6 -> 82 | O6: =IF(M6<>"",M6,MIN(D6,L6)) -> 74 | P6: =IF(N6<>"",N6,E6) -> 36.1
A7: Nikola Jokic | B7: DEN | C7: C | D7: 75 | E7: 36.2 | F7: 65 | G7: 34.8 | H7: =IF(G7="","",E7-G7) -> 1.4 | K7: =IF(J7="",0,COUNTIFS(Schedule!$B:$B,B7,Schedule!$A:$A,"<"&J7)) -> 0 | L7: =82-K7 -> 82 | O7: =IF(M7<>"",M7,MIN(D7,L7)) -> 75 | P7: =IF(N7<>"",N7,E7) -> 36.2
A8: Donovan Mitchell | B8: CLE | C8: PG,SG | D8: 75 | E8: 33.2 | F8: 70 | G8: 33.5 | H8: =IF(G8="","",E8-G8) -> -0.3 | K8: =IF(J8="",0,COUNTIFS(Schedule!$B:$B,B8,Schedule!$A:$A,"<"&J8)) -> 0 | L8: =82-K8 -> 82 | O8: =IF(M8<>"",M8,MIN(D8,L8)) -> 75 | P8: =IF(N8<>"",N8,E8) -> 33.2
A9: Jalen Brunson | B9: NYK | C9: PG | D9: 75 | E9: 35.6 | F9: 74 | G9: 35 | H9: =IF(G9="","",E9-G9) -> 0.6 | K9: =IF(J9="",0,COUNTIFS(Schedule!$B:$B,B9,Schedule!$A:$A,"<"&J9)) -> 0 | L9: =82-K9 -> 82 | O9: =IF(M9<>"",M9,MIN(D9,L9)) -> 75 | P9: =IF(N9<>"",N9,E9) -> 35.6
A10: Joel Embiid | B10: PHI | C10: C | D10: 59 | E10: 31 | F10: 38 | G10: 31.6 | H10: =IF(G10="","",E10-G10) -> -0.6 | I10: Day-To-Day | J10: 46311 | K10: =IF(J10="",0,COUNTIFS(Schedule!$B:$B,B10,Schedule!$A:$A,"<"&J10)) -> 0 | L10: =82-K10 -> 82 | O10: =IF(M10<>"",M10,MIN(D10,L10)) -> 59 | P10: =IF(N10<>"",N10,E10) -> 31 | Q10: 2026-10-10: Embiid (rest) is out for Saturday's exhibition against the Celtics, Tony Jones of The Athletic reports.
A11: Stephen Curry | B11: GSW | C11: PG | D11: 73 | E11: 31.7 | F11: 43 | G11: 30.9 | H11: =IF(G11="","",E11-G11) -> 0.8 | K11: =IF(J11="",0,COUNTIFS(Schedule!$B:$B,B11,Schedule!$A:$A,"<"&J11)) -> 0 | L11: =82-K11 -> 82 | O11: =IF(M11<>"",M11,MIN(D11,L11)) -> 73 | P11: =IF(N11<>"",N11,E11) -> 31.7
A12: Devin Booker | B12: PHO | C12: PG,SG | D12: 75 | E12: 35.9 | F12: 64 | G12: 33.5 | H12: =IF(G12="","",E12-G12) -> 2.4 | I12: Day-To-Day | J12: 46309 | K12: =IF(J12="",0,COUNTIFS(Schedule!$B:$B,B12,Schedule!$A:$A,"<"&J12)) -> 0 | L12: =82-K12 -> 82 | O12: =IF(M12<>"",M12,MIN(D12,L12)) -> 75 | P12: =IF(N12<>"",N12,E12) -> 35.9 | Q12: 2026-10-11: Booker is not playing in Saturday's preseason game against the Spurs due to rest, Hayden Cilley of ClutchPoints.com reports.
A13: Tyrese Maxey | B13: PHI | C13: PG,SG | D13: 75 | E13: 35.9 | F13: 70 | G13: 38 | H13: =IF(G13="","",E13-G13) -> -2.1 | K13: =IF(J13="",0,COUNTIFS(Schedule!$B:$B,B13,Schedule!$A:$A,"<"&J13)) -> 0 | L13: =82-K13 -> 82 | O13: =IF(M13<>"",M13,MIN(D13,L13)) -> 75 | P13: =IF(N13<>"",N13,E13) -> 35.9
A14: Kevin Durant | B14: HOU | C14: PF,SF,SG | D14: 75 | E14: 35.8 | F14: 78 | G14: 36.4 | H14: =IF(G14="","",E14-G14) -> -0.6 | I14: Day-To-Day | J14: 46310 | K14: =IF(J14="",0,COUNTIFS(Schedule!$B:$B,B14,Schedule!$A:$A,"<"&J14)) -> 0 | L14: =82-K14 -> 82 | O14: =IF(M14<>"",M14,MIN(D14,L14)) -> 75 | P14: =IF(N14<>"",N14,E14) -> 35.8 | Q14: 2026-10-09: Durant will not play in Sunday's preseason rematch against Dallas, Varun Shankar of the Houston Chronicle reports. The forward finished Friday's preseason contest with 15 points (7-12 FG, 1-1 3Pt, 0-1 FT), two assists and one block in 23 minutes.
A15: Victor Wembanyama | B15: SAS | C15: C | D15: 73 | E15: 31.9 | F15: 64 | G15: 29.2 | H15: =IF(G15="","",E15-G15) -> 2.7 | K15: =IF(J15="",0,COUNTIFS(Schedule!$B:$B,B15,Schedule!$A:$A,"<"&J15)) -> 0 | L15: =82-K15 -> 82 | O15: =IF(M15<>"",M15,MIN(D15,L15)) -> 73 | P15: =IF(N15<>"",N15,E15) -> 31.9
A16: Jaylen Brown | B16: PHI | C16: PF,SF,SG | D16: 75 | E16: 33.5 | F16: 71 | G16: 34.4 | H16: =IF(G16="","",E16-G16) -> -0.9 | I16: Day-To-Day | J16: 46311 | K16: =IF(J16="",0,COUNTIFS(Schedule!$B:$B,B16,Schedule!$A:$A,"<"&J16)) -> 0 | L16: =82-K16 -> 82 | O16: =IF(M16<>"",M16,MIN(D16,L16)) -> 75 | P16: =IF(N16<>"",N16,E16) -> 33.5 | Q16: 2026-10-10: Brown (rest) won't suit up for Saturday's preseason game in Boston, Tony Jones of The Athletic reports.
A17: Kawhi Leonard | B17: TOR | C17: PF,SF,SG | D17: 69 | E17: 32.3 | F17: 65 | G17: 32.1 | H17: =IF(G17="","",E17-G17) -> 0.2 | I17: Day-To-Day | J17: 46308 | K17: =IF(J17="",0,COUNTIFS(Schedule!$B:$B,B17,Schedule!$A:$A,"<"&J17)) -> 0 | L17: =82-K17 -> 82 | O17: =IF(M17<>"",M17,MIN(D17,L17)) -> 69 | P17: =IF(N17<>"",N17,E17) -> 32.3 | Q17: 2026-10-09: Leonard (not injury related) won't suit up for Saturday's exhibition against the Clippers, Tomer Azarly of ClutchPoints.com reports.
A18: Cade Cunningham | B18: DET | C18: PG,SG | D18: 74 | E18: 35.1 | F18: 64 | G18: 33.9 | H18: =IF(G18="","",E18-G18) -> 1.2 | I18: Day-To-Day | J18: 46309 | K18: =IF(J18="",0,COUNTIFS(Schedule!$B:$B,B18,Schedule!$A:$A,"<"&J18)) -> 0 | L18: =82-K18 -> 82 | O18: =IF(M18<>"",M18,MIN(D18,L18)) -> 74 | P18: =IF(N18<>"",N18,E18) -> 35.1 | Q18: 2026-10-11: Cunningham (rest) didn't play in Saturday's 114-108 preseason loss to the Wizards.
A19: Kyrie Irving | B19: DAL | C19: PG | D19: 69 | E19: 35 | H19: =IF(G19="","",E19-G19) | K19: =IF(J19="",0,COUNTIFS(Schedule!$B:$B,B19,Schedule!$A:$A,"<"&J19)) -> 0 | L19: =82-K19 -> 82 | O19: =IF(M19<>"",M19,MIN(D19,L19)) -> 69 | P19: =IF(N19<>"",N19,E19) -> 35
A20: Paolo Banchero | B20: ORL | C20: PF,SF | D20: 74 | E20: 34.8 | F20: 72 | G20: 34.8 | H20: =IF(G20="","",E20-G20) -> 0 | K20: =IF(J20="",0,COUNTIFS(Schedule!$B:$B,B20,Schedule!$A:$A,"<"&J20)) -> 0 | L20: =82-K20 -> 82 | O20: =IF(M20<>"",M20,MIN(D20,L20)) -> 74 | P20: =IF(N20<>"",N20,E20) -> 34.8
A21: Cooper Flagg | B21: DAL | C21: PF,SF,SG | D21: 75 | E21: 34.7 | F21: 70 | G21: 33.5 | H21: =IF(G21="","",E21-G21) -> 1.2 | K21: =IF(J21="",0,COUNTIFS(Schedule!$B:$B,B21,Schedule!$A:$A,"<"&J21)) -> 0 | L21: =82-K21 -> 82 | O21: =IF(M21<>"",M21,MIN(D21,L21)) -> 75 | P21: =IF(N21<>"",N21,E21) -> 34.7
A22: Austin Reaves | B22: LAL | C22: PG,SF,SG | D22: 73 | E22: 35.8 | F22: 51 | G22: 34.5 | H22: =IF(G22="","",E22-G22) -> 1.3 | K22: =IF(J22="",0,COUNTIFS(Schedule!$B:$B,B22,Schedule!$A:$A,"<"&J22)) -> 0 | L22: =82-K22 -> 82 | O22: =IF(M22<>"",M22,MIN(D22,L22)) -> 73 | P22: =IF(N22<>"",N22,E22) -> 35.8
A23: LaMelo Ball | B23: MIN | C23: PG | D23: 73 | E23: 31.3 | F23: 72 | G23: 28 | H23: =IF(G23="","",E23-G23) -> 3.3 | I23: Day-To-Day | J23: 46307 | K23: =IF(J23="",0,COUNTIFS(Schedule!$B:$B,B23,Schedule!$A:$A,"<"&J23)) -> 0 | L23: =82-K23 -> 82 | O23: =IF(M23<>"",M23,MIN(D23,L23)) -> 73 | P23: =IF(N23<>"",N23,E23) -> 31.3 | Q23: 2026-10-10: Ball (rest) has been ruled out for Saturday's preseason game against the Heat.
A24: Jamal Murray | B24: DEN | C24: PG | D24: 74 | E24: 35.7 | F24: 75 | G24: 35.4 | H24: =IF(G24="","",E24-G24) -> 0.3 | K24: =IF(J24="",0,COUNTIFS(Schedule!$B:$B,B24,Schedule!$A:$A,"<"&J24)) -> 0 | L24: =82-K24 -> 82 | O24: =IF(M24<>"",M24,MIN(D24,L24)) -> 74 | P24: =IF(N24<>"",N24,E24) -> 35.7
A25: Deni Avdija | B25: POR | C25: PF,SF,SG | D25: 75 | E25: 33.7 | F25: 66 | G25: 33.3 | H25: =IF(G25="","",E25-G25) -> 0.4 | K25: =IF(J25="",0,COUNTIFS(Schedule!$B:$B,B25,Schedule!$A:$A,"<"&J25)) -> 0 | L25: =82-K25 -> 82 | O25: =IF(M25<>"",M25,MIN(D25,L25)) -> 75 | P25: =IF(N25<>"",N25,E25) -> 33.7
A26: Damian Lillard | B26: POR | C26: PG | D26: 72 | E26: 33.5 | H26: =IF(G26="","",E26-G26) | K26: =IF(J26="",0,COUNTIFS(Schedule!$B:$B,B26,Schedule!$A:$A,"<"&J26)) -> 0 | L26: =82-K26 -> 82 | O26: =IF(M26<>"",M26,MIN(D26,L26)) -> 72 | P26: =IF(N26<>"",N26,E26) -> 33.5
A27: Franz Wagner | B27: ORL | C27: PF,SF | D27: 72 | E27: 33.4 | F27: 34 | G27: 30 | H27: =IF(G27="","",E27-G27) -> 3.4 | K27: =IF(J27="",0,COUNTIFS(Schedule!$B:$B,B27,Schedule!$A:$A,"<"&J27)) -> 0 | L27: =82-K27 -> 82 | O27: =IF(M27<>"",M27,MIN(D27,L27)) -> 72 | P27: =IF(N27<>"",N27,E27) -> 33.4
A28: Lauri Markkanen | B28: UTH | C28: SF,PF | D28: 74 | E28: 33.2 | F28: 42 | G28: 34.4 | H28: =IF(G28="","",E28-G28) -> -1.2 | I28: Day-To-Day | J28: 46307 | K28: =IF(J28="",0,COUNTIFS(Schedule!$B:$B,B28,Schedule!$A:$A,"<"&J28)) -> 0 | L28: =82-K28 -> 82 | O28: =IF(M28<>"",M28,MIN(D28,L28)) -> 74 | P28: =IF(N28<>"",N28,E28) -> 33.2 | Q28: 2026-10-07: Markkanen won't play in Tuesday's preseason game against the Nuggets due to neck soreness.
A29: Zion Williamson | B29: NOR | C29: C,PF | D29: 69 | E29: 30 | F29: 62 | G29: 29.7 | H29: =IF(G29="","",E29-G29) -> 0.3 | K29: =IF(J29="",0,COUNTIFS(Schedule!$B:$B,B29,Schedule!$A:$A,"<"&J29)) -> 0 | L29: =82-K29 -> 82 | O29: =IF(M29<>"",M29,MIN(D29,L29)) -> 69 | P29: =IF(N29<>"",N29,E29) -> 30
A30: Pascal Siakam | B30: IND | C30: C,PF,SF | D30: 76 | E30: 33.8 | F30: 62 | G30: 33.2 | H30: =IF(G30="","",E30-G30) -> 0.6 | K30: =IF(J30="",0,COUNTIFS(Schedule!$B:$B,B30,Schedule!$A:$A,"<"&J30)) -> 0 | L30: =82-K30 -> 82 | O30: =IF(M30<>"",M30,MIN(D30,L30)) -> 76 | P30: =IF(N30<>"",N30,E30) -> 33.8
A31: Anthony Davis | B31: WAS | C31: PF,C | D31: 70 | E31: 32.3 | F31: 20 | G31: 31.3 | H31: =IF(G31="","",E31-G31) -> 1 | K31: =IF(J31="",0,COUNTIFS(Schedule!$B:$B,B31,Schedule!$A:$A,"<"&J31)) -> 0 | L31: =82-K31 -> 82 | O31: =IF(M31<>"",M31,MIN(D31,L31)) -> 70 | P31: =IF(N31<>"",N31,E31) -> 32.3
A32: Tyler Herro | B32: MIL | C32: PG,SG | D32: 73 | E32: 34.2 | F32: 33 | G32: 31.3 | H32: =IF(G32="","",E32-G32) -> 2.9 | K32: =IF(J32="",0,COUNTIFS(Schedule!$B:$B,B32,Schedule!$A:$A,"<"&J32)) -> 0 | L32: =82-K32 -> 82 | O32: =IF(M32<>"",M32,MIN(D32,L32)) -> 73 | P32: =IF(N32<>"",N32,E32) -> 34.2
A33: Norman Powell | B33: CHI | C33: SG,SF | D33: 74 | E33: 32.5 | F33: 58 | G33: 29.6 | H33: =IF(G33="","",E33-G33) -> 2.9 | K33: =IF(J33="",0,COUNTIFS(Schedule!$B:$B,B33,Schedule!$A:$A,"<"&J33)) -> 0 | L33: =82-K33 -> 82 | O33: =IF(M33<>"",M33,MIN(D33,L33)) -> 74 | P33: =IF(N33<>"",N33,E33) -> 32.5
A34: LeBron James | B34: PHI | C34: SF,PF | D34: 68 | E34: 32.8 | F34: 60 | G34: 33.1 | H34: =IF(G34="","",E34-G34) -> -0.3 | I34: Day-To-Day | J34: 46311 | K34: =IF(J34="",0,COUNTIFS(Schedule!$B:$B,B34,Schedule!$A:$A,"<"&J34)) -> 0 | L34: =82-K34 -> 82 | O34: =IF(M34<>"",M34,MIN(D34,L34)) -> 68 | P34: =IF(N34<>"",N34,E34) -> 32.8 | Q34: 2026-10-10: James (rest) won't be available for Saturday's preseason contest against the Celtics, Tony Jones of The Athletic reports.
A35: Brandon Ingram | B35: LAC | C35: SG,SF,PF | D35: 64 | E35: 34.2 | F35: 77 | G35: 33.8 | H35: =IF(G35="","",E35-G35) -> 0.4 | I35: Out | J35: 46327 | K35: =IF(J35="",0,COUNTIFS(Schedule!$B:$B,B35,Schedule!$A:$A,"<"&J35)) -> 5 | L35: =82-K35 -> 77 | O35: =IF(M35<>"",M35,MIN(D35,L35)) -> 64 | P35: =IF(N35<>"",N35,E35) -> 34.2 | Q35: 2026-09-28: Ingram won't be ready for the start of the season due to a partially torn Achilles, per Joey Linn of SI.com.
A36: Jalen Johnson | B36: ATL | C36: PF,SF | D36: 75 | E36: 36.3 | F36: 72 | G36: 35.2 | H36: =IF(G36="","",E36-G36) -> 1.1 | K36: =IF(J36="",0,COUNTIFS(Schedule!$B:$B,B36,Schedule!$A:$A,"<"&J36)) -> 0 | L36: =82-K36 -> 82 | O36: =IF(M36<>"",M36,MIN(D36,L36)) -> 75 | P36: =IF(N36<>"",N36,E36) -> 36.3
A37: Trae Young | B37: WAS | C37: PG | D37: 75 | E37: 34.4 | F37: 15 | G37: 25.6 | H37: =IF(G37="","",E37-G37) -> 8.8 | K37: =IF(J37="",0,COUNTIFS(Schedule!$B:$B,B37,Schedule!$A:$A,"<"&J37)) -> 0 | L37: =82-K37 -> 82 | O37: =IF(M37<>"",M37,MIN(D37,L37)) -> 75 | P37: =IF(N37<>"",N37,E37) -> 34.4
A38: Karl-Anthony Towns | B38: NYK | C38: PF,C | D38: 74 | E38: 32.8 | F38: 75 | G38: 31 | H38: =IF(G38="","",E38-G38) -> 1.8 | K38: =IF(J38="",0,COUNTIFS(Schedule!$B:$B,B38,Schedule!$A:$A,"<"&J38)) -> 0 | L38: =82-K38 -> 82 | O38: =IF(M38<>"",M38,MIN(D38,L38)) -> 74 | P38: =IF(N38<>"",N38,E38) -> 32.8
A39: Brandon Miller | B39: CHA | C39: PF,SF,SG | D39: 73 | E39: 32.8 | F39: 65 | G39: 30.3 | H39: =IF(G39="","",E39-G39) -> 2.5 | K39: =IF(J39="",0,COUNTIFS(Schedule!$B:$B,B39,Schedule!$A:$A,"<"&J39)) -> 0 | L39: =82-K39 -> 82 | O39: =IF(M39<>"",M39,MIN(D39,L39)) -> 73 | P39: =IF(N39<>"",N39,E39) -> 32.8
A40: Michael Porter Jr. | B40: BKN | C40: SF,PF | D40: 74 | E40: 32.9 | F40: 52 | G40: 32.5 | H40: =IF(G40="","",E40-G40) -> 0.4 | I40: Day-To-Day | J40: 46307 | K40: =IF(J40="",0,COUNTIFS(Schedule!$B:$B,B40,Schedule!$A:$A,"<"&J40)) -> 0 | L40: =82-K40 -> 82 | O40: =IF(M40<>"",M40,MIN(D40,L40)) -> 74 | P40: =IF(N40<>"",N40,E40) -> 32.9 | Q40: 2026-10-08: Porter will not play in Thursday's preseason game against Philadelphia due to left wrist soreness, Brian Lewis of the New York Post reports.
...

Sheet Settings
A1: Category | B1: Weight | D1: League | F1: Notes | H1: Slot | I1: Count | K1: DIFF (ADP − RK) | L1: Meaning
A2: PTS | B2: 1 | D2: Number of Teams | F2: 12 | G2: Yahoo public prize leagues: 12 | H2: PG | I2: 1 | K2: ≥ +24 | L2: Steal (>2 rounds)
A3: REB | B3: 1 | D3: Players Drafted | F3: =F2*SUM(I2:I10) -> 156 | G3: teams × (starters + bench); IL excluded | H3: SG | I3: 1 | K3: +12 to +23 | L3: Potential steal (1–2 rounds)
A4: AST | B4: 1 | D4: Replacement Rank | F4: =F3+1 -> 157 | G4: first player left on waivers | H4: G | I4: 1 | K4: −12 to −23 | L4: Potential reach (1–2 rounds)
A5: STL | B5: 1 | D5: Value Pool | F5: =F3 -> 156 | G5: players the averages / stdevs are measured against | H5: SF | I5: 1 | K5: ≤ −24 | L5: Reach (>2 rounds)
A6: BLK | B6: 1 | H6: PF | I6: 1
A7: 3PM | B7: 1 | D7: Games Played Projection | F7: Yes | G7: "Yes" = projected GP, "No" = Flat GP for everyone | H7: F | I7: 1
A8: FG% | B8: 1 | D8: Flat GP | F8: 75 | G8: used when Games Played Projection is No | H8: C | I8: 2
A9: FT% | B9: 1 | H9: Util | I9: 2
A10: TO | B10: 1 | D10: Boost or Bust | F10: ON | G10: "ON" / "OFF" — your ADJ marks on The List | H10: BN | I10: 3
H11: IL | I11: 3
A12: 1 = counts, 0 = punt, or any weight in between. | D12: + + + | F12: 0.15 | G12: Multiplies every counting stat and attempt; FG% / FT% are unchanged.
A13: TO is scored in reverse automatically. | D13: + + | F13: 0.1 | H13: Max games played: 82 per slot
D14: + | F14: 0.05
D15: - | F15: -0.05
D16: - - | F16: -0.1
D17: - - - | F17: -0.15

Sheet Player Data
A1: Player | B1: Team | C1: Pos | D1: GP | E1: MIN | F1: PTS | G1: REB | H1: AST | I1: STL | J1: BLK | K1: 3PM | L1: TO | M1: FG% | N1: FT% | O1: FGA (est.) | P1: FTA (est.) | Q1: FTr source | R1: Yahoo ADP | S1: ESPN ADP
A2: Shai Gilgeous-Alexander | B2: OKC | C2: PG | D2: 77 | E2: 2641 | F2: 2421 | G2: 350 | H2: 484 | I2: 124 | J2: 63 | K2: 133 | L2: 180 | M2: 0.528 | N2: 0.887 | O2: 1584.5 | P2: 693.1 | Q2: 2025-26 (1321 FGA) | R2: 4 | S2: 2
A3: Giannis Antetokounmpo | B3: MIA | C3: PF,C | D3: 73 | E3: 2407 | F3: 2263 | G3: 828 | H3: 474 | I3: 79 | J3: 63 | K3: 26 | L3: 245 | M3: 0.607 | N3: 0.64 | O3: 1453.6 | P3: 738 | Q3: 2025-26 (598 FGA) | R3: 9 | S3: 5
A4: Luka Doncic | B4: LAL | C4: PG,SG | D4: 74 | E4: 2673 | F4: 2293 | G4: 588 | H4: 599 | I4: 115 | J4: 34 | K4: 272 | L4: 298 | M4: 0.469 | N4: 0.787 | O4: 1592.9 | P4: 669.4 | Q4: 2025-26 (1457 FGA) | R4: 3 | S4: 4
A5: Anthony Edwards | B5: MIN | C5: PG,SF,SG | D5: 75 | E5: 2693 | F5: 2151 | G5: 412 | H5: 318 | I5: 102 | J5: 57 | K5: 265 | L5: 222 | M5: 0.47 | N5: 0.808 | O5: 1551.3 | P5: 529.4 | Q5: 2025-26 (1231 FGA) | R5: 13 | S5: 6
A6: Jayson Tatum | B6: BOS | C6: SF,PF | D6: 74 | E6: 2671 | F6: 2043 | G6: 660 | H6: 421 | I6: 83 | J6: 34 | K6: 256 | L6: 229 | M6: 0.447 | N6: 0.819 | O6: 1610.5 | P6: 424 | Q6: 2025-26 (287 FGA) | R6: 8 | S6: 8
A7: Nikola Jokic | B7: DEN | C7: C | D7: 75 | E7: 2718 | F7: 2048 | G7: 933 | H7: 722 | I7: 111 | J7: 61 | K7: 125 | L7: 248 | M7: 0.563 | N7: 0.819 | O7: 1315.9 | P7: 538.9 | Q7: 2025-26 (1132 FGA) | R7: 2 | S7: 1
A8: Donovan Mitchell | B8: CLE | C8: PG,SG | D8: 75 | E8: 2488 | F8: 1996 | G8: 360 | H8: 415 | I8: 117 | J8: 22 | K8: 242 | L8: 194 | M8: 0.463 | N8: 0.842 | O8: 1487.9 | P8: 446.8 | Q8: 2025-26 (1403 FGA) | R8: 19 | S8: 21
A9: Jalen Brunson | B9: NYK | C9: PG | D9: 75 | E9: 2673 | F9: 1971 | G9: 245 | H9: 511 | I9: 65 | J9: 8 | K9: 190 | L9: 183 | M9: 0.473 | N9: 0.834 | O9: 1507.8 | P9: 425.2 | Q9: 2025-26 (1475 FGA) | R9: 21 | S9: 19
A10: Joel Embiid | B10: PHI | C10: C | D10: 59 | E10: 1827 | F10: 1522 | G10: 474 | H10: 239 | I10: 36 | J10: 70 | K10: 74 | L10: 173 | M10: 0.49 | N10: 0.861 | O10: 1061.3 | P10: 473.8 | Q10: 2025-26 (697 FGA) | R10: 49 | S10: 45
A11: Stephen Curry | B11: GSW | C11: PG | D11: 73 | E11: 2312 | F11: 1883 | G11: 304 | H11: 388 | I11: 81 | J11: 29 | K11: 336 | L11: 215 | M11: 0.452 | N11: 0.928 | O11: 1337.1 | P11: 364.6 | Q11: 2025-26 (799 FGA) | R11: 23 | S11: 18
A12: Devin Booker | B12: PHO | C12: PG,SG | D12: 75 | E12: 2690 | F12: 1914 | G12: 313 | H12: 483 | I12: 73 | J12: 21 | K12: 157 | L12: 219 | M12: 0.459 | N12: 0.882 | O12: 1374.3 | P12: 561.7 | Q12: 2025-26 (1198 FGA) | R12: 31 | S12: 17
A13: Tyrese Maxey | B13: PHI | C13: PG,SG | D13: 75 | E13: 2693 | F13: 1902 | G13: 284 | H13: 448 | I13: 119 | J13: 49 | K13: 207 | L13: 165 | M13: 0.468 | N13: 0.889 | O13: 1435.5 | P13: 395.3 | Q13: 2025-26 (1501 FGA) | R13: 7 | S13: 13
... A99: Jonathan Kuminga | B99: MIN | C99: PF,SF | D99: 72 | E99: 1853 | F99: 1061 | G99: 392 | H99: 167 | I99: 54 | J99: 30 | K99: 72 | L99: 133 | M99: 0.474 | N99: 0.702 | O99: 844.6 | P99: 268.2 | Q99: 2025-26 (339 FGA) | R99: 193 | S99: 144
A100: De'Andre Hunter | B100: SAC | C100: SF,PF | D100: 72 | E100: 1936 | F100: 1049 | G100: 270 | H100: 114 | I100: 48 | J100: 14 | K100: 133 | L100: 104 | M100: 0.455 | N100: 0.852 | O100: 801 | P100: 219.6 | Q100: 2025-26 (501 FGA) | R100: 98
A101: Jerami Grant | B101: MEM | C101: SF,PF | D101: 73 | E101: 1929 | F101: 1060 | G101: 203 | H101: 135 | I101: 48 | J101: 41 | K101: 145 | L101: 108 | M101: 0.442 | N101: 0.824 | O101: 754.4 | P101: 301.1 | Q101: 2025-26 (730 FGA) | S101: 176
A102: Keaton Wagler | B102: LAC | C102: PG,SG | D102: 74 | E102: 2016 | F102: 1060 | G102: 226 | H102: 314 | I102: 87 | J102: 14 | K102: 115 | L102: 166 | M102: 0.464 | N102: 0.817 | O102: 830.5 | P102: 213.4 | Q102: PG median | R102: 195 | S102: 177
A103: Ayo Dosunmu | B103: MIN | C103: PG,SF,SG | D103: 75 | E103: 2177 | F103: 1072 | G103: 264 | H103: 287 | I103: 75 | J103: 24 | K103: 124 | L103: 106 | M103: 0.512 | N103: 0.858 | O103: 788.7 | P103: 163.6 | Q103: 2025-26 (747 FGA) | R103: 127 | S103: 154
A104: Onyeka Okongwu | B104: ATL | C104: C | D104: 75 | E104: 2263 | F104: 1060 | G104: 564 | H104: 207 | I104: 75 | J104: 72 | K104: 113 | L104: 109 | M104: 0.506 | N104: 0.759 | O104: 786.9 | P104: 198.5 | Q104: 2025-26 (860 FGA) | R104: 57 | S104: 78
A105: Tobias Harris | B105: SAS | C105: PF,SF | D105: 75 | E105: 2282 | F105: 1047 | G105: 426 | H105: 181 | I105: 69 | J105: 44 | K105: 100 | L105: 75 | M105: 0.474 | N105: 0.865 | O105: 820.2 | P105: 195.9 | Q105: 2025-26 (659 FGA) | R105: 191 | S105: 109
A106: Cedric Coward | B106: MEM | C106: SF,SG | D106: 74 | E106: 2018 | F106: 1031 | G106: 428 | H106: 204 | I106: 49 | J106: 33 | K106: 116 | L106: 127 | M106: 0.481 | N106: 0.854 | O106: 776.3 | P106: 197 | Q106: 2025-26 (648 FGA) | R106: 118
A107: Brandin Podziemski | B107: GSW | C107: PG,SG | D107: 79 | E107: 2346 | F107: 1105 | G107: 423 | H107: 299 | I107: 95 | J107: 16 | K107: 160 | L107: 128 | M107: 0.447 | N107: 0.786 | O107: 851.7 | P107: 233.6 | Q107: 2025-26 (866 FGA) | R107: 147 | S107: 151
