Workbook

Sheet Settings
A1: Scoring System | B1: Points | C1: Categories | E1: Pos | F1: Players Selected Over Replacement | H1: Starting Lineup | I1: Position Based | J1: Draft Based | K1: Replacement Player FP | M1: Column | N1: Colour Legend
A2: Goals | B2: 6 | C2: 1 | E2: C | F2: {=ROUND(IF(E$21="Position",I2,IF(E$21="Draft",ROUND(J2*(H2/2)*($E$24/12),0),AVERAGE(I2,ROUND(J2*(H2/2)*($E$24/12),0)))),0)} -> 23 | H2: 2 | I2: {=H2*E$24} -> 24 | J2: 21 | K2: {=_xlfn.XLOOKUP(0,'C'!F3:F210,'C'!E3:E210)} -> 6.3600096 | M2: Team | N2: Weak Defensive SOS for Skaters, Offensive SOS for Goalies
A3: Assists | B3: 4 | C3: 1 | E3: LW | F3: {=ROUND(IF(E$21="Position",I3,IF(E$21="Draft",ROUND(J3*(H3/2)*($E$24/12),0),AVERAGE(I3,ROUND(J3*(H3/2)*($E$24/12),0)))),0)} -> 21 | H3: 2 | I3: {=H3*E$24} -> 24 | J3: 17 | K3: {=_xlfn.XLOOKUP(0,LW!F3:F210,LW!E3:E210)} -> 6.8943856 | M3: Team | N3: Strong Defensive SOS for Skaters, Offensive SOS for Goalies
A4: Points | E4: RW | F4: {=ROUND(IF(E$21="Position",I4,IF(E$21="Draft",ROUND(J4*(H4/2)*($E$24/12),0),AVERAGE(I4,ROUND(J4*(H4/2)*($E$24/12),0)))),0)} -> 22 | H4: 2 | I4: {=H4*E$24} -> 24 | J4: 20 | K4: {=_xlfn.XLOOKUP(0,RW!F3:F210,RW!E3:E210)} -> 6.8872346 | M4: Team | N4: Off-day heavy (Sun, Mon, Wed, Fri)
A5: Shots | B5: 0.9 | C5: 1 | E5: D | F5: {=ROUND(IF(E$21="Position",I5,IF(E$21="Draft",ROUND(J5*(H5/4)*($E$24/12),0),AVERAGE(I5,ROUND(J5*(H5/4)*($E$24/12),0)))),0)} -> 37 | H5: 4 | I5: {=H5*E$24} -> 48 | J5: 25 | K5: {=_xlfn.XLOOKUP(0,D!F3:F204,D!E3:E204)} -> 0.56685091 | M5: Team | N5: On-day heavy (Tue, Thu, Sat)
A6: Blocks | B6: 1 | E6: G | F6: {=ROUND(IF(E$21="Position",I6,IF(E$21="Draft",ROUND(J6*(H6/2)*($E$24/12),0),AVERAGE(I6,ROUND(J6*(H6/2)*($E$24/12),0)))),0)} -> 21 | H6: 2 | I6: {=H6*E$24} -> 24 | J6: 18 | K6: {=_xlfn.XLOOKUP(0,G!F3:F66,G!E3:E66)} -> 2.0381853
A7: Hits | C7: 1 | M7: Age | N7: Pre-Prime, chance to breakout
A8: Powerplay Goals | E8: Average Draft Position | H8: “Yahoo” or “Fantrax” or “Average” | M8: Age | N8: Post-Prime, chance to decline
A9: Powerplay Points | B9: 2 | C9: 1 | E9: YAHOO
A10: Shorthanded Goals | M10: Salary | N10: Contract Year
A11: Shorthanded Points | B11: 2 | E11: Games Played Projection | H11: “Yes” or “No”
A12: Time On Ice | E12: Yes | M12: ADP Diff | N12: Steal (>2 RD Difference)
A13: Defensemen Points | M13: ADP Diff | N13: Potential Steal (1-2 RD Difference)
A14: Plus-Minus | C14: 1 | E14: League Type | H14: “Points” or “Categories” | M14: ADP Diff | N14: Potential Reach (1-2 RD Difference)
A15: Penalty Minutes | E15: Categories | M15: ADP Diff | N15: Reach (>2 RD Difference)
A16: Game-Winning Goals
A17: Faceoff Wins | E17: Forward Separation | H17: “C/LW/RW” or “Forwards” | M17: TOI | N17: Role Increase (>1 min)
A18: Faceoff Losses | E18: C/LW/RW | M18: TOI | N18: Role Decrease (>1 min)
A19: Faceoff Percentage
E20: Replacement Level | H20: “Position” or “Draft” or “Blend” | M20: PPG | N20: PP1 (>60% of TOI)
A21: Wins | B21: 3 | C21: 1 | E21: Blend | M21: PPP | N21: PP1 (50-60% of TOI)
A22: Losses
A23: Overtime Losses | E23: Number of Teams
A24: Shutouts | B24: 1 | C24: 1 | E24: 12
A25: Saves | B25: 0.5
A26: Save Percentage | C26: 1 | E26: Boost or Bust | H26: How much a player’s projection moves up or down based on subjective opinion
A27: Goals Against | B27: -3 | E27: ON
A28: Goals Against Average | C28: 1 | E28: + + + | F28: 0.2 | H28: “ON” or “OFF” to toggle subjective boosts/busts from Shayna and Dom
A29: Games Played | E29: + + | F29: 0.1
E30: + | F30: 0.05 | H30: Skater Stats Affected: G, A, PTS, SOG, PPG, PPP, +/-, GWG Goalie Stats Affected: W, L, SV, GA, SV%, GAA
E31: - | F31: -0.05
E32: - - | F32: -0.1
E33: - - - | F33: -0.2

Sheet The List
A1: RK | B1: NAME | C1: KEEP? | D1: POS | F1: TEAM | G1: AGE | H1: SALARY | I1: FP | J1: /GP | K1: VORP | L1: /$ | M1: ADP | N1: DIFF. | P1: ADJ | Q1: GP | R1: TOI | S1: G | T1: A | U1: PTS | V1: SOG | W1: PPG | X1: PPP | Y1: SHG | Z1: SHP | AA1: BLK | AB1: HIT | AC1: +/- | AD1: PIM | AE1: GWG | AF1: FOW | AG1: FOL | AH1: FO% | AJ1: GP | AK1: W | AL1: L | AM1: OTL | AN1: SO | AO1: SV | AP1: GA | AQ1: SV% | AR1: GAA
A2: =RANK(K2,K$2:K$671) -> 3 | B2: Cale Makar | C2: N | D2: {=VLOOKUP(B2,'Player Data'!A1:D673,4,FALSE)} -> D | E2: {=VLOOKUP(B2,D!A1:C204,3,FALSE)} -> 1 | F2: {=VLOOKUP(B2,'Player Data'!A1:B673,2,FALSE)} -> COL | G2: {=VLOOKUP(B2,'Player Data'!A1:D673,3,FALSE)} -> 27 | H2: {=IFERROR(VLOOKUP(B2,ADP!A1:F671,6,FALSE)/1000000,VLOOKUP(B2,ADP!A1:F671,6,FALSE))} -> 9 | I2: =IF(Settings!$E$15="POINTS",((R2*Q2)*Settings!$B$12)+(S2*Settings!$B$2)+(T2*Settings!$B$3)+(U2*Settings!$B$4)+(V2*Settings!$B$5)+(X2*Settings!$B$9)+(AA2*Settings!$B$6)+(W2*Settings!$B$8)+(AB2*Settings!$B$7)+(AC2*Settings!$B$14)+(AD2*Settings!$B$15)+(AE2*Settings!$B$16)+(AF2*Settings!$B$17)+(AG2*Settings!$B$18)+(U2*Settings!$B$13)+(Y2*Settings!$B$10)+(Z2*Settings!$B$11),VLOOKUP(B2,'Standard Deviations'!A$1:C$672,3,FALSE)) -> 9.279134 | J2: {=IF(D2="G",I2/AJ2,I2/Q2)} -> 0.11316017 | K2: {=VLOOKUP(B2,D!A1:F204,6,FALSE)} -> 8.7122831 | L2: {=IFERROR(K2/H2,"N/A")} -> 0.96803145 | M2: 7.3 | N2: {=IFERROR(M2-A2,"N/A")} -> 4.3 | P2: {=_xlfn.XLOOKUP($B2,ADP!A2:A671,ADP!G2:G671)} -> 0 | Q2: {=IF(Settings!$E$12="YES",VLOOKUP(B2,'Player Data'!A1:E673,5,FALSE),84)} -> 82 | R2: {=VLOOKUP(B2,'Player Data'!$A1:$AE673,6,FALSE)} -> 25.3 | S2: {=VLOOKUP(B2,'Player Data'!$A1:$AE673,7,FALSE)*$Q2*IFERROR((VLOOKUP(P2,Settings!$E$28:$F$33,2,FALSE)+1),1)} -> 22.14 | T2: {=VLOOKUP(B2,'Player Data'!$A1:$AE673,8,FALSE)*$Q2*IFERROR((VLOOKUP(P2,Settings!$E$28:$F$33,2,FALSE)+1),1)} -> 63.96 | U2: {=SUM(S2:T2)} -> 86.1 | V2: {=VLOOKUP(B2,'Player Data'!$A1:$AE673,10,FALSE)*$Q2*IFERROR(((VLOOKUP(P2,Settings!$E$28:$F$33,2,FALSE)/2)+1),1)} -> 225.5 | W2: {=VLOOKUP(B2,'Player Data'!$A1:$AE673,11,FALSE)*$Q2*IFERROR((VLOOKUP(P2,Settings!$E$28:$F$33,2,FALSE)+1),1)} -> 6.56 | X2: {=VLOOKUP(B2,'Player Data'!$A1:$AE673,12,FALSE)*$Q2*IFERROR((VLOOKUP(P2,Settings!$E$28:$F$33,2,FALSE)+1),1)} -> 33.62 | Y2: {=VLOOKUP(B2,'Player Data'!$A1:$AE673,13,FALSE)*$Q2} -> 0.82 | Z2: {=VLOOKUP(B2,'Player Data'!$A1:$AE673,14,FALSE)*$Q2} -> 1.64 | AA2: {=VLOOKUP(B2,'Player Data'!$A1:$AE673,15,FALSE)*$Q2} -> 132.84 | AB2: {=VLOOKUP(B2,'Player Data'!$A1:$AE673,16,FALSE)*$Q2} -> 51.66 | AC2: {=VLOOKUP(B2,'Player Data'!$A1:$AE673,17,FALSE)*$Q2*IFERROR((VLOOKUP(P2,Settings!$E$28:$F$33,2,FALSE)+1),1)} -> 9.84 | AD2: {=VLOOKUP(B2,'Player Data'!$A1:$AE673,18,FALSE)*$Q2} -> 24.6 | AE2: {=VLOOKUP(B2,'Player Data'!$A1:$AE673,19,FALSE)*$Q2*IFERROR((VLOOKUP(P2,Settings!$E$28:$F$33,2,FALSE)+1),1)} -> 4.1 | AF2: {=VLOOKUP(B2,'Player Data'!$A1:$AE673,20,FALSE)*$Q2} -> 0 | AG2: {=VLOOKUP(B2,'Player Data'!$A1:$AE673,21,FALSE)*$Q2} -> 0 | AH2: {=VLOOKUP(B2,'Player Data'!$A1:$AE673,22,FALSE)} -> 0
A3: =RANK(K3,K$2:K$671) -> 1 | B3: Nathan MacKinnon | C3: N | D3: {=VLOOKUP(B3,'Player Data'!A1:D673,4,FALSE)} -> C | E3: {=VLOOKUP(B3,'C'!A1:C210,3,FALSE)} -> 1 | F3: {=VLOOKUP(B3,'Player Data'!A1:B673,2,FALSE)} -> COL | G3: {=VLOOKUP(B3,'Player Data'!A1:D673,3,FALSE)} -> 31 | H3: {=IFERROR(VLOOKUP(B3,ADP!A1:F671,6,FALSE)/1000000,VLOOKUP(B3,ADP!A1:F671,6,FALSE))} -> 12.6 | I3: =IF(Settings!$E$15="POINTS",((R3*Q3)*Settings!$B$12)+(S3*Settings!$B$2)+(T3*Settings!$B$3)+(U3*Settings!$B$4)+(V3*Settings!$B$5)+(X3*Settings!$B$9)+(AA3*Settings!$B$6)+(W3*Settings!$B$8)+(AB3*Settings!$B$7)+(AC3*Settings!$B$14)+(AD3*Settings!$B$15)+(AE3*Settings!$B$16)+(AF3*Settings!$B$17)+(AG3*Settings!$B$18)+(Y3*Settings!$B$10)+(Z3*Settings!$B$11),VLOOKUP(B3,'Standard Deviations'!A$1:C$672,3,FALSE)) -> 15.810473 | J3: {=IF(D3="G",I3/AJ3,I3/Q3)} -> 0.19048763 | K3: {=IF(Settings!$E$18="C/LW/RW",VLOOKUP(B3,'C'!A1:F210,6,FALSE),VLOOKUP(B3,F!A1:F407,6,FALSE))} -> 9.4504636 | L3: {=IFERROR(K3/H3,"N/A")} -> 0.75003679 | M3: 2.4 | N3: {=IFERROR(M3-A3,"N/A")} -> 1.4 | P3: {=_xlfn.XLOOKUP($B3,ADP!A2:A671,ADP!G2:G671)} -> 0 | Q3: {=IF(Settings!$E$12="YES",VLOOKUP(B3,'Player Data'!A1:E673,5,FALSE),84)} -> 83 | R3: {=VLOOKUP(B3,'Player Data'!$A1:$AE673,6,FALSE)} -> 22 | S3: {=VLOOKUP(B3,'Player Data'!$A1:$AE673,7,FALSE)*$Q3*IFERROR((VLOOKUP(P3,Settings!$E$28:$F$33,2,FALSE)+1),1)} -> 45.65 | T3: {=VLOOKUP(B3,'Player Data'!$A1:$AE673,8,FALSE)*$Q3*IFERROR((VLOOKUP(P3,Settings!$E$28:$F$33,2,FALSE)+1),1)} -> 77.19 | U3: {=SUM(S3:T3)} -> 122.84 | V3: {=VLOOKUP(B3,'Player Data'!$A1:$AE673,10,FALSE)*$Q3*IFERROR(((VLOOKUP(P3,Settings!$E$28:$F$33,2,FALSE)/2)+1),1)} -> 350.26 | W3: {=VLOOKUP(B3,'Player Data'!$A1:$AE673,11,FALSE)*$Q3*IFERROR((VLOOKUP(P3,Settings!$E$28:$F$33,2,FALSE)+1),1)} -> 9.96 | X3: {=VLOOKUP(B3,'Player Data'!$A1:$AE673,12,FALSE)*$Q3*IFERROR((VLOOKUP(P3,Settings!$E$28:$F$33,2,FALSE)+1),1)} -> 34.03 | Y3: {=VLOOKUP(B3,'Player Data'!$A1:$AE673,13,FALSE)*$Q3} -> 0 | Z3: {=VLOOKUP(B3,'Player Data'!$A1:$AE673,14,FALSE)*$Q3} -> 0 | AA3: {=VLOOKUP(B3,'Player Data'!$A1:$AE673,15,FALSE)*$Q3} -> 44.82 | AB3: {=VLOOKUP(B3,'Player Data'!$A1:$AE673,16,FALSE)*$Q3} -> 58.1 | AC3: {=VLOOKUP(B3,'Player Data'!$A1:$AE673,17,FALSE)*$Q3*IFERROR((VLOOKUP(P3,Settings!$E$28:$F$33,2,FALSE)+1),1)} -> 14.11 | AD3: {=VLOOKUP(B3,'Player Data'!$A1:$AE673,18,FALSE)*$Q3} -> 34.03 | AE3: {=VLOOKUP(B3,'Player Data'!$A1:$AE673,19,FALSE)*$Q3*IFERROR((VLOOKUP(P3,Settings!$E$28:$F$33,2,FALSE)+1),1)} -> 8.3 | AF3: {=VLOOKUP(B3,'Player Data'!$A1:$AE673,20,FALSE)*$Q3} -> 681.43 | AG3: {=VLOOKUP(B3,'Player Data'!$A1:$AE673,21,FALSE)*$Q3} -> 697.2 | AH3: {=VLOOKUP(B3,'Player Data'!$A1:$AE673,22,FALSE)} -> 0.49
A4: =RANK(K4,K$2:K$671) -> 2 | B4: Connor McDavid | C4: N | D4: {=VLOOKUP(B4,'Player Data'!A1:D673,4,FALSE)} -> C | E4: {=VLOOKUP(B4,'C'!A1:C210,3,FALSE)} -> 2 | F4: {=VLOOKUP(B4,'Player Data'!A1:B673,2,FALSE)} -> EDM | G4: {=VLOOKUP(B4,'Player Data'!A1:D673,3,FALSE)} -> 29 | H4: {=IFERROR(VLOOKUP(B4,ADP!A1:F671,6,FALSE)/1000000,VLOOKUP(B4,ADP!A1:F671,6,FALSE))} -> 12.5 | I4: =IF(Settings!$E$15="POINTS",((R4*Q4)*Settings!$B$12)+(S4*Settings!$B$2)+(T4*Settings!$B$3)+(U4*Settings!$B$4)+(V4*Settings!$B$5)+(X4*Settings!$B$9)+(AA4*Settings!$B$6)+(W4*Settings!$B$8)+(AB4*Settings!$B$7)+(AC4*Settings!$B$14)+(AD4*Settings!$B$15)+(AE4*Settings!$B$16)+(AF4*Settings!$B$17)+(AG4*Settings!$B$18)+(Y4*Settings!$B$10)+(Z4*Settings!$B$11),VLOOKUP(B4,'Standard Deviations'!A$1:C$672,3,FALSE)) -> 15.623747 | J4: {=IF(D4="G",I4/AJ4,I4/Q4)} -> 0.19288576 | K4: {=IF(Settings!$E$18="C/LW/RW",VLOOKUP(B4,'C'!A1:F210,6,FALSE),VLOOKUP(B4,F!A1:F407,6,FALSE))} -> 9.2637369 | L4: {=IFERROR(K4/H4,"N/A")} -> 0.74109896 | M4: 1.5 | N4: {=IFERROR(M4-A4,"N/A")} -> -0.5 | P4: {=_xlfn.XLOOKUP($B4,ADP!A2:A671,ADP!G2:G671)} -> 0 | Q4: {=IF(Settings!$E$12="YES",VLOOKUP(B4,'Player Data'!A1:E673,5,FALSE),84)} -> 81 | R4: {=VLOOKUP(B4,'Player Data'!$A1:$AE673,6,FALSE)} -> 22 | S4: {=VLOOKUP(B4,'Player Data'!$A1:$AE673,7,FALSE)*$Q4*IFERROR((VLOOKUP(P4,Settings!$E$28:$F$33,2,FALSE)+1),1)} -> 39.69 | T4: {=VLOOKUP(B4,'Player Data'!$A1:$AE673,8,FALSE)*$Q4*IFERROR((VLOOKUP(P4,Settings!$E$28:$F$33,2,FALSE)+1),1)} -> 90.72 | U4: {=SUM(S4:T4)} -> 130.41 | V4: {=VLOOKUP(B4,'Player Data'!$A1:$AE673,10,FALSE)*$Q4*IFERROR(((VLOOKUP(P4,Settings!$E$28:$F$33,2,FALSE)/2)+1),1)} -> 281.88 | W4: {=VLOOKUP(B4,'Player Data'!$A1:$AE673,11,FALSE)*$Q4*IFERROR((VLOOKUP(P4,Settings!$E$28:$F$33,2,FALSE)+1),1)} -> 12.15 | X4: {=VLOOKUP(B4,'Player Data'!$A1:$AE673,12,FALSE)*$Q4*IFERROR((VLOOKUP(P4,Settings!$E$28:$F$33,2,FALSE)+1),1)} -> 50.22 | Y4: {=VLOOKUP(B4,'Player Data'!$A1:$AE673,13,FALSE)*$Q4} -> 0 | Z4: {=VLOOKUP(B4,'Player Data'!$A1:$AE673,14,FALSE)*$Q4} -> 0 | AA4: {=VLOOKUP(B4,'Player Data'!$A1:$AE673,15,FALSE)*$Q4} -> 29.16 | AB4: {=VLOOKUP(B4,'Player Data'!$A1:$AE673,16,FALSE)*$Q4} -> 47.79 | AC4: {=VLOOKUP(B4,'Player Data'!$A1:$AE673,17,FALSE)*$Q4*IFERROR((VLOOKUP(P4,Settings!$E$28:$F$33,2,FALSE)+1),1)} -> 10.53 | AD4: {=VLOOKUP(B4,'Player Data'!$A1:$AE673,18,FALSE)*$Q4} -> 38.07 | AE4: {=VLOOKUP(B4,'Player Data'!$A1:$AE673,19,FALSE)*$Q4*IFERROR((VLOOKUP(P4,Settings!$E$28:$F$33,2,FALSE)+1),1)} -> 6.48 | AF4: {=VLOOKUP(B4,'Player Data'!$A1:$AE673,20,FALSE)*$Q4} -> 437.4 | AG4: {=VLOOKUP(B4,'Player Data'!$A1:$AE673,21,FALSE)*$Q4} -> 450.36 | AH4: {=VLOOKUP(B4,'Player Data'!$A1:$AE673,22,FALSE)} -> 0.49
A5: =RANK(K5,K$2:K$671) -> 4 | B5: Evan Bouchard | C5: N | D5: {=VLOOKUP(B5,'Player Data'!A1:D673,4,FALSE)} -> D | E5: {=VLOOKUP(B5,D!A1:C204,3,FALSE)} -> 2 | F5: {=VLOOKUP(B5,'Player Data'!A1:B673,2,FALSE)} -> EDM | G5: {=VLOOKUP(B5,'Player Data'!A1:D673,3,FALSE)} -> 26 | H5: {=IFERROR(VLOOKUP(B5,ADP!A1:F671,6,FALSE)/1000000,VLOOKUP(B5,ADP!A1:F671,6,FALSE))} -> 10.5 | I5: =IF(Settings!$E$15="POINTS",((R5*Q5)*Settings!$B$12)+(S5*Settings!$B$2)+(T5*Settings!$B$3)+(U5*Settings!$B$4)+(V5*Settings!$B$5)+(X5*Settings!$B$9)+(AA5*Settings!$B$6)+(W5*Settings!$B$8)+(AB5*Settings!$B$7)+(AC5*Settings!$B$14)+(AD5*Settings!$B$15)+(AE5*Settings!$B$16)+(AF5*Settings!$B$17)+(AG5*Settings!$B$18)+(U5*Settings!$B$13)+(Y5*Settings!$B$10)+(Z5*Settings!$B$11),VLOOKUP(B5,'Standard Deviations'!A$1:C$672,3,FALSE)) -> 8.8388075 | J5: {=IF(D5="G",I5/AJ5,I5/Q5)} -> 0.1052239 | K5: {=VLOOKUP(B5,D!A1:F204,6,FALSE)} -> 8.2719566 | L5: {=IFERROR(K5/H5,"N/A")} -> 0.78780539 | M5: 18.9 | N5: {=IFERROR(M5-A5,"N/A")} -> 14.9 | P5: {=_xlfn.XLOOKUP($B5,ADP!A2:A671,ADP!G2:G671)} -> 0 | Q5: {=IF(Settings!$E$12="YES",VLOOKUP(B5,'Player Data'!A1:E673,5,FALSE),84)} -> 84 | R5: {=VLOOKUP(B5,'Player Data'!$A1:$AE673,6,FALSE)} -> 24.9 | S5: {=VLOOKUP(B5,'Player Data'!$A1:$AE673,7,FALSE)*$Q5*IFERROR((VLOOKUP(P5,Settings!$E$28:$F$33,2,FALSE)+1),1)} -> 17.64 | T5: {=VLOOKUP(B5,'Player Data'!$A1:$AE673,8,FALSE)*$Q5*IFERROR((VLOOKUP(P5,Settings!$E$28:$F$33,2,FALSE)+1),1)} -> 66.36 | U5: {=SUM(S5:T5)} -> 84 | V5: {=VLOOKUP(B5,'Player Data'!$A1:$AE673,10,FALSE)*$Q5*IFERROR(((VLOOKUP(P5,Settings!$E$28:$F$33,2,FALSE)/2)+1),1)} -> 228.48 | W5: {=VLOOKUP(B5,'Player Data'!$A1:$AE673,11,FALSE)*$Q5*IFERROR((VLOOKUP(P5,Settings!$E$28:$F$33,2,FALSE)+1),1)} -> 5.88 | X5: {=VLOOKUP(B5,'Player Data'!$A1:$AE673,12,FALSE)*$Q5*IFERROR((VLOOKUP(P5,Settings!$E$28:$F$33,2,FALSE)+1),1)} -> 34.44 | Y5: {=VLOOKUP(B5,'Player Data'!$A1:$AE673,13,FALSE)*$Q5} -> 0 | Z5: {=VLOOKUP(B5,'Player Data'!$A1:$AE673,14,FALSE)*$Q5} -> 1.68 | AA5: {=VLOOKUP(B5,'Player Data'!$A1:$AE673,15,FALSE)*$Q5} -> 115.08 | AB5: {=VLOOKUP(B5,'Player Data'!$A1:$AE673,16,FALSE)*$Q5} -> 43.68 | AC5: {=VLOOKUP(B5,'Player Data'!$A1:$AE673,17,FALSE)*$Q5*IFERROR((VLOOKUP(P5,Settings!$E$28:$F$33,2,FALSE)+1),1)} -> 9.24 | AD5: {=VLOOKUP(B5,'Player Data'!$A1:$AE673,18,FALSE)*$Q5} -> 36.12 | AE5: {=VLOOKUP(B5,'Player Data'!$A1:$AE673,19,FALSE)*$Q5*IFERROR((VLOOKUP(P5,Settings!$E$28:$F$33,2,FALSE)+1),1)} -> 3.36 | AF5: {=VLOOKUP(B5,'Player Data'!$A1:$AE673,20,FALSE)*$Q5} -> 0 | AG5: {=VLOOKUP(B5,'Player Data'!$A1:$AE673,21,FALSE)*$Q5} -> 0 | AH5: {=VLOOKUP(B5,'Player Data'!$A1:$AE673,22,FALSE)} -> 0
A6: =RANK(K6,K$2:K$671) -> 5 | B6: Quinn Hughes | C6: N | D6: {=VLOOKUP(B6,'Player Data'!A1:D673,4,FALSE)} -> D | E6: {=VLOOKUP(B6,D!A1:C204,3,FALSE)} -> 3 | F6: {=VLOOKUP(B6,'Player Data'!A1:B673,2,FALSE)} -> MIN | G6: {=VLOOKUP(B6,'Player Data'!A1:D673,3,FALSE)} -> 26 | H6: {=IFERROR(VLOOKUP(B6,ADP!A1:F671,6,FALSE)/1000000,VLOOKUP(B6,ADP!A1:F671,6,FALSE))} -> 7.85 | I6: =IF(Settings!$E$15="POINTS",((R6*Q6)*Settings!$B$12)+(S6*Settings!$B$2)+(T6*Settings!$B$3)+(U6*Settings!$B$4)+(V6*Settings!$B$5)+(X6*Settings!$B$9)+(AA6*Settings!$B$6)+(W6*Settings!$B$8)+(AB6*Settings!$B$7)+(AC6*Settings!$B$14)+(AD6*Settings!$B$15)+(AE6*Settings!$B$16)+(AF6*Settings!$B$17)+(AG6*Settings!$B$18)+(U6*Settings!$B$13)+(Y6*Settings!$B$10)+(Z6*Settings!$B$11),VLOOKUP(B6,'Standard Deviations'!A$1:C$672,3,FALSE)) -> 8.368205 | J6: {=IF(D6="G",I6/AJ6,I6/Q6)} -> 0.10331117 | K6: {=VLOOKUP(B6,D!A1:F204,6,FALSE)} -> 7.8013541 | L6: {=IFERROR(K6/H6,"N/A")} -> 0.99380307 | M6: 14.1 | N6: {=IFERROR(M6-A6,"N/A")} -> 9.1 | P6: {=_xlfn.XLOOKUP($B6,ADP!A2:A671,ADP!G2:G671)} -> 0 | Q6: {=IF(Settings!$E$12="YES",VLOOKUP(B6,'Player Data'!A1:E673,5,FALSE),84)} -> 81 | R6: {=VLOOKUP(B6,'Player Data'!$A1:$AE673,6,FALSE)} -> 27.7 | S6: {=VLOOKUP(B6,'Player Data'!$A1:$AE673,7,FALSE)*$Q6*IFERROR((VLOOKUP(P6,Settings!$E$28:$F$33,2,FALSE)+1),1)} -> 15.39 | T6: {=VLOOKUP(B6,'Player Data'!$A1:$AE673,8,FALSE)*$Q6*IFERROR((VLOOKUP(P6,Settings!$E$28:$F$33,2,FALSE)+1),1)} -> 76.95 | U6: {=SUM(S6:T6)} -> 92.34 | V6: {=VLOOKUP(B6,'Player Data'!$A1:$AE673,10,FALSE)*$Q6*IFERROR(((VLOOKUP(P6,Settings!$E$28:$F$33,2,FALSE)/2)+1),1)} -> 216.27 | W6: {=VLOOKUP(B6,'Player Data'!$A1:$AE673,11,FALSE)*$Q6*IFERROR((VLOOKUP(P6,Settings!$E$28:$F$33,2,FALSE)+1),1)} -> 4.05 | X6: {=VLOOKUP(B6,'Player Data'!$A1:$AE673,12,FALSE)*$Q6*IFERROR((VLOOKUP(P6,Settings!$E$28:$F$33,2,FALSE)+1),1)} -> 37.26 | Y6: {=VLOOKUP(B6,'Player Data'!$A1:$AE673,13,FALSE)*$Q6} -> 0 | Z6: {=VLOOKUP(B6,'Player Data'!$A1:$AE673,14,FALSE)*$Q6} -> 0 | AA6: {=VLOOKUP(B6,'Player Data'!$A1:$AE673,15,FALSE)*$Q6} -> 98.01 | AB6: {=VLOOKUP(B6,'Player Data'!$A1:$AE673,16,FALSE)*$Q6} -> 21.06 | AC6: {=VLOOKUP(B6,'Player Data'!$A1:$AE673,17,FALSE)*$Q6*IFERROR((VLOOKUP(P6,Settings!$E$28:$F$33,2,FALSE)+1),1)} -> 6.48 | AD6: {=VLOOKUP(B6,'Player Data'!$A1:$AE673,18,FALSE)*$Q6} -> 37.26 | AE6: {=VLOOKUP(B6,'Player Data'!$A1:$AE673,19,FALSE)*$Q6*IFERROR((VLOOKUP(P6,Settings!$E$28:$F$33,2,FALSE)+1),1)} -> 2.43 | AF6: {=VLOOKUP(B6,'Player Data'!$A1:$AE673,20,FALSE)*$Q6} -> 0 | AG6: {=VLOOKUP(B6,'Player Data'!$A1:$AE673,21,FALSE)*$Q6} -> 0 | AH6: {=VLOOKUP(B6,'Player Data'!$A1:$AE673,22,FALSE)} -> 0
A7: =RANK(K7,K$2:K$671) -> 7 | B7: Zach Werenski | C7: N | D7: {=VLOOKUP(B7,'Player Data'!A1:D673,4,FALSE)} -> D | E7: {=VLOOKUP(B7,D!A1:C204,3,FALSE)} -> 4 | F7: {=VLOOKUP(B7,'Player Data'!A1:B673,2,FALSE)} -> CBJ | G7: {=VLOOKUP(B7,'Player Data'!A1:D673,3,FALSE)} -> 29 | H7: {=IFERROR(VLOOKUP(B7,ADP!A1:F671,6,FALSE)/1000000,VLOOKUP(B7,ADP!A1:F671,6,FALSE))} -> 9.583 | I7: =IF(Settings!$E$15="POINTS",((R7*Q7)*Settings!$B$12)+(S7*Settings!$B$2)+(T7*Settings!$B$3)+(U7*Settings!$B$4)+(V7*Settings!$B$5)+(X7*Settings!$B$9)+(AA7*Settings!$B$6)+(W7*Settings!$B$8)+(AB7*Settings!$B$7)+(AC7*Settings!$B$14)+(AD7*Settings!$B$15)+(AE7*Settings!$B$16)+(AF7*Settings!$B$17)+(AG7*Settings!$B$18)+(U7*Settings!$B$13)+(Y7*Settings!$B$10)+(Z7*Settings!$B$11),VLOOKUP(B7,'Standard Deviations'!A$1:C$672,3,FALSE)) -> 7.5895483 | J7: {=IF(D7="G",I7/AJ7,I7/Q7)} -> 0.093698127 | K7: {=VLOOKUP(B7,D!A1:F204,6,FALSE)} -> 7.0226974 | L7: {=IFERROR(K7/H7,"N/A")} -> 0.73282869 | M7: 17.1 | N7: {=IFERROR(M7-A7,"N/A")} -> 10.1 | P7: {=_xlfn.XLOOKUP($B7,ADP!A2:A671,ADP!G2:G671)} -> 0 | Q7: {=IF(Settings!$E$12="YES",VLOOKUP(B7,'Player Data'!A1:E673,5,FALSE),84)} -> 81 | R7: {=VLOOKUP(B7,'Player Data'!$A1:$AE673,6,FALSE)} -> 27.1 | S7: {=VLOOKUP(B7,'Player Data'!$A1:$AE673,7,FALSE)*$Q7*IFERROR((VLOOKUP(P7,Settings!$E$28:$F$33,2,FALSE)+1),1)} -> 20.25 | T7: {=VLOOKUP(B7,'Player Data'!$A1:$AE673,8,FALSE)*$Q7*IFERROR((VLOOKUP(P7,Settings!$E$28:$F$33,2,FALSE)+1),1)} -> 61.56 | U7: {=SUM(S7:T7)} -> 81.81 | V7: {=VLOOKUP(B7,'Player Data'!$A1:$AE673,10,FALSE)*$Q7*IFERROR(((VLOOKUP(P7,Settings!$E$28:$F$33,2,FALSE)/2)+1),1)} -> 279.45 | W7: {=VLOOKUP(B7,'Player Data'!$A1:$AE673,11,FALSE)*$Q7*IFERROR((VLOOKUP(P7,Settings!$E$28:$F$33,2,FALSE)+1),1)} -> 4.86 | X7: {=VLOOKUP(B7,'Player Data'!$A1:$AE673,12,FALSE)*$Q7*IFERROR((VLOOKUP(P7,Settings!$E$28:$F$33,2,FALSE)+1),1)} -> 25.11 | Y7: {=VLOOKUP(B7,'Player Data'!$A1:$AE673,13,FALSE)*$Q7} -> 0 | Z7: {=VLOOKUP(B7,'Player Data'!$A1:$AE673,14,FALSE)*$Q7} -> 1.62 | AA7: {=VLOOKUP(B7,'Player Data'!$A1:$AE673,15,FALSE)*$Q7} -> 117.45 | AB7: {=VLOOKUP(B7,'Player Data'!$A1:$AE673,16,FALSE)*$Q7} -> 35.64 | AC7: {=VLOOKUP(B7,'Player Data'!$A1:$AE673,17,FALSE)*$Q7*IFERROR((VLOOKUP(P7,Settings!$E$28:$F$33,2,FALSE)+1),1)} -> 4.86 | AD7: {=VLOOKUP(B7,'Player Data'!$A1:$AE673,18,FALSE)*$Q7} -> 29.16 | AE7: {=VLOOKUP(B7,'Player Data'!$A1:$AE673,19,FALSE)*$Q7*IFERROR((VLOOKUP(P7,Settings!$E$28:$F$33,2,FALSE)+1),1)} -> 3.24 | AF7: {=VLOOKUP(B7,'Player Data'!$A1:$AE673,20,FALSE)*$Q7} -> 0 | AG7: {=VLOOKUP(B7,'Player Data'!$A1:$AE673,21,FALSE)*$Q7} -> 0 | AH7: {=VLOOKUP(B7,'Player Data'!$A1:$AE673,22,FALSE)} -> 0
A8: =RANK(K8,K$2:K$671) -> 8 | B8: Rasmus Dahlin | C8: N | D8: {=VLOOKUP(B8,'Player Data'!A1:D673,4,FALSE)} -> D | E8: {=VLOOKUP(B8,D!A1:C204,3,FALSE)} -> 5 | F8: {=VLOOKUP(B8,'Player Data'!A1:B673,2,FALSE)} -> BUF | G8: {=VLOOKUP(B8,'Player Data'!A1:D673,3,FALSE)} -> 26 | H8: {=IFERROR(VLOOKUP(B8,ADP!A1:F671,6,FALSE)/1000000,VLOOKUP(B8,ADP!A1:F671,6,FALSE))} -> 11 | I8: =IF(Settings!$E$15="POINTS",((R8*Q8)*Settings!$B$12)+(S8*Settings!$B$2)+(T8*Settings!$B$3)+(U8*Settings!$B$4)+(V8*Settings!$B$5)+(X8*Settings!$B$9)+(AA8*Settings!$B$6)+(W8*Settings!$B$8)+(AB8*Settings!$B$7)+(AC8*Settings!$B$14)+(AD8*Settings!$B$15)+(AE8*Settings!$B$16)+(AF8*Settings!$B$17)+(AG8*Settings!$B$18)+(U8*Settings!$B$13)+(Y8*Settings!$B$10)+(Z8*Settings!$B$11),VLOOKUP(B8,'Standard Deviations'!A$1:C$672,3,FALSE)) -> 7.355086 | J8: {=IF(D8="G",I8/AJ8,I8/Q8)} -> 0.090803531 | K8: {=VLOOKUP(B8,D!A1:F204,6,FALSE)} -> 6.7882351 | L8: {=IFERROR(K8/H8,"N/A")} -> 0.61711228 | M8: 35.8 | N8: {=IFERROR(M8-A8,"N/A")} -> 27.8 | P8: {=_xlfn.XLOOKUP($B8,ADP!A2:A671,ADP!G2:G671)} -> + + | Q8: {=IF(Settings!$E$12="YES",VLOOKUP(B8,'Player Data'!A1:E673,5,FALSE),84)} -> 81 | R8: {=VLOOKUP(B8,'Player Data'!$A1:$AE673,6,FALSE)} -> 24.2 | S8: {=VLOOKUP(B8,'Player Data'!$A1:$AE673,7,FALSE)*$Q8*IFERROR((VLOOKUP(P8,Settings!$E$28:$F$33,2,FALSE)+1),1)} -> 21.384 | T8: {=VLOOKUP(B8,'Player Data'!$A1:$AE673,8,FALSE)*$Q8*IFERROR((VLOOKUP(P8,Settings!$E$28:$F$33,2,FALSE)+1),1)} -> 56.133 | U8: {=SUM(S8:T8)} -> 77.517 | V8: {=VLOOKUP(B8,'Player Data'!$A1:$AE673,10,FALSE)*$Q8*IFERROR(((VLOOKUP(P8,Settings!$E$28:$F$33,2,FALSE)/2)+1),1)} -> 218.5785 | W8: {=VLOOKUP(B8,'Player Data'!$A1:$AE673,11,FALSE)*$Q8*IFERROR((VLOOKUP(P8,Settings!$E$28:$F$33,2,FALSE)+1),1)} -> 7.128 | X8: {=VLOOKUP(B8,'Player Data'!$A1:$AE673,12,FALSE)*$Q8*IFERROR((VLOOKUP(P8,Settings!$E$28:$F$33,2,FALSE)+1),1)} -> 24.948 | Y8: {=VLOOKUP(B8,'Player Data'!$A1:$AE673,13,FALSE)*$Q8} -> 0 | Z8: {=VLOOKUP(B8,'Player Data'!$A1:$AE673,14,FALSE)*$Q8} -> 0 | AA8: {=VLOOKUP(B8,'Player Data'!$A1:$AE673,15,FALSE)*$Q8} -> 100.44 | AB8: {=VLOOKUP(B8,'Player Data'!$A1:$AE673,16,FALSE)*$Q8} -> 84.24 | AC8: {=VLOOKUP(B8,'Player Data'!$A1:$AE673,17,FALSE)*$Q8*IFERROR((VLOOKUP(P8,Settings!$E$28:$F$33,2,FALSE)+1),1)} -> 5.346 | AD8: {=VLOOKUP(B8,'Player Data'!$A1:$AE673,18,FALSE)*$Q8} -> 60.75 | AE8: {=VLOOKUP(B8,'Player Data'!$A1:$AE673,19,FALSE)*$Q8*IFERROR((VLOOKUP(P8,Settings!$E$28:$F$33,2,FALSE)+1),1)} -> 3.564 | AF8: {=VLOOKUP(B8,'Player Data'!$A1:$AE673,20,FALSE)*$Q8} -> 0 | AG8: {=VLOOKUP(B8,'Player Data'!$A1:$AE673,21,FALSE)*$Q8} -> 0 | AH8: {=VLOOKUP(B8,'Player Data'!$A1:$AE673,22,FALSE)} -> 0
A9: =RANK(K9,K$2:K$671) -> 6 | B9: Nikita Kucherov | C9: N | D9: {=VLOOKUP(B9,'Player Data'!A1:D673,4,FALSE)} -> RW | E9: {=VLOOKUP(B9,RW!A1:F210,3,FALSE)} -> 1 | F9: {=VLOOKUP(B9,'Player Data'!A1:B673,2,FALSE)} -> T.B | G9: {=VLOOKUP(B9,'Player Data'!A1:D673,3,FALSE)} -> 33 | H9: {=IFERROR(VLOOKUP(B9,ADP!A1:F671,6,FALSE)/1000000,VLOOKUP(B9,ADP!A1:F671,6,FALSE))} -> 9.5 | I9: =IF(Settings!$E$15="POINTS",((R9*Q9)*Settings!$B$12)+(S9*Settings!$B$2)+(T9*Settings!$B$3)+(U9*Settings!$B$4)+(V9*Settings!$B$5)+(X9*Settings!$B$9)+(AA9*Settings!$B$6)+(W9*Settings!$B$8)+(AB9*Settings!$B$7)+(AC9*Settings!$B$14)+(AD9*Settings!$B$15)+(AE9*Settings!$B$16)+(AF9*Settings!$B$17)+(AG9*Settings!$B$18)+(Y9*Settings!$B$10)+(Z9*Settings!$B$11),VLOOKUP(B9,'Standard Deviations'!A$1:C$672,3,FALSE)) -> 14.596009 | J9: {=IF(D9="G",I9/AJ9,I9/Q9)} -> 0.17800011 | K9: {=IF(Settings!$E$18="C/LW/RW",VLOOKUP(B9,RW!A1:F210,6,FALSE),VLOOKUP(B9,F!A1:F407,6,FALSE))} -> 7.7087748 | L9: {=IFERROR(K9/H9,"N/A")} -> 0.81144998 | M9: 4.1 | N9: {=IFERROR(M9-A9,"N/A")} -> -1.9 | P9: {=_xlfn.XLOOKUP($B9,ADP!A2:A671,ADP!G2:G671)} -> 0 | Q9: {=IF(Settings!$E$12="YES",VLOOKUP(B9,'Player Data'!A1:E673,5,FALSE),84)} -> 82 | R9: {=VLOOKUP(B9,'Player Data'!$A1:$AE673,6,FALSE)} -> 20.3 | S9: {=VLOOKUP(B9,'Player Data'!$A1:$AE673,7,FALSE)*$Q9*IFERROR((VLOOKUP(P9,Settings!$E$28:$F$33,2,FALSE)+1),1)} -> 41 | T9: {=VLOOKUP(B9,'Player Data'!$A1:$AE673,8,FALSE)*$Q9*IFERROR((VLOOKUP(P9,Settings!$E$28:$F$33,2,FALSE)+1),1)} -> 85.28 | U9: {=SUM(S9:T9)} -> 126.28 | V9: {=VLOOKUP(B9,'Player Data'!$A1:$AE673,10,FALSE)*$Q9*IFERROR(((VLOOKUP(P9,Settings!$E$28:$F$33,2,FALSE)/2)+1),1)} -> 256.66 | W9: {=VLOOKUP(B9,'Player Data'!$A1:$AE673,11,FALSE)*$Q9*IFERROR((VLOOKUP(P9,Settings!$E$28:$F$33,2,FALSE)+1),1)} -> 9.02 | X9: {=VLOOKUP(B9,'Player Data'!$A1:$AE673,12,FALSE)*$Q9*IFERROR((VLOOKUP(P9,Settings!$E$28:$F$33,2,FALSE)+1),1)} -> 43.46 | Y9: {=VLOOKUP(B9,'Player Data'!$A1:$AE673,13,FALSE)*$Q9} -> 0 | Z9: {=VLOOKUP(B9,'Player Data'!$A1:$AE673,14,FALSE)*$Q9} -> 0 | AA9: {=VLOOKUP(B9,'Player Data'!$A1:$AE673,15,FALSE)*$Q9} -> 33.62 | AB9: {=VLOOKUP(B9,'Player Data'!$A1:$AE673,16,FALSE)*$Q9} -> 36.9 | AC9: {=VLOOKUP(B9,'Player Data'!$A1:$AE673,17,FALSE)*$Q9*IFERROR((VLOOKUP(P9,Settings!$E$28:$F$33,2,FALSE)+1),1)} -> 13.12 | AD9: {=VLOOKUP(B9,'Player Data'!$A1:$AE673,18,FALSE)*$Q9} -> 35.26 | AE9: {=VLOOKUP(B9,'Player Data'!$A1:$AE673,19,FALSE)*$Q9*IFERROR((VLOOKUP(P9,Settings!$E$28:$F$33,2,FALSE)+1),1)} -> 7.38 | AF9: {=VLOOKUP(B9,'Player Data'!$A1:$AE673,20,FALSE)*$Q9} -> 0.82 | AG9: {=VLOOKUP(B9,'Player Data'!$A1:$AE673,21,FALSE)*$Q9} -> 1.64 | AH9: {=VLOOKUP(B9,'Player Data'!$A1:$AE673,22,FALSE)} -> 0.3
A10: =RANK(K10,K$2:K$671) -> 10 | B10: Andrei Vasilevskiy | C10: N | D10: {=VLOOKUP(B10,'Player Data'!A1:D673,4,FALSE)} -> G | E10: {=VLOOKUP(B10,G!A1:D66,3,FALSE)} -> 1 | F10: {=VLOOKUP(B10,'Player Data'!A1:B673,2,FALSE)} -> T.B | G10: {=VLOOKUP(B10,'Player Data'!A1:D673,3,FALSE)} -> 32 | H10: {=IFERROR(VLOOKUP(B10,ADP!A1:F671,6,FALSE)/1000000,VLOOKUP(B10,ADP!A1:F671,6,FALSE))} -> 9.5 | I10: =IF(Settings!$E$15="POINTS",(AJ10*Settings!$B$29)+(AK10*Settings!$B$21)+(AL10*Settings!$B$22)+(AN10*Settings!$B$24)+(AO10*Settings!$B$25)+(AP10*Settings!$B$27)+(AM10*Settings!$B$23),VLOOKUP(B10,'Standard Deviations'!A$1:C$672,3,FALSE)) -> 7.7477346 | J10: {=IF(D10="G",I10/AJ10,I10/Q10)} -> 0.1408679 | K10: {=VLOOKUP(B10,G!A1:F66,6,FALSE)} -> 5.7095493 | L10: {=IFERROR(K10/H10,"N/A")} -> 0.60100519 | M10: 11.9 | N10: {=IFERROR(M10-A10,"N/A")} -> 1.9 | P10: {=_xlfn.XLOOKUP($B10,ADP!A2:A671,ADP!G2:G671)} -> 0 | AJ10: {=VLOOKUP(B10,'Player Data'!$A1:$AE673,24,FALSE)} -> 55 | AK10: {=VLOOKUP(B10,'Player Data'!$A1:$AE673,25,FALSE)*$AJ10*IFERROR((VLOOKUP(P10,Settings!$E$28:$F$33,2,FALSE)+1),1)} -> 33.55 | AL10: {=AJ10-AK10-AM10} -> 15.95 | AM10: {=VLOOKUP(B10,'Player Data'!$A1:$AE673,27,FALSE)*$AJ10} -> 5.5 | AN10: {=VLOOKUP(B10,'Player Data'!$A1:$AE673,28,FALSE)*AJ10} -> 3.85 | AO10: {=VLOOKUP(B10,'Player Data'!$A1:$AE673,29,FALSE)*$AJ10*IFERROR((VLOOKUP(P10,Settings!$E$28:$F$33,2,FALSE)/4)+1,1)} -> 1468.5 | AP10: {=VLOOKUP(B10,'Player Data'!$A1:$AE673,31,FALSE)*$AJ10*(IFERROR(1-(VLOOKUP(P10,Settings!$E$28:$F$33,2,FALSE)/4),1))} -> 142.45 | AQ10: {=1-(AP10/(AO10+AP10))} -> 0.91157392 | AR10: {=AP10/AJ10} -> 2.59
A11: =RANK(K11,K$2:K$671) -> 11 | B11: Moritz Seider | C11: N | D11: {=VLOOKUP(B11,'Player Data'!A1:D673,4,FALSE)} -> D | E11: {=VLOOKUP(B11,D!A1:C204,3,FALSE)} -> 6 | F11: {=VLOOKUP(B11,'Player Data'!A1:B673,2,FALSE)} -> DET | G11: {=VLOOKUP(B11,'Player Data'!A1:D673,3,FALSE)} -> 25 | H11: {=IFERROR(VLOOKUP(B11,ADP!A1:F671,6,FALSE)/1000000,VLOOKUP(B11,ADP!A1:F671,6,FALSE))} -> 8.55 | I11: =IF(Settings!$E$15="POINTS",((R11*Q11)*Settings!$B$12)+(S11*Settings!$B$2)+(T11*Settings!$B$3)+(U11*Settings!$B$4)+(V11*Settings!$B$5)+(X11*Settings!$B$9)+(AA11*Settings!$B$6)+(W11*Settings!$B$8)+(AB11*Settings!$B$7)+(AC11*Settings!$B$14)+(AD11*Settings!$B$15)+(AE11*Settings!$B$16)+(AF11*Settings!$B$17)+(AG11*Settings!$B$18)+(U11*Settings!$B$13)+(Y11*Settings!$B$10)+(Z11*Settings!$B$11),VLOOKUP(B11,'Standard Deviations'!A$1:C$672,3,FALSE)) -> 6.0618594 | J11: {=IF(D11="G",I11/AJ11,I11/Q11)} -> 0.072164993 | K11: {=VLOOKUP(B11,D!A1:F204,6,FALSE)} -> 5.4950085 | L11: {=IFERROR(K11/H11,"N/A")} -> 0.64269105 | M11: 55.9 | N11: {=IFERROR(M11-A11,"N/A")} -> 44.9 | P11: {=_xlfn.XLOOKUP($B11,ADP!A2:A671,ADP!G2:G671)} -> 0 | Q11: {=IF(Settings!$E$12="YES",VLOOKUP(B11,'Player Data'!A1:E673,5,FALSE),84)} -> 84 | R11: {=VLOOKUP(B11,'Player Data'!$A1:$AE673,6,FALSE)} -> 25.9 | S11: {=VLOOKUP(B11,'Player Data'!$A1:$AE673,7,FALSE)*$Q11*IFERROR((VLOOKUP(P11,Settings!$E$28:$F$33,2,FALSE)+1),1)} -> 10.92 | T11: {=VLOOKUP(B11,'Player Data'!$A1:$AE673,8,FALSE)*$Q11*IFERROR((VLOOKUP(P11,Settings!$E$28:$F$33,2,FALSE)+1),1)} -> 47.88 | U11: {=SUM(S11:T11)} -> 58.8 | V11: {=VLOOKUP(B11,'Player Data'!$A1:$AE673,10,FALSE)*$Q11*IFERROR(((VLOOKUP(P11,Settings!$E$28:$F$33,2,FALSE)/2)+1),1)} -> 185.64 | W11: {=VLOOKUP(B11,'Player Data'!$A1:$AE673,11,FALSE)*$Q11*IFERROR((VLOOKUP(P11,Settings!$E$28:$F$33,2,FALSE)+1),1)} -> 4.2 | X11: {=VLOOKUP(B11,'Player Data'!$A1:$AE673,12,FALSE)*$Q11*IFERROR((VLOOKUP(P11,Settings!$E$28:$F$33,2,FALSE)+1),1)} -> 27.72 | Y11: {=VLOOKUP(B11,'Player Data'!$A1:$AE673,13,FALSE)*$Q11} -> 0 | Z11: {=VLOOKUP(B11,'Player Data'!$A1:$AE673,14,FALSE)*$Q11} -> 0 | AA11: {=VLOOKUP(B11,'Player Data'!$A1:$AE673,15,FALSE)*$Q11} -> 180.6 | AB11: {=VLOOKUP(B11,'Player Data'!$A1:$AE673,16,FALSE)*$Q11} -> 144.48 | AC11: {=VLOOKUP(B11,'Player Data'!$A1:$AE673,17,FALSE)*$Q11*IFERROR((VLOOKUP(P11,Settings!$E$28:$F$33,2,FALSE)+1),1)} -> 2.52 | AD11: {=VLOOKUP(B11,'Player Data'!$A1:$AE673,18,FALSE)*$Q11} -> 53.76 | AE11: {=VLOOKUP(B11,'Player Data'!$A1:$AE673,19,FALSE)*$Q11*IFERROR((VLOOKUP(P11,Settings!$E$28:$F$33,2,FALSE)+1),1)} -> 1.68 | AF11: {=VLOOKUP(B11,'Player Data'!$A1:$AE673,20,FALSE)*$Q11} -> 0 | AG11: {=VLOOKUP(B11,'Player Data'!$A1:$AE673,21,FALSE)*$Q11} -> 0 | AH11: {=VLOOKUP(B11,'Player Data'!$A1:$AE673,22,FALSE)} -> 0
A12: =RANK(K12,K$2:K$671) -> 9 | B12: Leon Draisaitl | C12: N | D12: {=VLOOKUP(B12,'Player Data'!A1:D673,4,FALSE)} -> C,LW | E12: {=VLOOKUP(B12,LW!A1:C210,3,FALSE)} -> 1 | F12: {=VLOOKUP(B12,'Player Data'!A1:B673,2,FALSE)} -> EDM | G12: {=VLOOKUP(B12,'Player Data'!A1:D673,3,FALSE)} -> 30 | H12: {=IFERROR(VLOOKUP(B12,ADP!A1:F671,6,FALSE)/1000000,VLOOKUP(B12,ADP!A1:F671,6,FALSE))} -> 14 | I12: =IF(Settings!$E$15="POINTS",((R12*Q12)*Settings!$B$12)+(S12*Settings!$B$2)+(T12*Settings!$B$3)+(U12*Settings!$B$4)+(V12*Settings!$B$5)+(X12*Settings!$B$9)+(AA12*Settings!$B$6)+(W12*Settings!$B$8)+(AB12*Settings!$B$7)+(AC12*Settings!$B$14)+(AD12*Settings!$B$15)+(AE12*Settings!$B$16)+(AF12*Settings!$B$17)+(AG12*Settings!$B$18)+(Y12*Settings!$B$10)+(Z12*Settings!$B$11),VLOOKUP(B12,'Standard Deviations'!A$1:C$672,3,FALSE)) -> 12.747493 | J12: {=IF(D12="G",I12/AJ12,I12/Q12)} -> 0.16136067 | K12: {=IF(Settings!$E$18="C/LW/RW",VLOOKUP(B12,LW!A1:F210,6,FALSE),VLOOKUP(B12,F!A1:F407,6,FALSE))} -> 5.8531073 | L12: {=IFERROR(K12/H12,"N/A")} -> 0.41807909 | M12: 6.6 | N12: {=IFERROR(M12-A12,"N/A")} -> -2.4 | P12: {=_xlfn.XLOOKUP($B12,ADP!A2:A671,ADP!G2:G671)} -> 0 | Q12: {=IF(Settings!$E$12="YES",VLOOKUP(B12,'Player Data'!A1:E673,5,FALSE),84)} -> 79 | R12: {=VLOOKUP(B12,'Player Data'!$A1:$AE673,6,FALSE)} -> 21.1 | S12: {=VLOOKUP(B12,'Player Data'!$A1:$AE673,7,FALSE)*$Q12*IFERROR((VLOOKUP(P12,Settings!$E$28:$F$33,2,FALSE)+1),1)} -> 45.03 | T12: {=VLOOKUP(B12,'Player Data'!$A1:$AE673,8,FALSE)*$Q12*IFERROR((VLOOKUP(P12,Settings!$E$28:$F$33,2,FALSE)+1),1)} -> 66.36 | U12: {=SUM(S12:T12)} -> 111.39 | V12: {=VLOOKUP(B12,'Player Data'!$A1:$AE673,10,FALSE)*$Q12*IFERROR(((VLOOKUP(P12,Settings!$E$28:$F$33,2,FALSE)/2)+1),1)} -> 232.26 | W12: {=VLOOKUP(B12,'Player Data'!$A1:$AE673,11,FALSE)*$Q12*IFERROR((VLOOKUP(P12,Settings!$E$28:$F$33,2,FALSE)+1),1)} -> 19.75 | X12: {=VLOOKUP(B12,'Player Data'!$A1:$AE673,12,FALSE)*$Q12*IFERROR((VLOOKUP(P12,Settings!$E$28:$F$33,2,FALSE)+1),1)} -> 45.82 | Y12: {=VLOOKUP(B12,'Player Data'!$A1:$AE673,13,FALSE)*$Q12} -> 0 | Z12: {=VLOOKUP(B12,'Player Data'!$A1:$AE673,14,FALSE)*$Q12} -> 0 | AA12: {=VLOOKUP(B12,'Player Data'!$A1:$AE673,15,FALSE)*$Q12} -> 23.7 | AB12: {=VLOOKUP(B12,'Player Data'!$A1:$AE673,16,FALSE)*$Q12} -> 39.5 | AC12: {=VLOOKUP(B12,'Player Data'!$A1:$AE673,17,FALSE)*$Q12*IFERROR((VLOOKUP(P12,Settings!$E$28:$F$33,2,FALSE)+1),1)} -> 9.48 | AD12: {=VLOOKUP(B12,'Player Data'!$A1:$AE673,18,FALSE)*$Q12} -> 39.5 | AE12: {=VLOOKUP(B12,'Player Data'!$A1:$AE673,19,FALSE)*$Q12*IFERROR((VLOOKUP(P12,Settings!$E$28:$F$33,2,FALSE)+1),1)} -> 7.9 | AF12: {=VLOOKUP(B12,'Player Data'!$A1:$AE673,20,FALSE)*$Q12} -> 746.55 | AG12: {=VLOOKUP(B12,'Player Data'!$A1:$AE673,21,FALSE)*$Q12} -> 584.6 | AH12: {=VLOOKUP(B12,'Player Data'!$A1:$AE673,22,FALSE)} -> 0.56
A13: =RANK(K13,K$2:K$671) -> 12 | B13: Lane Hutson | C13: N | D13: {=VLOOKUP(B13,'Player Data'!A1:D673,4,FALSE)} -> D | E13: {=VLOOKUP(B13,D!A1:C204,3,FALSE)} -> 7 | F13: {=VLOOKUP(B13,'Player Data'!A1:B673,2,FALSE)} -> MTL | G13: {=VLOOKUP(B13,'Player Data'!A1:D673,3,FALSE)} -> 22 | H13: {=IFERROR(VLOOKUP(B13,ADP!A1:F671,6,FALSE)/1000000,VLOOKUP(B13,ADP!A1:F671,6,FALSE))} -> 8.85 | I13: =IF(Settings!$E$15="POINTS",((R13*Q13)*Settings!$B$12)+(S13*Settings!$B$2)+(T13*Settings!$B$3)+(U13*Settings!$B$4)+(V13*Settings!$B$5)+(X13*Settings!$B$9)+(AA13*Settings!$B$6)+(W13*Settings!$B$8)+(AB13*Settings!$B$7)+(AC13*Settings!$B$14)+(AD13*Settings!$B$15)+(AE13*Settings!$B$16)+(AF13*Settings!$B$17)+(AG13*Settings!$B$18)+(U13*Settings!$B$13)+(Y13*Settings!$B$10)+(Z13*Settings!$B$11),VLOOKUP(B13,'Standard Deviations'!A$1:C$672,3,FALSE)) -> 5.479629 | J13: {=IF(D13="G",I13/AJ13,I13/Q13)} -> 0.065233679 | K13: {=VLOOKUP(B13,D!A1:F204,6,FALSE)} -> 4.9127781 | L13: {=IFERROR(K13/H13,"N/A")} -> 0.55511617 | M13: 20 | N13: {=IFERROR(M13-A13,"N/A")} -> 8 | P13: {=_xlfn.XLOOKUP($B13,ADP!A2:A671,ADP!G2:G671)} -> 0 | Q13: {=IF(Settings!$E$12="YES",VLOOKUP(B13,'Player Data'!A1:E673,5,FALSE),84)} -> 84 | R13: {=VLOOKUP(B13,'Player Data'!$A1:$AE673,6,FALSE)} -> 23.7 | S13: {=VLOOKUP(B13,'Player Data'!$A1:$AE673,7,FALSE)*$Q13*IFERROR((VLOOKUP(P13,Settings!$E$28:$F$33,2,FALSE)+1),1)} -> 11.76 | T13: {=VLOOKUP(B13,'Player Data'!$A1:$AE673,8,FALSE)*$Q13*IFERROR((VLOOKUP(P13,Settings!$E$28:$F$33,2,FALSE)+1),1)} -> 66.36 | U13: {=SUM(S13:T13)} -> 78.12 | V13: {=VLOOKUP(B13,'Player Data'!$A1:$AE673,10,FALSE)*$Q13*IFERROR(((VLOOKUP(P13,Settings!$E$28:$F$33,2,FALSE)/2)+1),1)} -> 128.52 | W13: {=VLOOKUP(B13,'Player Data'!$A1:$AE673,11,FALSE)*$Q13*IFERROR((VLOOKUP(P13,Settings!$E$28:$F$33,2,FALSE)+1),1)} -> 2.52 | X13: {=VLOOKUP(B13,'Player Data'!$A1:$AE673,12,FALSE)*$Q13*IFERROR((VLOOKUP(P13,Settings!$E$28:$F$33,2,FALSE)+1),1)} -> 26.88 | Y13: {=VLOOKUP(B13,'Player Data'!$A1:$AE673,13,FALSE)*$Q13} -> 0 | Z13: {=VLOOKUP(B13,'Player Data'!$A1:$AE673,14,FALSE)*$Q13} -> 0 | AA13: {=VLOOKUP(B13,'Player Data'!$A1:$AE673,15,FALSE)*$Q13} -> 131.88 | AB13: {=VLOOKUP(B13,'Player Data'!$A1:$AE673,16,FALSE)*$Q13} -> 38.64 | AC13: {=VLOOKUP(B13,'Player Data'!$A1:$AE673,17,FALSE)*$Q13*IFERROR((VLOOKUP(P13,Settings!$E$28:$F$33,2,FALSE)+1),1)} -> 8.4 | AD13: {=VLOOKUP(B13,'Player Data'!$A1:$AE673,18,FALSE)*$Q13} -> 37.8 | AE13: {=VLOOKUP(B13,'Player Data'!$A1:$AE673,19,FALSE)*$Q13*IFERROR((VLOOKUP(P13,Settings!$E$28:$F$33,2,FALSE)+1),1)} -> 1.68 | AF13: {=VLOOKUP(B13,'Player Data'!$A1:$AE673,20,FALSE)*$Q13} -> 0 | AG13: {=VLOOKUP(B13,'Player Data'!$A1:$AE673,21,FALSE)*$Q13} -> 0 | AH13: {=VLOOKUP(B13,'Player Data'!$A1:$AE673,22,FALSE)} -> 0
A14: =RANK(K14,K$2:K$671) -> 16 | B14: Jakob Chychrun | C14: N | D14: {=VLOOKUP(B14,'Player Data'!A1:D673,4,FALSE)} -> D | E14: {=VLOOKUP(B14,D!A1:C204,3,FALSE)} -> 8 | F14: {=VLOOKUP(B14,'Player Data'!A1:B673,2,FALSE)} -> WSH | G14: {=VLOOKUP(B14,'Player Data'!A1:D673,3,FALSE)} -> 28 | H14: {=IFERROR(VLOOKUP(B14,ADP!A1:F671,6,FALSE)/1000000,VLOOKUP(B14,ADP!A1:F671,6,FALSE))} -> 9 | I14: =IF(Settings!$E$15="POINTS",((R14*Q14)*Settings!$B$12)+(S14*Settings!$B$2)+(T14*Settings!$B$3)+(U14*Settings!$B$4)+(V14*Settings!$B$5)+(X14*Settings!$B$9)+(AA14*Settings!$B$6)+(W14*Settings!$B$8)+(AB14*Settings!$B$7)+(AC14*Settings!$B$14)+(AD14*Settings!$B$15)+(AE14*Settings!$B$16)+(AF14*Settings!$B$17)+(AG14*Settings!$B$18)+(U14*Settings!$B$13)+(Y14*Settings!$B$10)+(Z14*Settings!$B$11),VLOOKUP(B14,'Standard Deviations'!A$1:C$672,3,FALSE)) -> 5.0308181 | J14: {=IF(D14="G",I14/AJ14,I14/Q14)} -> 0.060612266 | K14: {=VLOOKUP(B14,D!A1:F204,6,FALSE)} -> 4.4639672 | L14: {=IFERROR(K14/H14,"N/A")} -> 0.49599635 | M14: 54.7 | N14: {=IFERROR(M14-A14,"N/A")} -> 38.7 | P14: {=_xlfn.XLOOKUP($B14,ADP!A2:A671,ADP!G2:G671)} -> 0 | Q14: {=IF(Settings!$E$12="YES",VLOOKUP(B14,'Player Data'!A1:E673,5,FALSE),84)} -> 83 | R14: {=VLOOKUP(B14,'Player Data'!$A1:$AE673,6,FALSE)} -> 23.2 | S14: {=VLOOKUP(B14,'Player Data'!$A1:$AE673,7,FALSE)*$Q14*IFERROR((VLOOKUP(P14,Settings!$E$28:$F$33,2,FALSE)+1),1)} -> 21.58 | T14: {=VLOOKUP(B14,'Player Data'!$A1:$AE673,8,FALSE)*$Q14*IFERROR((VLOOKUP(P14,Settings!$E$28:$F$33,2,FALSE)+1),1)} -> 33.2 | U14: {=SUM(S14:T14)} -> 54.78 | V14: {=VLOOKUP(B14,'Player Data'!$A1:$AE673,10,FALSE)*$Q14*IFERROR(((VLOOKUP(P14,Settings!$E$28:$F$33,2,FALSE)/2)+1),1)} -> 219.12 | W14: {=VLOOKUP(B14,'Player Data'!$A1:$AE673,11,FALSE)*$Q14*IFERROR((VLOOKUP(P14,Settings!$E$28:$F$33,2,FALSE)+1),1)} -> 7.47 | X14: {=VLOOKUP(B14,'Player Data'!$A1:$AE673,12,FALSE)*$Q14*IFERROR((VLOOKUP(P14,Settings!$E$28:$F$33,2,FALSE)+1),1)} -> 19.09 | Y14: {=VLOOKUP(B14,'Player Data'!$A1:$AE673,13,FALSE)*$Q14} -> 0 | Z14: {=VLOOKUP(B14,'Player Data'!$A1:$AE673,14,FALSE)*$Q14} -> 0 | AA14: {=VLOOKUP(B14,'Player Data'!$A1:$AE673,15,FALSE)*$Q14} -> 118.69 | AB14: {=VLOOKUP(B14,'Player Data'!$A1:$AE673,16,FALSE)*$Q14} -> 63.08 | AC14: {=VLOOKUP(B14,'Player Data'!$A1:$AE673,17,FALSE)*$Q14*IFERROR((VLOOKUP(P14,Settings!$E$28:$F$33,2,FALSE)+1),1)} -> 6.64 | AD14: {=VLOOKUP(B14,'Player Data'!$A1:$AE673,18,FALSE)*$Q14} -> 58.93 | AE14: {=VLOOKUP(B14,'Player Data'!$A1:$AE673,19,FALSE)*$Q14*IFERROR((VLOOKUP(P14,Settings!$E$28:$F$33,2,FALSE)+1),1)} -> 3.32 | AF14: {=VLOOKUP(B14,'Player Data'!$A1:$AE673,20,FALSE)*$Q14} -> 0 | AG14: {=VLOOKUP(B14,'Player Data'!$A1:$AE673,21,FALSE)*$Q14} -> 0 | AH14: {=VLOOKUP(B14,'Player Data'!$A1:$AE673,22,FALSE)} -> 0
A15: =RANK(K15,K$2:K$671) -> 14 | B15: Connor Hellebuyck | C15: N | D15: {=VLOOKUP(B15,'Player Data'!A1:D673,4,FALSE)} -> G | E15: {=VLOOKUP(B15,G!A1:D66,3,FALSE)} -> 2 | F15: {=VLOOKUP(B15,'Player Data'!A1:B673,2,FALSE)} -> WPG | G15: {=VLOOKUP(B15,'Player Data'!A1:D673,3,FALSE)} -> 33 | H15: {=IFERROR(VLOOKUP(B15,ADP!A1:F671,6,FALSE)/1000000,VLOOKUP(B15,ADP!A1:F671,6,FALSE))} -> 8.5 | I15: =IF(Settings!$E$15="POINTS",(AJ15*Settings!$B$29)+(AK15*Settings!$B$21)+(AL15*Settings!$B$22)+(AN15*Settings!$B$24)+(AO15*Settings!$B$25)+(AP15*Settings!$B$27)+(AM15*Settings!$B$23),VLOOKUP(B15,'Standard Deviations'!A$1:C$672,3,FALSE)) -> 6.6333594 | J15: {=IF(D15="G",I15/AJ15,I15/Q15)} -> 0.12060653 | K15: {=VLOOKUP(B15,G!A1:F66,6,FALSE)} -> 4.5951741 | L15: {=IFERROR(K15/H15,"N/A")} -> 0.54060872 | M15: 26.6 | N15: {=IFERROR(M15-A15,"N/A")} -> 12.6 | P15: {=_xlfn.XLOOKUP($B15,ADP!A2:A671,ADP!G2:G671)} -> 0 | AJ15: {=VLOOKUP(B15,'Player Data'!$A1:$AE673,24,FALSE)} -> 55 | AK15: {=VLOOKUP(B15,'Player Data'!$A1:$AE673,25,FALSE)*$AJ15*IFERROR((VLOOKUP(P15,Settings!$E$28:$F$33,2,FALSE)+1),1)} -> 29.15 | AL15: {=AJ15-AK15-AM15} -> 19.25 | AM15: {=VLOOKUP(B15,'Player Data'!$A1:$AE673,27,FALSE)*$AJ15} -> 6.6 | AN15: {=VLOOKUP(B15,'Player Data'!$A1:$AE673,28,FALSE)*AJ15} -> 3.85 | AO15: {=VLOOKUP(B15,'Player Data'!$A1:$AE673,29,FALSE)*$AJ15*IFERROR((VLOOKUP(P15,Settings!$E$28:$F$33,2,FALSE)/4)+1,1)} -> 1446.5 | AP15: {=VLOOKUP(B15,'Player Data'!$A1:$AE673,31,FALSE)*$AJ15*(IFERROR(1-(VLOOKUP(P15,Settings!$E$28:$F$33,2,FALSE)/4),1))} -> 143.55 | AQ15: {=1-(AP15/(AO15+AP15))} -> 0.90971982 | AR15: {=AP15/AJ15} -> 2.61
A16: =RANK(K16,K$2:K$671) -> 18 | B16: Matthew Schaefer | C16: N | D16: {=VLOOKUP(B16,'Player Data'!A1:D673,4,FALSE)} -> D | E16: {=VLOOKUP(B16,D!A1:C204,3,FALSE)} -> 9 | F16: {=VLOOKUP(B16,'Player Data'!A1:B673,2,FALSE)} -> NYI | G16: {=VLOOKUP(B16,'Player Data'!A1:D673,3,FALSE)} -> 19 | H16: {=IFERROR(VLOOKUP(B16,ADP!A1:F671,6,FALSE)/1000000,VLOOKUP(B16,ADP!A1:F671,6,FALSE))} -> 0.975 | I16: =IF(Settings!$E$15="POINTS",((R16*Q16)*Settings!$B$12)+(S16*Settings!$B$2)+(T16*Settings!$B$3)+(U16*Settings!$B$4)+(V16*Settings!$B$5)+(X16*Settings!$B$9)+(AA16*Settings!$B$6)+(W16*Settings!$B$8)+(AB16*Settings!$B$7)+(AC16*Settings!$B$14)+(AD16*Settings!$B$15)+(AE16*Settings!$B$16)+(AF16*Settings!$B$17)+(AG16*Settings!$B$18)+(U16*Settings!$B$13)+(Y16*Settings!$B$10)+(Z16*Settings!$B$11),VLOOKUP(B16,'Standard Deviations'!A$1:C$672,3,FALSE)) -> 4.9499454 | J16: {=IF(D16="G",I16/AJ16,I16/Q16)} -> 0.059637896 | K16: {=VLOOKUP(B16,D!A1:F204,6,FALSE)} -> 4.3830945 | L16: {=IFERROR(K16/H16,"N/A")} -> 4.4954815 | M16: 34.2 | N16: {=IFERROR(M16-A16,"N/A")} -> 16.2 | P16: {=_xlfn.XLOOKUP($B16,ADP!A2:A671,ADP!G2:G671)} -> + | Q16: {=IF(Settings!$E$12="YES",VLOOKUP(B16,'Player Data'!A1:E673,5,FALSE),84)} -> 83 | R16: {=VLOOKUP(B16,'Player Data'!$A1:$AE673,6,FALSE)} -> 24.8 | S16: {=VLOOKUP(B16,'Player Data'!$A1:$AE673,7,FALSE)*$Q16*IFERROR((VLOOKUP(P16,Settings!$E$28:$F$33,2,FALSE)+1),1)} -> 26.145 | T16: {=VLOOKUP(B16,'Player Data'!$A1:$AE673,8,FALSE)*$Q16*IFERROR((VLOOKUP(P16,Settings!$E$28:$F$33,2,FALSE)+1),1)} -> 44.4465 | U16: {=SUM(S16:T16)} -> 70.5915 | V16: {=VLOOKUP(B16,'Player Data'!$A1:$AE673,10,FALSE)*$Q16*IFERROR(((VLOOKUP(P16,Settings!$E$28:$F$33,2,FALSE)/2)+1),1)} -> 230.55325 | W16: {=VLOOKUP(B16,'Player Data'!$A1:$AE673,11,FALSE)*$Q16*IFERROR((VLOOKUP(P16,Settings!$E$28:$F$33,2,FALSE)+1),1)} -> 9.5865 | X16: {=VLOOKUP(B16,'Player Data'!$A1:$AE673,12,FALSE)*$Q16*IFERROR((VLOOKUP(P16,Settings!$E$28:$F$33,2,FALSE)+1),1)} -> 23.5305 | Y16: {=VLOOKUP(B16,'Player Data'!$A1:$AE673,13,FALSE)*$Q16} -> 0 | Z16: {=VLOOKUP(B16,'Player Data'!$A1:$AE673,14,FALSE)*$Q16} -> 0 | AA16: {=VLOOKUP(B16,'Player Data'!$A1:$AE673,15,FALSE)*$Q16} -> 113.71 | AB16: {=VLOOKUP(B16,'Player Data'!$A1:$AE673,16,FALSE)*$Q16} -> 46.48 | AC16: {=VLOOKUP(B16,'Player Data'!$A1:$AE673,17,FALSE)*$Q16*IFERROR((VLOOKUP(P16,Settings!$E$28:$F$33,2,FALSE)+1),1)} -> -0.8715 | AD16: {=VLOOKUP(B16,'Player Data'!$A1:$AE673,18,FALSE)*$Q16} -> 43.16 | AE16: {=VLOOKUP(B16,'Player Data'!$A1:$AE673,19,FALSE)*$Q16*IFERROR((VLOOKUP(P16,Settings!$E$28:$F$33,2,FALSE)+1),1)} -> 3.486 | AF16: {=VLOOKUP(B16,'Player Data'!$A1:$AE673,20,FALSE)*$Q16} -> 0 | AG16: {=VLOOKUP(B16,'Player Data'!$A1:$AE673,21,FALSE)*$Q16} -> 0 | AH16: {=VLOOKUP(B16,'Player Data'!$A1:$AE673,22,FALSE)} -> 0
A17: =RANK(K17,K$2:K$671) -> 15 | B17: Logan Thompson | C17: N | D17: {=VLOOKUP(B17,'Player Data'!A1:D673,4,FALSE)} -> G | E17: {=VLOOKUP(B17,G!A1:D66,3,FALSE)} -> 3 | F17: {=VLOOKUP(B17,'Player Data'!A1:B673,2,FALSE)} -> WSH | G17: {=VLOOKUP(B17,'Player Data'!A1:D673,3,FALSE)} -> 29 | H17: {=IFERROR(VLOOKUP(B17,ADP!A1:F671,6,FALSE)/1000000,VLOOKUP(B17,ADP!A1:F671,6,FALSE))} -> 5.85 | I17: =IF(Settings!$E$15="POINTS",(AJ17*Settings!$B$29)+(AK17*Settings!$B$21)+(AL17*Settings!$B$22)+(AN17*Settings!$B$24)+(AO17*Settings!$B$25)+(AP17*Settings!$B$27)+(AM17*Settings!$B$23),VLOOKUP(B17,'Standard Deviations'!A$1:C$672,3,FALSE)) -> 6.596576 | J17: {=IF(D17="G",I17/AJ17,I17/Q17)} -> 0.11993775 | K17: {=VLOOKUP(B17,G!A1:F66,6,FALSE)} -> 4.5583907 | L17: {=IFERROR(K17/H17,"N/A")} -> 0.77921209 | M17: 28.6 | N17: {=IFERROR(M17-A17,"N/A")} -> 13.6 | P17: {=_xlfn.XLOOKUP($B17,ADP!A2:A671,ADP!G2:G671)} -> 0 | AJ17: {=VLOOKUP(B17,'Player Data'!$A1:$AE673,24,FALSE)} -> 55 | AK17: {=VLOOKUP(B17,'Player Data'!$A1:$AE673,25,FALSE)*$AJ17*IFERROR((VLOOKUP(P17,Settings!$E$28:$F$33,2,FALSE)+1),1)} -> 31.9 | AL17: {=AJ17-AK17-AM17} -> 17.05 | AM17: {=VLOOKUP(B17,'Player Data'!$A1:$AE673,27,FALSE)*$AJ17} -> 6.05 | AN17: {=VLOOKUP(B17,'Player Data'!$A1:$AE673,28,FALSE)*AJ17} -> 3.85 | AO17: {=VLOOKUP(B17,'Player Data'!$A1:$AE673,29,FALSE)*$AJ17*IFERROR((VLOOKUP(P17,Settings!$E$28:$F$33,2,FALSE)/4)+1,1)} -> 1457.5 | AP17: {=VLOOKUP(B17,'Player Data'!$A1:$AE673,31,FALSE)*$AJ17*(IFERROR(1-(VLOOKUP(P17,Settings!$E$28:$F$33,2,FALSE)/4),1))} -> 146.3 | AQ17: {=1-(AP17/(AO17+AP17))} -> 0.90877915 | AR17: {=AP17/AJ17} -> 2.66
A18: =RANK(K18,K$2:K$671) -> 20 | B18: Darren Raddysh | C18: N | D18: {=VLOOKUP(B18,'Player Data'!A1:D673,4,FALSE)} -> D | E18: {=VLOOKUP(B18,D!A1:C204,3,FALSE)} -> 10 | F18: {=VLOOKUP(B18,'Player Data'!A1:B673,2,FALSE)} -> TOR | G18: {=VLOOKUP(B18,'Player Data'!A1:D673,3,FALSE)} -> 30 | H18: {=IFERROR(VLOOKUP(B18,ADP!A1:F671,6,FALSE)/1000000,VLOOKUP(B18,ADP!A1:F671,6,FALSE))} -> 8.5 | I18: =IF(Settings!$E$15="POINTS",((R18*Q18)*Settings!$B$12)+(S18*Settings!$B$2)+(T18*Settings!$B$3)+(U18*Settings!$B$4)+(V18*Settings!$B$5)+(X18*Settings!$B$9)+(AA18*Settings!$B$6)+(W18*Settings!$B$8)+(AB18*Settings!$B$7)+(AC18*Settings!$B$14)+(AD18*Settings!$B$15)+(AE18*Settings!$B$16)+(AF18*Settings!$B$17)+(AG18*Settings!$B$18)+(U18*Settings!$B$13)+(Y18*Settings!$B$10)+(Z18*Settings!$B$11),VLOOKUP(B18,'Standard Deviations'!A$1:C$672,3,FALSE)) -> 4.8016307 | J18: {=IF(D18="G",I18/AJ18,I18/Q18)} -> 0.059279392 | K18: {=VLOOKUP(B18,D!A1:F204,6,FALSE)} -> 4.2347798 | L18: {=IFERROR(K18/H18,"N/A")} -> 0.49820939 | M18: 50.4 | N18: {=IFERROR(M18-A18,"N/A")} -> 30.4 | P18: {=_xlfn.XLOOKUP($B18,ADP!A2:A671,ADP!G2:G671)} -> 0 | Q18: {=IF(Settings!$E$12="YES",VLOOKUP(B18,'Player Data'!A1:E673,5,FALSE),84)} -> 81 | R18: {=VLOOKUP(B18,'Player Data'!$A1:$AE673,6,FALSE)} -> 23.3 | S18: {=VLOOKUP(B18,'Player Data'!$A1:$AE673,7,FALSE)*$Q18*IFERROR((VLOOKUP(P18,Settings!$E$28:$F$33,2,FALSE)+1),1)} -> 14.58 | T18: {=VLOOKUP(B18,'Player Data'!$A1:$AE673,8,FALSE)*$Q18*IFERROR((VLOOKUP(P18,Settings!$E$28:$F$33,2,FALSE)+1),1)} -> 45.36 | U18: {=SUM(S18:T18)} -> 59.94 | V18: {=VLOOKUP(B18,'Player Data'!$A1:$AE673,10,FALSE)*$Q18*IFERROR(((VLOOKUP(P18,Settings!$E$28:$F$33,2,FALSE)/2)+1),1)} -> 198.45 | W18: {=VLOOKUP(B18,'Player Data'!$A1:$AE673,11,FALSE)*$Q18*IFERROR((VLOOKUP(P18,Settings!$E$28:$F$33,2,FALSE)+1),1)} -> 7.29 | X18: {=VLOOKUP(B18,'Player Data'!$A1:$AE673,12,FALSE)*$Q18*IFERROR((VLOOKUP(P18,Settings!$E$28:$F$33,2,FALSE)+1),1)} -> 23.49 | Y18: {=VLOOKUP(B18,'Player Data'!$A1:$AE673,13,FALSE)*$Q18} -> 0 | Z18: {=VLOOKUP(B18,'Player Data'!$A1:$AE673,14,FALSE)*$Q18} -> 0 | AA18: {=VLOOKUP(B18,'Player Data'!$A1:$AE673,15,FALSE)*$Q18} -> 95.58 | AB18: {=VLOOKUP(B18,'Player Data'!$A1:$AE673,16,FALSE)*$Q18} -> 76.14 | AC18: {=VLOOKUP(B18,'Player Data'!$A1:$AE673,17,FALSE)*$Q18*IFERROR((VLOOKUP(P18,Settings!$E$28:$F$33,2,FALSE)+1),1)} -> 3.24 | AD18: {=VLOOKUP(B18,'Player Data'!$A1:$AE673,18,FALSE)*$Q18} -> 41.31 | AE18: {=VLOOKUP(B18,'Player Data'!$A1:$AE673,19,FALSE)*$Q18*IFERROR((VLOOKUP(P18,Settings!$E$28:$F$33,2,FALSE)+1),1)} -> 1.62 | AF18: {=VLOOKUP(B18,'Player Data'!$A1:$AE673,20,FALSE)*$Q18} -> 0 | AG18: {=VLOOKUP(B18,'Player Data'!$A1:$AE673,21,FALSE)*$Q18} -> 0 | AH18: {=VLOOKUP(B18,'Player Data'!$A1:$AE673,22,FALSE)} -> 0
A19: =RANK(K19,K$2:K$671) -> 21 | B19: Adam Fox | C19: N | D19: {=VLOOKUP(B19,'Player Data'!A1:D673,4,FALSE)} -> D | E19: {=VLOOKUP(B19,D!A1:C204,3,FALSE)} -> 11 | F19: {=VLOOKUP(B19,'Player Data'!A1:B673,2,FALSE)} -> NYR | G19: {=VLOOKUP(B19,'Player Data'!A1:D673,3,FALSE)} -> 28 | H19: {=IFERROR(VLOOKUP(B19,ADP!A1:F671,6,FALSE)/1000000,VLOOKUP(B19,ADP!A1:F671,6,FALSE))} -> 9.5 | I19: =IF(Settings!$E$15="POINTS",((R19*Q19)*Settings!$B$12)+(S19*Settings!$B$2)+(T19*Settings!$B$3)+(U19*Settings!$B$4)+(V19*Settings!$B$5)+(X19*Settings!$B$9)+(AA19*Settings!$B$6)+(W19*Settings!$B$8)+(AB19*Settings!$B$7)+(AC19*Settings!$B$14)+(AD19*Settings!$B$15)+(AE19*Settings!$B$16)+(AF19*Settings!$B$17)+(AG19*Settings!$B$18)+(U19*Settings!$B$13)+(Y19*Settings!$B$10)+(Z19*Settings!$B$11),VLOOKUP(B19,'Standard Deviations'!A$1:C$672,3,FALSE)) -> 4.6954541 | J19: {=IF(D19="G",I19/AJ19,I19/Q19)} -> 0.060979924 | K19: {=VLOOKUP(B19,D!A1:F204,6,FALSE)} -> 4.1286032 | L19: {=IFERROR(K19/H19,"N/A")} -> 0.43458981 | M19: 58 | N19: {=IFERROR(M19-A19,"N/A")} -> 37 | P19: {=_xlfn.XLOOKUP($B19,ADP!A2:A671,ADP!G2:G671)} -> 0 | Q19: {=IF(Settings!$E$12="YES",VLOOKUP(B19,'Player Data'!A1:E673,5,FALSE),84)} -> 77 | R19: {=VLOOKUP(B19,'Player Data'!$A1:$AE673,6,FALSE)} -> 23.8 | S19: {=VLOOKUP(B19,'Player Data'!$A1:$AE673,7,FALSE)*$Q19*IFERROR((VLOOKUP(P19,Settings!$E$28:$F$33,2,FALSE)+1),1)} -> 13.09 | T19: {=VLOOKUP(B19,'Player Data'!$A1:$AE673,8,FALSE)*$Q19*IFERROR((VLOOKUP(P19,Settings!$E$28:$F$33,2,FALSE)+1),1)} -> 58.52 | U19: {=SUM(S19:T19)} -> 71.61 | V19: {=VLOOKUP(B19,'Player Data'!$A1:$AE673,10,FALSE)*$Q19*IFERROR(((VLOOKUP(P19,Settings!$E$28:$F$33,2,FALSE)/2)+1),1)} -> 136.29 | W19: {=VLOOKUP(B19,'Player Data'!$A1:$AE673,11,FALSE)*$Q19*IFERROR((VLOOKUP(P19,Settings!$E$28:$F$33,2,FALSE)+1),1)} -> 4.62 | X19: {=VLOOKUP(B19,'Player Data'!$A1:$AE673,12,FALSE)*$Q19*IFERROR((VLOOKUP(P19,Settings!$E$28:$F$33,2,FALSE)+1),1)} -> 30.03 | Y19: {=VLOOKUP(B19,'Player Data'!$A1:$AE673,13,FALSE)*$Q19} -> 0 | Z19: {=VLOOKUP(B19,'Player Data'!$A1:$AE673,14,FALSE)*$Q19} -> 0.77 | AA19: {=VLOOKUP(B19,'Player Data'!$A1:$AE673,15,FALSE)*$Q19} -> 110.11 | AB19: {=VLOOKUP(B19,'Player Data'!$A1:$AE673,16,FALSE)*$Q19} -> 46.97 | AC19: {=VLOOKUP(B19,'Player Data'!$A1:$AE673,17,FALSE)*$Q19*IFERROR((VLOOKUP(P19,Settings!$E$28:$F$33,2,FALSE)+1),1)} -> 3.85 | AD19: {=VLOOKUP(B19,'Player Data'!$A1:$AE673,18,FALSE)*$Q19} -> 36.19 | AE19: {=VLOOKUP(B19,'Player Data'!$A1:$AE673,19,FALSE)*$Q19*IFERROR((VLOOKUP(P19,Settings!$E$28:$F$33,2,FALSE)+1),1)} -> 2.31 | AF19: {=VLOOKUP(B19,'Player Data'!$A1:$AE673,20,FALSE)*$Q19} -> 0 | AG19: {=VLOOKUP(B19,'Player Data'!$A1:$AE673,21,FALSE)*$Q19} -> 0 | AH19: {=VLOOKUP(B19,'Player Data'!$A1:$AE673,22,FALSE)} -> 0
A20: =RANK(K20,K$2:K$671) -> 22 | B20: Jake Oettinger | C20: N | D20: {=VLOOKUP(B20,'Player Data'!A1:D673,4,FALSE)} -> G | E20: {=VLOOKUP(B20,G!A1:D66,3,FALSE)} -> 4 | F20: {=VLOOKUP(B20,'Player Data'!A1:B673,2,FALSE)} -> DAL | G20: {=VLOOKUP(B20,'Player Data'!A1:D673,3,FALSE)} -> 27 | H20: {=IFERROR(VLOOKUP(B20,ADP!A1:F671,6,FALSE)/1000000,VLOOKUP(B20,ADP!A1:F671,6,FALSE))} -> 8.25 | I20: =IF(Settings!$E$15="POINTS",(AJ20*Settings!$B$29)+(AK20*Settings!$B$21)+(AL20*Settings!$B$22)+(AN20*Settings!$B$24)+(AO20*Settings!$B$25)+(AP20*Settings!$B$27)+(AM20*Settings!$B$23),VLOOKUP(B20,'Standard Deviations'!A$1:C$672,3,FALSE)) -> 6.1615972 | J20: {=IF(D20="G",I20/AJ20,I20/Q20)} -> 0.11202904 | K20: {=VLOOKUP(B20,G!A1:F66,6,FALSE)} -> 4.123412 | L20: {=IFERROR(K20/H20,"N/A")} -> 0.49980751 | M20: 24.6 | N20: {=IFERROR(M20-A20,"N/A")} -> 2.6 | P20: {=_xlfn.XLOOKUP($B20,ADP!A2:A671,ADP!G2:G671)} -> 0 | AJ20: {=VLOOKUP(B20,'Player Data'!$A1:$AE673,24,FALSE)} -> 55 | AK20: {=VLOOKUP(B20,'Player Data'!$A1:$AE673,25,FALSE)*$AJ20*IFERROR((VLOOKUP(P20,Settings!$E$28:$F$33,2,FALSE)+1),1)} -> 32.45 | AL20: {=AJ20-AK20-AM20} -> 17.05 | AM20: {=VLOOKUP(B20,'Player Data'!$A1:$AE673,27,FALSE)*$AJ20} -> 5.5 | AN20: {=VLOOKUP(B20,'Player Data'!$A1:$AE673,28,FALSE)*AJ20} -> 3.85 | AO20: {=VLOOKUP(B20,'Player Data'!$A1:$AE673,29,FALSE)*$AJ20*IFERROR((VLOOKUP(P20,Settings!$E$28:$F$33,2,FALSE)/4)+1,1)} -> 1397 | AP20: {=VLOOKUP(B20,'Player Data'!$A1:$AE673,31,FALSE)*$AJ20*(IFERROR(1-(VLOOKUP(P20,Settings!$E$28:$F$33,2,FALSE)/4),1))} -> 145.75 | AQ20: {=1-(AP20/(AO20+AP20))} -> 0.90552585 | AR20: {=AP20/AJ20} -> 2.65
A21: =RANK(K21,K$2:K$671) -> 13 | B21: Jason Robertson | C21: N | D21: {=VLOOKUP(B21,'Player Data'!A1:D673,4,FALSE)} -> LW,RW | E21: {=VLOOKUP(B21,RW!A1:F210,3,FALSE)} -> 2 | F21: {=VLOOKUP(B21,'Player Data'!A1:B673,2,FALSE)} -> DAL | G21: {=VLOOKUP(B21,'Player Data'!A1:D673,3,FALSE)} -> 27 | H21: {=IFERROR(VLOOKUP(B21,ADP!A1:F671,6,FALSE)/1000000,VLOOKUP(B21,ADP!A1:F671,6,FALSE))} -> 12 | I21: =IF(Settings!$E$15="POINTS",((R21*Q21)*Settings!$B$12)+(S21*Settings!$B$2)+(T21*Settings!$B$3)+(U21*Settings!$B$4)+(V21*Settings!$B$5)+(X21*Settings!$B$9)+(AA21*Settings!$B$6)+(W21*Settings!$B$8)+(AB21*Settings!$B$7)+(AC21*Settings!$B$14)+(AD21*Settings!$B$15)+(AE21*Settings!$B$16)+(AF21*Settings!$B$17)+(AG21*Settings!$B$18)+(Y21*Settings!$B$10)+(Z21*Settings!$B$11),VLOOKUP(B21,'Standard Deviations'!A$1:C$672,3,FALSE)) -> 11.586552 | J21: {=IF(D21="G",I21/AJ21,I21/Q21)} -> 0.13793514 | K21: {=IF(Settings!$E$18="C/LW/RW",VLOOKUP(B21,RW!A1:F210,6,FALSE),VLOOKUP(B21,F!A1:F407,6,FALSE))} -> 4.6993175 | L21: {=IFERROR(K21/H21,"N/A")} -> 0.39160979 | M21: 13.3 | N21: {=IFERROR(M21-A21,"N/A")} -> 0.3 | P21: {=_xlfn.XLOOKUP($B21,ADP!A2:A671,ADP!G2:G671)} -> 0 | Q21: {=IF(Settings!$E$12="YES",VLOOKUP(B21,'Player Data'!A1:E673,5,FALSE),84)} -> 84 | R21: {=VLOOKUP(B21,'Player Data'!$A1:$AE673,6,FALSE)} -> 20.2 | S21: {=VLOOKUP(B21,'Player Data'!$A1:$AE673,7,FALSE)*$Q21*IFERROR((VLOOKUP(P21,Settings!$E$28:$F$33,2,FALSE)+1),1)} -> 41.16 | T21: {=VLOOKUP(B21,'Player Data'!$A1:$AE673,8,FALSE)*$Q21*IFERROR((VLOOKUP(P21,Settings!$E$28:$F$33,2,FALSE)+1),1)} -> 53.76 | U21: {=SUM(S21:T21)} -> 94.92 | V21: {=VLOOKUP(B21,'Player Data'!$A1:$AE673,10,FALSE)*$Q21*IFERROR(((VLOOKUP(P21,Settings!$E$28:$F$33,2,FALSE)/2)+1),1)} -> 283.08 | W21: {=VLOOKUP(B21,'Player Data'!$A1:$AE673,11,FALSE)*$Q21*IFERROR((VLOOKUP(P21,Settings!$E$28:$F$33,2,FALSE)+1),1)} -> 13.44 | X21: {=VLOOKUP(B21,'Player Data'!$A1:$AE673,12,FALSE)*$Q21*IFERROR((VLOOKUP(P21,Settings!$E$28:$F$33,2,FALSE)+1),1)} -> 35.28 | Y21: {=VLOOKUP(B21,'Player Data'!$A1:$AE673,13,FALSE)*$Q21} -> 0 | Z21: {=VLOOKUP(B21,'Player Data'!$A1:$AE673,14,FALSE)*$Q21} -> 0 | AA21: {=VLOOKUP(B21,'Player Data'!$A1:$AE673,15,FALSE)*$Q21} -> 39.48 | AB21: {=VLOOKUP(B21,'Player Data'!$A1:$AE673,16,FALSE)*$Q21} -> 56.28 | AC21: {=VLOOKUP(B21,'Player Data'!$A1:$AE673,17,FALSE)*$Q21*IFERROR((VLOOKUP(P21,Settings!$E$28:$F$33,2,FALSE)+1),1)} -> 9.24 | AD21: {=VLOOKUP(B21,'Player Data'!$A1:$AE673,18,FALSE)*$Q21} -> 29.4 | AE21: {=VLOOKUP(B21,'Player Data'!$A1:$AE673,19,FALSE)*$Q21*IFERROR((VLOOKUP(P21,Settings!$E$28:$F$33,2,FALSE)+1),1)} -> 6.72 | AF21: {=VLOOKUP(B21,'Player Data'!$A1:$AE673,20,FALSE)*$Q21} -> 1.68 | AG21: {=VLOOKUP(B21,'Player Data'!$A1:$AE673,21,FALSE)*$Q21} -> 4.2 | AH21: {=VLOOKUP(B21,'Player Data'!$A1:$AE673,22,FALSE)} -> 0.27
A22: =RANK(K22,K$2:K$671) -> 17 | B22: Macklin Celebrini | C22: N | D22: {=VLOOKUP(B22,'Player Data'!A1:D673,4,FALSE)} -> C | E22: {=VLOOKUP(B22,'C'!A1:C210,3,FALSE)} -> 4 | F22: {=VLOOKUP(B22,'Player Data'!A1:B673,2,FALSE)} -> S.J | G22: {=VLOOKUP(B22,'Player Data'!A1:D673,3,FALSE)} -> 20 | H22: {=IFERROR(VLOOKUP(B22,ADP!A1:F671,6,FALSE)/1000000,VLOOKUP(B22,ADP!A1:F671,6,FALSE))} -> 0.975 | I22: =IF(Settings!$E$15="POINTS",((R22*Q22)*Settings!$B$12)+(S22*Settings!$B$2)+(T22*Settings!$B$3)+(U22*Settings!$B$4)+(V22*Settings!$B$5)+(X22*Settings!$B$9)+(AA22*Settings!$B$6)+(W22*Settings!$B$8)+(AB22*Settings!$B$7)+(AC22*Settings!$B$14)+(AD22*Settings!$B$15)+(AE22*Settings!$B$16)+(AF22*Settings!$B$17)+(AG22*Settings!$B$18)+(Y22*Settings!$B$10)+(Z22*Settings!$B$11),VLOOKUP(B22,'Standard Deviations'!A$1:C$672,3,FALSE)) -> 10.746074 | J22: {=IF(D22="G",I22/AJ22,I22/Q22)} -> 0.13104969 | K22: {=IF(Settings!$E$18="C/LW/RW",VLOOKUP(B22,'C'!A1:F210,6,FALSE),VLOOKUP(B22,F!A1:F407,6,FALSE))} -> 4.3860647 | L22: {=IFERROR(K22/H22,"N/A")} -> 4.4985279 | M22: 7.4 | N22: {=IFERROR(M22-A22,"N/A")} -> -9.6 | P22: {=_xlfn.XLOOKUP($B22,ADP!A2:A671,ADP!G2:G671)} -> + | Q22: {=IF(Settings!$E$12="YES",VLOOKUP(B22,'Player Data'!A1:E673,5,FALSE),84)} -> 82 | R22: {=VLOOKUP(B22,'Player Data'!$A1:$AE673,6,FALSE)} -> 21.4 | S22: {=VLOOKUP(B22,'Player Data'!$A1:$AE673,7,FALSE)*$Q22*IFERROR((VLOOKUP(P22,Settings!$E$28:$F$33,2,FALSE)+1),1)} -> 43.911 | T22: {=VLOOKUP(B22,'Player Data'!$A1:$AE673,8,FALSE)*$Q22*IFERROR((VLOOKUP(P22,Settings!$E$28:$F$33,2,FALSE)+1),1)} -> 68.019 | U22: {=SUM(S22:T22)} -> 111.93 | V22: {=VLOOKUP(B22,'Player Data'!$A1:$AE673,10,FALSE)*$Q22*IFERROR(((VLOOKUP(P22,Settings!$E$28:$F$33,2,FALSE)/2)+1),1)} -> 295.856 | W22: {=VLOOKUP(B22,'Player Data'!$A1:$AE673,11,FALSE)*$Q22*IFERROR((VLOOKUP(P22,Settings!$E$28:$F$33,2,FALSE)+1),1)} -> 10.332 | X22: {=VLOOKUP(B22,'Player Data'!$A1:$AE673,12,FALSE)*$Q22*IFERROR((VLOOKUP(P22,Settings!$E$28:$F$33,2,FALSE)+1),1)} -> 34.44 | Y22: {=VLOOKUP(B22,'Player Data'!$A1:$AE673,13,FALSE)*$Q22} -> 0 | Z22: {=VLOOKUP(B22,'Player Data'!$A1:$AE673,14,FALSE)*$Q22} -> 0 | AA22: {=VLOOKUP(B22,'Player Data'!$A1:$AE673,15,FALSE)*$Q22} -> 55.76 | AB22: {=VLOOKUP(B22,'Player Data'!$A1:$AE673,16,FALSE)*$Q22} -> 53.3 | AC22: {=VLOOKUP(B22,'Player Data'!$A1:$AE673,17,FALSE)*$Q22*IFERROR((VLOOKUP(P22,Settings!$E$28:$F$33,2,FALSE)+1),1)} -> -0.861 | AD22: {=VLOOKUP(B22,'Player Data'!$A1:$AE673,18,FALSE)*$Q22} -> 41.82 | AE22: {=VLOOKUP(B22,'Player Data'!$A1:$AE673,19,FALSE)*$Q22*IFERROR((VLOOKUP(P22,Settings!$E$28:$F$33,2,FALSE)+1),1)} -> 6.027 | AF22: {=VLOOKUP(B22,'Player Data'!$A1:$AE673,20,FALSE)*$Q22} -> 628.94 | AG22: {=VLOOKUP(B22,'Player Data'!$A1:$AE673,21,FALSE)*$Q22} -> 669.12 | AH22: {=VLOOKUP(B22,'Player Data'!$A1:$AE673,22,FALSE)} -> 0.48
A23: =RANK(K23,K$2:K$671) -> 19 | B23: Jack Eichel | C23: N | D23: {=VLOOKUP(B23,'Player Data'!A1:D673,4,FALSE)} -> C | E23: {=VLOOKUP(B23,'C'!A1:C210,3,FALSE)} -> 5 | F23: {=VLOOKUP(B23,'Player Data'!A1:B673,2,FALSE)} -> VGK | G23: {=VLOOKUP(B23,'Player Data'!A1:D673,3,FALSE)} -> 29 | H23: {=IFERROR(VLOOKUP(B23,ADP!A1:F671,6,FALSE)/1000000,VLOOKUP(B23,ADP!A1:F671,6,FALSE))} -> 13.5 | I23: =IF(Settings!$E$15="POINTS",((R23*Q23)*Settings!$B$12)+(S23*Settings!$B$2)+(T23*Settings!$B$3)+(U23*Settings!$B$4)+(V23*Settings!$B$5)+(X23*Settings!$B$9)+(AA23*Settings!$B$6)+(W23*Settings!$B$8)+(AB23*Settings!$B$7)+(AC23*Settings!$B$14)+(AD23*Settings!$B$15)+(AE23*Settings!$B$16)+(AF23*Settings!$B$17)+(AG23*Settings!$B$18)+(Y23*Settings!$B$10)+(Z23*Settings!$B$11),VLOOKUP(B23,'Standard Deviations'!A$1:C$672,3,FALSE)) -> 10.711307 | J23: {=IF(D23="G",I23/AJ23,I23/Q23)} -> 0.13389134 | K23: {=IF(Settings!$E$18="C/LW/RW",VLOOKUP(B23,'C'!A1:F210,6,FALSE),VLOOKUP(B23,F!A1:F407,6,FALSE))} -> 4.3512979 | L23: {=IFERROR(K23/H23,"N/A")} -> 0.32231836 | M23: 23 | N23: {=IFERROR(M23-A23,"N/A")} -> 4 | P23: {=_xlfn.XLOOKUP($B23,ADP!A2:A671,ADP!G2:G671)} -> 0 | Q23: {=IF(Settings!$E$12="YES",VLOOKUP(B23,'Player Data'!A1:E673,5,FALSE),84)} -> 80 | R23: {=VLOOKUP(B23,'Player Data'!$A1:$AE673,6,FALSE)} -> 21.4 | S23: {=VLOOKUP(B23,'Player Data'!$A1:$AE673,7,FALSE)*$Q23*IFERROR((VLOOKUP(P23,Settings!$E$28:$F$33,2,FALSE)+1),1)} -> 31.2 | T23: {=VLOOKUP(B23,'Player Data'!$A1:$AE673,8,FALSE)*$Q23*IFERROR((VLOOKUP(P23,Settings!$E$28:$F$33,2,FALSE)+1),1)} -> 65.6 | U23: {=SUM(S23:T23)} -> 96.8 | V23: {=VLOOKUP(B23,'Player Data'!$A1:$AE673,10,FALSE)*$Q23*IFERROR(((VLOOKUP(P23,Settings!$E$28:$F$33,2,FALSE)/2)+1),1)} -> 285.6 | W23: {=VLOOKUP(B23,'Player Data'!$A1:$AE673,11,FALSE)*$Q23*IFERROR((VLOOKUP(P23,Settings!$E$28:$F$33,2,FALSE)+1),1)} -> 5.6 | X23: {=VLOOKUP(B23,'Player Data'!$A1:$AE673,12,FALSE)*$Q23*IFERROR((VLOOKUP(P23,Settings!$E$28:$F$33,2,FALSE)+1),1)} -> 34.4 | Y23: {=VLOOKUP(B23,'Player Data'!$A1:$AE673,13,FALSE)*$Q23} -> 0.8 | Z23: {=VLOOKUP(B23,'Player Data'!$A1:$AE673,14,FALSE)*$Q23} -> 2.4 | AA23: {=VLOOKUP(B23,'Player Data'!$A1:$AE673,15,FALSE)*$Q23} -> 48.8 | AB23: {=VLOOKUP(B23,'Player Data'!$A1:$AE673,16,FALSE)*$Q23} -> 36.8 | AC23: {=VLOOKUP(B23,'Player Data'!$A1:$AE673,17,FALSE)*$Q23*IFERROR((VLOOKUP(P23,Settings!$E$28:$F$33,2,FALSE)+1),1)} -> 8 | AD23: {=VLOOKUP(B23,'Player Data'!$A1:$AE673,18,FALSE)*$Q23} -> 20.8 | AE23: {=VLOOKUP(B23,'Player Data'!$A1:$AE673,19,FALSE)*$Q23*IFERROR((VLOOKUP(P23,Settings!$E$28:$F$33,2,FALSE)+1),1)} -> 6.4 | AF23: {=VLOOKUP(B23,'Player Data'!$A1:$AE673,20,FALSE)*$Q23} -> 595.2 | AG23: {=VLOOKUP(B23,'Player Data'!$A1:$AE673,21,FALSE)*$Q23} -> 684.8 | AH23: {=VLOOKUP(B23,'Player Data'!$A1:$AE673,22,FALSE)} -> 0.46
